Initialising...
Simulation: Reached termination time.
Starting CloudSim version 3.0
Broker is starting...
Datacenter is starting...
Entities started.
0.0: Broker: Cloud Resource List received with 1 resource(s)
0.0: Broker: Trying to Create VM #0 in Datacenter
0.0: Broker: Trying to Create VM #1 in Datacenter
0.0: Broker: Trying to Create VM #2 in Datacenter
0.0: Broker: Trying to Create VM #3 in Datacenter
0.0: Broker: Trying to Create VM #4 in Datacenter
0.0: Broker: Trying to Create VM #5 in Datacenter
0.0: Broker: Trying to Create VM #6 in Datacenter
0.0: Broker: Trying to Create VM #7 in Datacenter
0.0: Broker: Trying to Create VM #8 in Datacenter
0.0: Broker: Trying to Create VM #9 in Datacenter
0.0: Broker: Trying to Create VM #10 in Datacenter
0.0: Broker: Trying to Create VM #11 in Datacenter
0.0: Broker: Trying to Create VM #12 in Datacenter
0.0: Broker: Trying to Create VM #13 in Datacenter
0.0: Broker: Trying to Create VM #14 in Datacenter
0.0: Broker: Trying to Create VM #15 in Datacenter
0.0: Broker: Trying to Create VM #16 in Datacenter
0.0: Broker: Trying to Create VM #17 in Datacenter
0.0: Broker: Trying to Create VM #18 in Datacenter
0.0: Broker: Trying to Create VM #19 in Datacenter
0.0: Broker: Trying to Create VM #20 in Datacenter
0.0: Broker: Trying to Create VM #21 in Datacenter
0.0: Broker: Trying to Create VM #22 in Datacenter
0.0: Broker: Trying to Create VM #23 in Datacenter
0.0: Broker: Trying to Create VM #24 in Datacenter
0.0: Broker: Trying to Create VM #25 in Datacenter
0.0: Broker: Trying to Create VM #26 in Datacenter
0.0: Broker: Trying to Create VM #27 in Datacenter
0.0: Broker: Trying to Create VM #28 in Datacenter
0.0: Broker: Trying to Create VM #29 in Datacenter
0.0: Broker: Trying to Create VM #30 in Datacenter
0.0: Broker: Trying to Create VM #31 in Datacenter
0.0: Broker: Trying to Create VM #32 in Datacenter
0.0: Broker: Trying to Create VM #33 in Datacenter
0.0: Broker: Trying to Create VM #34 in Datacenter
0.0: Broker: Trying to Create VM #35 in Datacenter
0.0: Broker: Trying to Create VM #36 in Datacenter
0.0: Broker: Trying to Create VM #37 in Datacenter
0.0: Broker: Trying to Create VM #38 in Datacenter
0.0: Broker: Trying to Create VM #39 in Datacenter
0.0: Broker: Trying to Create VM #40 in Datacenter
0.0: Broker: Trying to Create VM #41 in Datacenter
0.0: Broker: Trying to Create VM #42 in Datacenter
0.0: Broker: Trying to Create VM #43 in Datacenter
0.0: Broker: Trying to Create VM #44 in Datacenter
0.0: Broker: Trying to Create VM #45 in Datacenter
0.0: Broker: Trying to Create VM #46 in Datacenter
0.0: Broker: Trying to Create VM #47 in Datacenter
0.0: Broker: Trying to Create VM #48 in Datacenter
0.0: Broker: Trying to Create VM #49 in Datacenter
0.0: Broker: Trying to Create VM #50 in Datacenter
0.0: Broker: Trying to Create VM #51 in Datacenter
0.0: Broker: Trying to Create VM #52 in Datacenter
0.0: Broker: Trying to Create VM #53 in Datacenter
0.0: Broker: Trying to Create VM #54 in Datacenter
0.0: Broker: Trying to Create VM #55 in Datacenter
0.0: Broker: Trying to Create VM #56 in Datacenter
0.0: Broker: Trying to Create VM #57 in Datacenter
0.0: Broker: Trying to Create VM #58 in Datacenter
0.0: Broker: Trying to Create VM #59 in Datacenter
0.0: Broker: Trying to Create VM #60 in Datacenter
0.0: Broker: Trying to Create VM #61 in Datacenter
0.0: Broker: Trying to Create VM #62 in Datacenter
0.0: Broker: Trying to Create VM #63 in Datacenter
0.0: Broker: Trying to Create VM #64 in Datacenter
0.0: Broker: Trying to Create VM #65 in Datacenter
0.0: Broker: Trying to Create VM #66 in Datacenter
0.0: Broker: Trying to Create VM #67 in Datacenter
0.0: Broker: Trying to Create VM #68 in Datacenter
0.0: Broker: Trying to Create VM #69 in Datacenter
0.0: Broker: Trying to Create VM #70 in Datacenter
0.0: Broker: Trying to Create VM #71 in Datacenter
0.0: Broker: Trying to Create VM #72 in Datacenter
0.0: Broker: Trying to Create VM #73 in Datacenter
0.0: Broker: Trying to Create VM #74 in Datacenter
0.0: Broker: Trying to Create VM #75 in Datacenter
0.0: Broker: Trying to Create VM #76 in Datacenter
0.0: Broker: Trying to Create VM #77 in Datacenter
0.0: Broker: Trying to Create VM #78 in Datacenter
0.0: Broker: Trying to Create VM #79 in Datacenter
0.0: Broker: Trying to Create VM #80 in Datacenter
0.0: Broker: Trying to Create VM #81 in Datacenter
0.0: Broker: Trying to Create VM #82 in Datacenter
0.0: Broker: Trying to Create VM #83 in Datacenter
0.0: Broker: Trying to Create VM #84 in Datacenter
0.0: Broker: Trying to Create VM #85 in Datacenter
0.0: Broker: Trying to Create VM #86 in Datacenter
0.0: Broker: Trying to Create VM #87 in Datacenter
0.0: Broker: Trying to Create VM #88 in Datacenter
0.0: Broker: Trying to Create VM #89 in Datacenter
0.0: Broker: Trying to Create VM #90 in Datacenter
0.0: Broker: Trying to Create VM #91 in Datacenter
0.0: Broker: Trying to Create VM #92 in Datacenter
0.0: Broker: Trying to Create VM #93 in Datacenter
0.0: Broker: Trying to Create VM #94 in Datacenter
0.0: Broker: Trying to Create VM #95 in Datacenter
0.0: Broker: Trying to Create VM #96 in Datacenter
0.0: Broker: Trying to Create VM #97 in Datacenter
0.0: Broker: Trying to Create VM #98 in Datacenter
0.0: Broker: Trying to Create VM #99 in Datacenter
0.0: Broker: Trying to Create VM #100 in Datacenter
0.0: Broker: Trying to Create VM #101 in Datacenter
0.0: Broker: Trying to Create VM #102 in Datacenter
0.0: Broker: Trying to Create VM #103 in Datacenter
0.0: Broker: Trying to Create VM #104 in Datacenter
0.0: Broker: Trying to Create VM #105 in Datacenter
0.0: Broker: Trying to Create VM #106 in Datacenter
0.0: Broker: Trying to Create VM #107 in Datacenter
0.0: Broker: Trying to Create VM #108 in Datacenter
0.0: Broker: Trying to Create VM #109 in Datacenter
0.0: Broker: Trying to Create VM #110 in Datacenter
0.0: Broker: Trying to Create VM #111 in Datacenter
0.0: Broker: Trying to Create VM #112 in Datacenter
0.0: Broker: Trying to Create VM #113 in Datacenter
0.0: Broker: Trying to Create VM #114 in Datacenter
0.0: Broker: Trying to Create VM #115 in Datacenter
0.0: Broker: Trying to Create VM #116 in Datacenter
0.0: Broker: Trying to Create VM #117 in Datacenter
0.0: Broker: Trying to Create VM #118 in Datacenter
0.0: Broker: Trying to Create VM #119 in Datacenter
0.0: Broker: Trying to Create VM #120 in Datacenter
0.0: Broker: Trying to Create VM #121 in Datacenter
0.0: Broker: Trying to Create VM #122 in Datacenter
0.0: Broker: Trying to Create VM #123 in Datacenter
0.0: Broker: Trying to Create VM #124 in Datacenter
0.0: Broker: Trying to Create VM #125 in Datacenter
0.0: Broker: Trying to Create VM #126 in Datacenter
0.0: Broker: Trying to Create VM #127 in Datacenter
0.0: Broker: Trying to Create VM #128 in Datacenter
0.0: Broker: Trying to Create VM #129 in Datacenter
0.0: Broker: Trying to Create VM #130 in Datacenter
0.0: Broker: Trying to Create VM #131 in Datacenter
0.0: Broker: Trying to Create VM #132 in Datacenter
0.0: Broker: Trying to Create VM #133 in Datacenter
0.0: Broker: Trying to Create VM #134 in Datacenter
0.0: Broker: Trying to Create VM #135 in Datacenter
0.0: Broker: Trying to Create VM #136 in Datacenter
0.0: Broker: Trying to Create VM #137 in Datacenter
0.0: Broker: Trying to Create VM #138 in Datacenter
0.0: Broker: Trying to Create VM #139 in Datacenter
0.0: Broker: Trying to Create VM #140 in Datacenter
0.0: Broker: Trying to Create VM #141 in Datacenter
0.0: Broker: Trying to Create VM #142 in Datacenter
0.0: Broker: Trying to Create VM #143 in Datacenter
0.0: Broker: Trying to Create VM #144 in Datacenter
0.0: Broker: Trying to Create VM #145 in Datacenter
0.0: Broker: Trying to Create VM #146 in Datacenter
0.0: Broker: Trying to Create VM #147 in Datacenter
0.0: Broker: Trying to Create VM #148 in Datacenter
0.0: Broker: Trying to Create VM #149 in Datacenter
0.0: Broker: Trying to Create VM #150 in Datacenter
0.0: Broker: Trying to Create VM #151 in Datacenter
0.0: Broker: Trying to Create VM #152 in Datacenter
0.0: Broker: Trying to Create VM #153 in Datacenter
0.0: Broker: Trying to Create VM #154 in Datacenter
0.0: Broker: Trying to Create VM #155 in Datacenter
0.0: Broker: Trying to Create VM #156 in Datacenter
0.0: Broker: Trying to Create VM #157 in Datacenter
0.0: Broker: Trying to Create VM #158 in Datacenter
0.0: Broker: Trying to Create VM #159 in Datacenter
0.0: Broker: Trying to Create VM #160 in Datacenter
0.0: Broker: Trying to Create VM #161 in Datacenter
0.0: Broker: Trying to Create VM #162 in Datacenter
0.0: Broker: Trying to Create VM #163 in Datacenter
0.0: Broker: Trying to Create VM #164 in Datacenter
0.0: Broker: Trying to Create VM #165 in Datacenter
0.0: Broker: Trying to Create VM #166 in Datacenter
0.0: Broker: Trying to Create VM #167 in Datacenter
0.0: Broker: Trying to Create VM #168 in Datacenter
0.0: Broker: Trying to Create VM #169 in Datacenter
0.0: Broker: Trying to Create VM #170 in Datacenter
0.0: Broker: Trying to Create VM #171 in Datacenter
0.0: Broker: Trying to Create VM #172 in Datacenter
0.0: Broker: Trying to Create VM #173 in Datacenter
0.0: Broker: Trying to Create VM #174 in Datacenter
0.0: Broker: Trying to Create VM #175 in Datacenter
0.0: Broker: Trying to Create VM #176 in Datacenter
0.0: Broker: Trying to Create VM #177 in Datacenter
0.0: Broker: Trying to Create VM #178 in Datacenter
0.0: Broker: Trying to Create VM #179 in Datacenter
0.0: Broker: Trying to Create VM #180 in Datacenter
0.0: Broker: Trying to Create VM #181 in Datacenter
0.0: Broker: Trying to Create VM #182 in Datacenter
0.0: Broker: Trying to Create VM #183 in Datacenter
0.0: Broker: Trying to Create VM #184 in Datacenter
0.0: Broker: Trying to Create VM #185 in Datacenter
0.0: Broker: Trying to Create VM #186 in Datacenter
0.0: Broker: Trying to Create VM #187 in Datacenter
0.0: Broker: Trying to Create VM #188 in Datacenter
0.0: Broker: Trying to Create VM #189 in Datacenter
0.0: Broker: Trying to Create VM #190 in Datacenter
0.0: Broker: Trying to Create VM #191 in Datacenter
0.0: Broker: Trying to Create VM #192 in Datacenter
0.0: Broker: Trying to Create VM #193 in Datacenter
0.0: Broker: Trying to Create VM #194 in Datacenter
0.0: Broker: Trying to Create VM #195 in Datacenter
0.0: Broker: Trying to Create VM #196 in Datacenter
0.0: Broker: Trying to Create VM #197 in Datacenter
0.0: Broker: Trying to Create VM #198 in Datacenter
0.0: Broker: Trying to Create VM #199 in Datacenter
0.0: Broker: Trying to Create VM #200 in Datacenter
0.0: Broker: Trying to Create VM #201 in Datacenter
0.0: Broker: Trying to Create VM #202 in Datacenter
0.0: Broker: Trying to Create VM #203 in Datacenter
0.0: Broker: Trying to Create VM #204 in Datacenter
0.0: Broker: Trying to Create VM #205 in Datacenter
0.0: Broker: Trying to Create VM #206 in Datacenter
0.0: Broker: Trying to Create VM #207 in Datacenter
0.0: Broker: Trying to Create VM #208 in Datacenter
0.0: Broker: Trying to Create VM #209 in Datacenter
0.0: Broker: Trying to Create VM #210 in Datacenter
0.0: Broker: Trying to Create VM #211 in Datacenter
0.0: Broker: Trying to Create VM #212 in Datacenter
0.0: Broker: Trying to Create VM #213 in Datacenter
0.0: Broker: Trying to Create VM #214 in Datacenter
0.0: Broker: Trying to Create VM #215 in Datacenter
0.0: Broker: Trying to Create VM #216 in Datacenter
0.0: Broker: Trying to Create VM #217 in Datacenter
0.0: Broker: Trying to Create VM #218 in Datacenter
0.0: Broker: Trying to Create VM #219 in Datacenter
0.0: Broker: Trying to Create VM #220 in Datacenter
0.0: Broker: Trying to Create VM #221 in Datacenter
0.0: Broker: Trying to Create VM #222 in Datacenter
0.0: Broker: Trying to Create VM #223 in Datacenter
0.0: Broker: Trying to Create VM #224 in Datacenter
0.0: Broker: Trying to Create VM #225 in Datacenter
0.0: Broker: Trying to Create VM #226 in Datacenter
0.0: Broker: Trying to Create VM #227 in Datacenter
0.0: Broker: Trying to Create VM #228 in Datacenter
0.0: Broker: Trying to Create VM #229 in Datacenter
0.0: Broker: Trying to Create VM #230 in Datacenter
0.0: Broker: Trying to Create VM #231 in Datacenter
0.0: Broker: Trying to Create VM #232 in Datacenter
0.0: Broker: Trying to Create VM #233 in Datacenter
0.0: Broker: Trying to Create VM #234 in Datacenter
0.0: Broker: Trying to Create VM #235 in Datacenter
0.0: Broker: Trying to Create VM #236 in Datacenter
0.0: Broker: Trying to Create VM #237 in Datacenter
0.0: Broker: Trying to Create VM #238 in Datacenter
0.0: Broker: Trying to Create VM #239 in Datacenter
0.0: Broker: Trying to Create VM #240 in Datacenter
0.0: Broker: Trying to Create VM #241 in Datacenter
0.0: Broker: Trying to Create VM #242 in Datacenter
0.0: Broker: Trying to Create VM #243 in Datacenter
0.0: Broker: Trying to Create VM #244 in Datacenter
0.0: Broker: Trying to Create VM #245 in Datacenter
0.0: Broker: Trying to Create VM #246 in Datacenter
0.0: Broker: Trying to Create VM #247 in Datacenter
0.0: Broker: Trying to Create VM #248 in Datacenter
0.0: Broker: Trying to Create VM #249 in Datacenter
0.0: Broker: Trying to Create VM #250 in Datacenter
0.0: Broker: Trying to Create VM #251 in Datacenter
0.0: Broker: Trying to Create VM #252 in Datacenter
0.0: Broker: Trying to Create VM #253 in Datacenter
0.0: Broker: Trying to Create VM #254 in Datacenter
0.0: Broker: Trying to Create VM #255 in Datacenter
0.0: Broker: Trying to Create VM #256 in Datacenter
0.0: Broker: Trying to Create VM #257 in Datacenter
0.0: Broker: Trying to Create VM #258 in Datacenter
0.0: Broker: Trying to Create VM #259 in Datacenter
0.0: Broker: Trying to Create VM #260 in Datacenter
0.0: Broker: Trying to Create VM #261 in Datacenter
0.0: Broker: Trying to Create VM #262 in Datacenter
0.0: Broker: Trying to Create VM #263 in Datacenter
0.0: Broker: Trying to Create VM #264 in Datacenter
0.0: Broker: Trying to Create VM #265 in Datacenter
0.0: Broker: Trying to Create VM #266 in Datacenter
0.0: Broker: Trying to Create VM #267 in Datacenter
0.0: Broker: Trying to Create VM #268 in Datacenter
0.0: Broker: Trying to Create VM #269 in Datacenter
0.0: Broker: Trying to Create VM #270 in Datacenter
0.0: Broker: Trying to Create VM #271 in Datacenter
0.0: Broker: Trying to Create VM #272 in Datacenter
0.0: Broker: Trying to Create VM #273 in Datacenter
0.0: Broker: Trying to Create VM #274 in Datacenter
0.0: Broker: Trying to Create VM #275 in Datacenter
0.0: Broker: Trying to Create VM #276 in Datacenter
0.0: Broker: Trying to Create VM #277 in Datacenter
0.0: Broker: Trying to Create VM #278 in Datacenter
0.0: Broker: Trying to Create VM #279 in Datacenter
0.0: Broker: Trying to Create VM #280 in Datacenter
0.0: Broker: Trying to Create VM #281 in Datacenter
0.0: Broker: Trying to Create VM #282 in Datacenter
0.0: Broker: Trying to Create VM #283 in Datacenter
0.0: Broker: Trying to Create VM #284 in Datacenter
0.0: Broker: Trying to Create VM #285 in Datacenter
0.0: Broker: Trying to Create VM #286 in Datacenter
0.0: Broker: Trying to Create VM #287 in Datacenter
0.0: Broker: Trying to Create VM #288 in Datacenter
0.0: Broker: Trying to Create VM #289 in Datacenter
0.0: Broker: Trying to Create VM #290 in Datacenter
0.0: Broker: Trying to Create VM #291 in Datacenter
0.0: Broker: Trying to Create VM #292 in Datacenter
0.0: Broker: Trying to Create VM #293 in Datacenter
0.0: Broker: Trying to Create VM #294 in Datacenter
0.0: Broker: Trying to Create VM #295 in Datacenter
0.0: Broker: Trying to Create VM #296 in Datacenter
0.0: Broker: Trying to Create VM #297 in Datacenter
0.0: Broker: Trying to Create VM #298 in Datacenter
0.0: Broker: Trying to Create VM #299 in Datacenter
0.0: Broker: Trying to Create VM #300 in Datacenter
0.0: Broker: Trying to Create VM #301 in Datacenter
0.0: Broker: Trying to Create VM #302 in Datacenter
0.0: Broker: Trying to Create VM #303 in Datacenter
0.0: Broker: Trying to Create VM #304 in Datacenter
0.0: Broker: Trying to Create VM #305 in Datacenter
0.0: Broker: Trying to Create VM #306 in Datacenter
0.0: Broker: Trying to Create VM #307 in Datacenter
0.0: Broker: Trying to Create VM #308 in Datacenter
0.0: Broker: Trying to Create VM #309 in Datacenter
0.0: Broker: Trying to Create VM #310 in Datacenter
0.0: Broker: Trying to Create VM #311 in Datacenter
0.0: Broker: Trying to Create VM #312 in Datacenter
0.0: Broker: Trying to Create VM #313 in Datacenter
0.0: Broker: Trying to Create VM #314 in Datacenter
0.0: Broker: Trying to Create VM #315 in Datacenter
0.0: Broker: Trying to Create VM #316 in Datacenter
0.0: Broker: Trying to Create VM #317 in Datacenter
0.0: Broker: Trying to Create VM #318 in Datacenter
0.0: Broker: Trying to Create VM #319 in Datacenter
0.0: Broker: Trying to Create VM #320 in Datacenter
0.0: Broker: Trying to Create VM #321 in Datacenter
0.0: Broker: Trying to Create VM #322 in Datacenter
0.0: Broker: Trying to Create VM #323 in Datacenter
0.0: Broker: Trying to Create VM #324 in Datacenter
0.0: Broker: Trying to Create VM #325 in Datacenter
0.0: Broker: Trying to Create VM #326 in Datacenter
0.0: Broker: Trying to Create VM #327 in Datacenter
0.0: Broker: Trying to Create VM #328 in Datacenter
0.0: Broker: Trying to Create VM #329 in Datacenter
0.0: Broker: Trying to Create VM #330 in Datacenter
0.0: Broker: Trying to Create VM #331 in Datacenter
0.0: Broker: Trying to Create VM #332 in Datacenter
0.0: Broker: Trying to Create VM #333 in Datacenter
0.0: Broker: Trying to Create VM #334 in Datacenter
0.0: Broker: Trying to Create VM #335 in Datacenter
0.0: Broker: Trying to Create VM #336 in Datacenter
0.0: Broker: Trying to Create VM #337 in Datacenter
0.0: Broker: Trying to Create VM #338 in Datacenter
0.0: Broker: Trying to Create VM #339 in Datacenter
0.0: Broker: Trying to Create VM #340 in Datacenter
0.0: Broker: Trying to Create VM #341 in Datacenter
0.0: Broker: Trying to Create VM #342 in Datacenter
0.0: Broker: Trying to Create VM #343 in Datacenter
0.0: Broker: Trying to Create VM #344 in Datacenter
0.0: Broker: Trying to Create VM #345 in Datacenter
0.0: Broker: Trying to Create VM #346 in Datacenter
0.0: Broker: Trying to Create VM #347 in Datacenter
0.0: Broker: Trying to Create VM #348 in Datacenter
0.0: Broker: Trying to Create VM #349 in Datacenter
0.0: Broker: Trying to Create VM #350 in Datacenter
0.0: Broker: Trying to Create VM #351 in Datacenter
0.0: Broker: Trying to Create VM #352 in Datacenter
0.0: Broker: Trying to Create VM #353 in Datacenter
0.0: Broker: Trying to Create VM #354 in Datacenter
0.0: Broker: Trying to Create VM #355 in Datacenter
0.0: Broker: Trying to Create VM #356 in Datacenter
0.0: Broker: Trying to Create VM #357 in Datacenter
0.0: Broker: Trying to Create VM #358 in Datacenter
0.0: Broker: Trying to Create VM #359 in Datacenter
0.0: Broker: Trying to Create VM #360 in Datacenter
0.0: Broker: Trying to Create VM #361 in Datacenter
0.0: Broker: Trying to Create VM #362 in Datacenter
0.0: Broker: Trying to Create VM #363 in Datacenter
0.0: Broker: Trying to Create VM #364 in Datacenter
0.0: Broker: Trying to Create VM #365 in Datacenter
0.0: Broker: Trying to Create VM #366 in Datacenter
0.0: Broker: Trying to Create VM #367 in Datacenter
0.0: Broker: Trying to Create VM #368 in Datacenter
0.0: Broker: Trying to Create VM #369 in Datacenter
0.0: Broker: Trying to Create VM #370 in Datacenter
0.0: Broker: Trying to Create VM #371 in Datacenter
0.0: Broker: Trying to Create VM #372 in Datacenter
0.0: Broker: Trying to Create VM #373 in Datacenter
0.0: Broker: Trying to Create VM #374 in Datacenter
0.0: Broker: Trying to Create VM #375 in Datacenter
0.0: Broker: Trying to Create VM #376 in Datacenter
0.0: Broker: Trying to Create VM #377 in Datacenter
0.0: Broker: Trying to Create VM #378 in Datacenter
0.0: Broker: Trying to Create VM #379 in Datacenter
0.0: Broker: Trying to Create VM #380 in Datacenter
0.0: Broker: Trying to Create VM #381 in Datacenter
0.0: Broker: Trying to Create VM #382 in Datacenter
0.0: Broker: Trying to Create VM #383 in Datacenter
0.0: Broker: Trying to Create VM #384 in Datacenter
0.0: Broker: Trying to Create VM #385 in Datacenter
0.0: Broker: Trying to Create VM #386 in Datacenter
0.0: Broker: Trying to Create VM #387 in Datacenter
0.0: Broker: Trying to Create VM #388 in Datacenter
0.0: Broker: Trying to Create VM #389 in Datacenter
0.0: Broker: Trying to Create VM #390 in Datacenter
0.0: Broker: Trying to Create VM #391 in Datacenter
0.0: Broker: Trying to Create VM #392 in Datacenter
0.0: Broker: Trying to Create VM #393 in Datacenter
0.0: Broker: Trying to Create VM #394 in Datacenter
0.0: Broker: Trying to Create VM #395 in Datacenter
0.0: Broker: Trying to Create VM #396 in Datacenter
0.0: Broker: Trying to Create VM #397 in Datacenter
0.0: Broker: Trying to Create VM #398 in Datacenter
0.0: Broker: Trying to Create VM #399 in Datacenter
0.0: Broker: Trying to Create VM #400 in Datacenter
0.0: Broker: Trying to Create VM #401 in Datacenter
0.0: Broker: Trying to Create VM #402 in Datacenter
0.0: Broker: Trying to Create VM #403 in Datacenter
0.0: Broker: Trying to Create VM #404 in Datacenter
0.0: Broker: Trying to Create VM #405 in Datacenter
0.0: Broker: Trying to Create VM #406 in Datacenter
0.0: Broker: Trying to Create VM #407 in Datacenter
0.0: Broker: Trying to Create VM #408 in Datacenter
0.0: Broker: Trying to Create VM #409 in Datacenter
0.0: Broker: Trying to Create VM #410 in Datacenter
0.0: Broker: Trying to Create VM #411 in Datacenter
0.0: Broker: Trying to Create VM #412 in Datacenter
0.0: Broker: Trying to Create VM #413 in Datacenter
0.0: Broker: Trying to Create VM #414 in Datacenter
0.0: Broker: Trying to Create VM #415 in Datacenter
0.0: Broker: Trying to Create VM #416 in Datacenter
0.0: Broker: Trying to Create VM #417 in Datacenter
0.0: Broker: Trying to Create VM #418 in Datacenter
0.0: Broker: Trying to Create VM #419 in Datacenter
0.0: Broker: Trying to Create VM #420 in Datacenter
0.0: Broker: Trying to Create VM #421 in Datacenter
0.0: Broker: Trying to Create VM #422 in Datacenter
0.0: Broker: Trying to Create VM #423 in Datacenter
0.0: Broker: Trying to Create VM #424 in Datacenter
0.0: Broker: Trying to Create VM #425 in Datacenter
0.0: Broker: Trying to Create VM #426 in Datacenter
0.0: Broker: Trying to Create VM #427 in Datacenter
0.0: Broker: Trying to Create VM #428 in Datacenter
0.0: Broker: Trying to Create VM #429 in Datacenter
0.0: Broker: Trying to Create VM #430 in Datacenter
0.0: Broker: Trying to Create VM #431 in Datacenter
0.0: Broker: Trying to Create VM #432 in Datacenter
0.0: Broker: Trying to Create VM #433 in Datacenter
0.0: Broker: Trying to Create VM #434 in Datacenter
0.0: Broker: Trying to Create VM #435 in Datacenter
0.0: Broker: Trying to Create VM #436 in Datacenter
0.0: Broker: Trying to Create VM #437 in Datacenter
0.0: Broker: Trying to Create VM #438 in Datacenter
0.0: Broker: Trying to Create VM #439 in Datacenter
0.0: Broker: Trying to Create VM #440 in Datacenter
0.0: Broker: Trying to Create VM #441 in Datacenter
0.0: Broker: Trying to Create VM #442 in Datacenter
0.0: Broker: Trying to Create VM #443 in Datacenter
0.0: Broker: Trying to Create VM #444 in Datacenter
0.0: Broker: Trying to Create VM #445 in Datacenter
0.0: Broker: Trying to Create VM #446 in Datacenter
0.0: Broker: Trying to Create VM #447 in Datacenter
0.0: Broker: Trying to Create VM #448 in Datacenter
0.0: Broker: Trying to Create VM #449 in Datacenter
0.0: Broker: Trying to Create VM #450 in Datacenter
0.0: Broker: Trying to Create VM #451 in Datacenter
0.0: Broker: Trying to Create VM #452 in Datacenter
0.0: Broker: Trying to Create VM #453 in Datacenter
0.0: Broker: Trying to Create VM #454 in Datacenter
0.0: Broker: Trying to Create VM #455 in Datacenter
0.0: Broker: Trying to Create VM #456 in Datacenter
0.0: Broker: Trying to Create VM #457 in Datacenter
0.0: Broker: Trying to Create VM #458 in Datacenter
0.0: Broker: Trying to Create VM #459 in Datacenter
0.0: Broker: Trying to Create VM #460 in Datacenter
0.0: Broker: Trying to Create VM #461 in Datacenter
0.0: Broker: Trying to Create VM #462 in Datacenter
0.0: Broker: Trying to Create VM #463 in Datacenter
0.0: Broker: Trying to Create VM #464 in Datacenter
0.0: Broker: Trying to Create VM #465 in Datacenter
0.0: Broker: Trying to Create VM #466 in Datacenter
0.0: Broker: Trying to Create VM #467 in Datacenter
0.0: Broker: Trying to Create VM #468 in Datacenter
0.0: Broker: Trying to Create VM #469 in Datacenter
0.0: Broker: Trying to Create VM #470 in Datacenter
0.0: Broker: Trying to Create VM #471 in Datacenter
0.0: Broker: Trying to Create VM #472 in Datacenter
0.0: Broker: Trying to Create VM #473 in Datacenter
0.0: Broker: Trying to Create VM #474 in Datacenter
0.0: Broker: Trying to Create VM #475 in Datacenter
0.0: Broker: Trying to Create VM #476 in Datacenter
0.0: Broker: Trying to Create VM #477 in Datacenter
0.0: Broker: Trying to Create VM #478 in Datacenter
0.0: Broker: Trying to Create VM #479 in Datacenter
0.0: Broker: Trying to Create VM #480 in Datacenter
0.0: Broker: Trying to Create VM #481 in Datacenter
0.0: Broker: Trying to Create VM #482 in Datacenter
0.0: Broker: Trying to Create VM #483 in Datacenter
0.0: Broker: Trying to Create VM #484 in Datacenter
0.0: Broker: Trying to Create VM #485 in Datacenter
0.0: Broker: Trying to Create VM #486 in Datacenter
0.0: Broker: Trying to Create VM #487 in Datacenter
0.0: Broker: Trying to Create VM #488 in Datacenter
0.0: Broker: Trying to Create VM #489 in Datacenter
0.0: Broker: Trying to Create VM #490 in Datacenter
0.0: Broker: Trying to Create VM #491 in Datacenter
0.0: Broker: Trying to Create VM #492 in Datacenter
0.0: Broker: Trying to Create VM #493 in Datacenter
0.0: Broker: Trying to Create VM #494 in Datacenter
0.0: Broker: Trying to Create VM #495 in Datacenter
0.0: Broker: Trying to Create VM #496 in Datacenter
0.0: Broker: Trying to Create VM #497 in Datacenter
0.0: Broker: Trying to Create VM #498 in Datacenter
0.0: Broker: Trying to Create VM #499 in Datacenter
0.0: Broker: Trying to Create VM #500 in Datacenter
0.0: Broker: Trying to Create VM #501 in Datacenter
0.0: Broker: Trying to Create VM #502 in Datacenter
0.0: Broker: Trying to Create VM #503 in Datacenter
0.0: Broker: Trying to Create VM #504 in Datacenter
0.0: Broker: Trying to Create VM #505 in Datacenter
0.0: Broker: Trying to Create VM #506 in Datacenter
0.0: Broker: Trying to Create VM #507 in Datacenter
0.0: Broker: Trying to Create VM #508 in Datacenter
0.0: Broker: Trying to Create VM #509 in Datacenter
0.0: Broker: Trying to Create VM #510 in Datacenter
0.0: Broker: Trying to Create VM #511 in Datacenter
0.0: Broker: Trying to Create VM #512 in Datacenter
0.0: Broker: Trying to Create VM #513 in Datacenter
0.0: Broker: Trying to Create VM #514 in Datacenter
0.0: Broker: Trying to Create VM #515 in Datacenter
0.0: Broker: Trying to Create VM #516 in Datacenter
0.0: Broker: Trying to Create VM #517 in Datacenter
0.0: Broker: Trying to Create VM #518 in Datacenter
0.0: Broker: Trying to Create VM #519 in Datacenter
0.0: Broker: Trying to Create VM #520 in Datacenter
0.0: Broker: Trying to Create VM #521 in Datacenter
0.0: Broker: Trying to Create VM #522 in Datacenter
0.0: Broker: Trying to Create VM #523 in Datacenter
0.0: Broker: Trying to Create VM #524 in Datacenter
0.0: Broker: Trying to Create VM #525 in Datacenter
0.0: Broker: Trying to Create VM #526 in Datacenter
0.0: Broker: Trying to Create VM #527 in Datacenter
0.0: Broker: Trying to Create VM #528 in Datacenter
0.0: Broker: Trying to Create VM #529 in Datacenter
0.0: Broker: Trying to Create VM #530 in Datacenter
0.0: Broker: Trying to Create VM #531 in Datacenter
0.0: Broker: Trying to Create VM #532 in Datacenter
0.0: Broker: Trying to Create VM #533 in Datacenter
0.0: Broker: Trying to Create VM #534 in Datacenter
0.0: Broker: Trying to Create VM #535 in Datacenter
0.0: Broker: Trying to Create VM #536 in Datacenter
0.0: Broker: Trying to Create VM #537 in Datacenter
0.0: Broker: Trying to Create VM #538 in Datacenter
0.0: Broker: Trying to Create VM #539 in Datacenter
0.0: Broker: Trying to Create VM #540 in Datacenter
0.0: Broker: Trying to Create VM #541 in Datacenter
0.0: Broker: Trying to Create VM #542 in Datacenter
0.0: Broker: Trying to Create VM #543 in Datacenter
0.0: Broker: Trying to Create VM #544 in Datacenter
0.0: Broker: Trying to Create VM #545 in Datacenter
0.0: Broker: Trying to Create VM #546 in Datacenter
0.0: Broker: Trying to Create VM #547 in Datacenter
0.0: Broker: Trying to Create VM #548 in Datacenter
0.0: Broker: Trying to Create VM #549 in Datacenter
0.0: Broker: Trying to Create VM #550 in Datacenter
0.0: Broker: Trying to Create VM #551 in Datacenter
0.0: Broker: Trying to Create VM #552 in Datacenter
0.0: Broker: Trying to Create VM #553 in Datacenter
0.0: Broker: Trying to Create VM #554 in Datacenter
0.0: Broker: Trying to Create VM #555 in Datacenter
0.0: Broker: Trying to Create VM #556 in Datacenter
0.0: Broker: Trying to Create VM #557 in Datacenter
0.0: Broker: Trying to Create VM #558 in Datacenter
0.0: Broker: Trying to Create VM #559 in Datacenter
0.0: Broker: Trying to Create VM #560 in Datacenter
0.0: Broker: Trying to Create VM #561 in Datacenter
0.0: Broker: Trying to Create VM #562 in Datacenter
0.0: Broker: Trying to Create VM #563 in Datacenter
0.0: Broker: Trying to Create VM #564 in Datacenter
0.0: Broker: Trying to Create VM #565 in Datacenter
0.0: Broker: Trying to Create VM #566 in Datacenter
0.0: Broker: Trying to Create VM #567 in Datacenter
0.0: Broker: Trying to Create VM #568 in Datacenter
0.0: Broker: Trying to Create VM #569 in Datacenter
0.0: Broker: Trying to Create VM #570 in Datacenter
0.0: Broker: Trying to Create VM #571 in Datacenter
0.0: Broker: Trying to Create VM #572 in Datacenter
0.0: Broker: Trying to Create VM #573 in Datacenter
0.0: Broker: Trying to Create VM #574 in Datacenter
0.0: Broker: Trying to Create VM #575 in Datacenter
0.0: Broker: Trying to Create VM #576 in Datacenter
0.0: Broker: Trying to Create VM #577 in Datacenter
0.0: Broker: Trying to Create VM #578 in Datacenter
0.0: Broker: Trying to Create VM #579 in Datacenter
0.0: Broker: Trying to Create VM #580 in Datacenter
0.0: Broker: Trying to Create VM #581 in Datacenter
0.0: Broker: Trying to Create VM #582 in Datacenter
0.0: Broker: Trying to Create VM #583 in Datacenter
0.0: Broker: Trying to Create VM #584 in Datacenter
0.0: Broker: Trying to Create VM #585 in Datacenter
0.0: Broker: Trying to Create VM #586 in Datacenter
0.0: Broker: Trying to Create VM #587 in Datacenter
0.0: Broker: Trying to Create VM #588 in Datacenter
0.0: Broker: Trying to Create VM #589 in Datacenter
0.0: Broker: Trying to Create VM #590 in Datacenter
0.0: Broker: Trying to Create VM #591 in Datacenter
0.0: Broker: Trying to Create VM #592 in Datacenter
0.0: Broker: Trying to Create VM #593 in Datacenter
0.0: Broker: Trying to Create VM #594 in Datacenter
0.0: Broker: Trying to Create VM #595 in Datacenter
0.0: Broker: Trying to Create VM #596 in Datacenter
0.0: Broker: Trying to Create VM #597 in Datacenter
0.0: Broker: Trying to Create VM #598 in Datacenter
0.0: Broker: Trying to Create VM #599 in Datacenter
0,00: VM #0 has been allocated to the host #0
0,00: VM #1 has been allocated to the host #0
0,00: VM #2 has been allocated to the host #0
0,00: VM #3 has been allocated to the host #0
0,00: VM #4 has been allocated to the host #0
0,00: VM #5 has been allocated to the host #0
0,00: VM #6 has been allocated to the host #0
0,00: VM #7 has been allocated to the host #0
0,00: VM #8 has been allocated to the host #1
0,00: VM #9 has been allocated to the host #1
0,00: VM #10 has been allocated to the host #1
0,00: VM #11 has been allocated to the host #1
0,00: VM #12 has been allocated to the host #1
0,00: VM #13 has been allocated to the host #1
0,00: VM #14 has been allocated to the host #1
0,00: VM #15 has been allocated to the host #1
0,00: VM #16 has been allocated to the host #2
0,00: VM #17 has been allocated to the host #2
0,00: VM #18 has been allocated to the host #2
0,00: VM #19 has been allocated to the host #2
0,00: VM #20 has been allocated to the host #2
0,00: VM #21 has been allocated to the host #2
0,00: VM #22 has been allocated to the host #2
0,00: VM #23 has been allocated to the host #2
0,00: VM #24 has been allocated to the host #3
0,00: VM #25 has been allocated to the host #3
0,00: VM #26 has been allocated to the host #3
0,00: VM #27 has been allocated to the host #3
0,00: VM #28 has been allocated to the host #3
0,00: VM #29 has been allocated to the host #3
0,00: VM #30 has been allocated to the host #3
0,00: VM #31 has been allocated to the host #3
0,00: VM #32 has been allocated to the host #4
0,00: VM #33 has been allocated to the host #4
0,00: VM #34 has been allocated to the host #4
0,00: VM #35 has been allocated to the host #4
0,00: VM #36 has been allocated to the host #4
0,00: VM #37 has been allocated to the host #4
0,00: VM #38 has been allocated to the host #4
0,00: VM #39 has been allocated to the host #4
0,00: VM #40 has been allocated to the host #5
0,00: VM #41 has been allocated to the host #5
0,00: VM #42 has been allocated to the host #5
0,00: VM #43 has been allocated to the host #5
0,00: VM #44 has been allocated to the host #5
0,00: VM #45 has been allocated to the host #5
0,00: VM #46 has been allocated to the host #5
0,00: VM #47 has been allocated to the host #5
0,00: VM #48 has been allocated to the host #6
0,00: VM #49 has been allocated to the host #6
0,00: VM #50 has been allocated to the host #6
0,00: VM #51 has been allocated to the host #6
0,00: VM #52 has been allocated to the host #6
0,00: VM #53 has been allocated to the host #6
0,00: VM #54 has been allocated to the host #6
0,00: VM #55 has been allocated to the host #6
0,00: VM #56 has been allocated to the host #7
0,00: VM #57 has been allocated to the host #7
0,00: VM #58 has been allocated to the host #7
0,00: VM #59 has been allocated to the host #7
0,00: VM #60 has been allocated to the host #7
0,00: VM #61 has been allocated to the host #7
0,00: VM #62 has been allocated to the host #7
0,00: VM #63 has been allocated to the host #7
0,00: VM #64 has been allocated to the host #8
0,00: VM #65 has been allocated to the host #8
0,00: VM #66 has been allocated to the host #8
0,00: VM #67 has been allocated to the host #8
0,00: VM #68 has been allocated to the host #8
0,00: VM #69 has been allocated to the host #8
0,00: VM #70 has been allocated to the host #8
0,00: VM #71 has been allocated to the host #8
0,00: VM #72 has been allocated to the host #9
0,00: VM #73 has been allocated to the host #9
0,00: VM #74 has been allocated to the host #9
0,00: VM #75 has been allocated to the host #9
0,00: VM #76 has been allocated to the host #9
0,00: VM #77 has been allocated to the host #9
0,00: VM #78 has been allocated to the host #9
0,00: VM #79 has been allocated to the host #9
0,00: VM #80 has been allocated to the host #10
0,00: VM #81 has been allocated to the host #10
0,00: VM #82 has been allocated to the host #10
0,00: VM #83 has been allocated to the host #10
0,00: VM #84 has been allocated to the host #10
0,00: VM #85 has been allocated to the host #10
0,00: VM #86 has been allocated to the host #10
0,00: VM #87 has been allocated to the host #10
0,00: VM #88 has been allocated to the host #11
0,00: VM #89 has been allocated to the host #11
0,00: VM #90 has been allocated to the host #11
0,00: VM #91 has been allocated to the host #11
0,00: VM #92 has been allocated to the host #11
0,00: VM #93 has been allocated to the host #11
0,00: VM #94 has been allocated to the host #11
0,00: VM #95 has been allocated to the host #11
0,00: VM #96 has been allocated to the host #12
0,00: VM #97 has been allocated to the host #12
0,00: VM #98 has been allocated to the host #12
0,00: VM #99 has been allocated to the host #12
0,00: VM #100 has been allocated to the host #12
0,00: VM #101 has been allocated to the host #12
0,00: VM #102 has been allocated to the host #12
0,00: VM #103 has been allocated to the host #12
0,00: VM #104 has been allocated to the host #13
0,00: VM #105 has been allocated to the host #13
0,00: VM #106 has been allocated to the host #13
0,00: VM #107 has been allocated to the host #13
0,00: VM #108 has been allocated to the host #13
0,00: VM #109 has been allocated to the host #13
0,00: VM #110 has been allocated to the host #13
0,00: VM #111 has been allocated to the host #13
0,00: VM #112 has been allocated to the host #14
0,00: VM #113 has been allocated to the host #14
0,00: VM #114 has been allocated to the host #14
0,00: VM #115 has been allocated to the host #14
0,00: VM #116 has been allocated to the host #14
0,00: VM #117 has been allocated to the host #14
0,00: VM #118 has been allocated to the host #14
0,00: VM #119 has been allocated to the host #14
0,00: VM #120 has been allocated to the host #15
0,00: VM #121 has been allocated to the host #15
0,00: VM #122 has been allocated to the host #15
0,00: VM #123 has been allocated to the host #15
0,00: VM #124 has been allocated to the host #15
0,00: VM #125 has been allocated to the host #15
0,00: VM #126 has been allocated to the host #15
0,00: VM #127 has been allocated to the host #15
0,00: VM #128 has been allocated to the host #16
0,00: VM #129 has been allocated to the host #16
0,00: VM #130 has been allocated to the host #16
0,00: VM #131 has been allocated to the host #16
0,00: VM #132 has been allocated to the host #16
0,00: VM #133 has been allocated to the host #16
0,00: VM #134 has been allocated to the host #16
0,00: VM #135 has been allocated to the host #16
0,00: VM #136 has been allocated to the host #17
0,00: VM #137 has been allocated to the host #17
0,00: VM #138 has been allocated to the host #17
0,00: VM #139 has been allocated to the host #17
0,00: VM #140 has been allocated to the host #17
0,00: VM #141 has been allocated to the host #17
0,00: VM #142 has been allocated to the host #17
0,00: VM #143 has been allocated to the host #17
0,00: VM #144 has been allocated to the host #18
0,00: VM #145 has been allocated to the host #18
0,00: VM #146 has been allocated to the host #18
0,00: VM #147 has been allocated to the host #18
0,00: VM #148 has been allocated to the host #18
0,00: VM #149 has been allocated to the host #18
0,00: VM #150 has been allocated to the host #18
0,00: VM #151 has been allocated to the host #18
0,00: VM #152 has been allocated to the host #19
0,00: VM #153 has been allocated to the host #19
0,00: VM #154 has been allocated to the host #19
0,00: VM #155 has been allocated to the host #19
0,00: VM #156 has been allocated to the host #19
0,00: VM #157 has been allocated to the host #19
0,00: VM #158 has been allocated to the host #19
0,00: VM #159 has been allocated to the host #19
0,00: VM #160 has been allocated to the host #20
0,00: VM #161 has been allocated to the host #20
0,00: VM #162 has been allocated to the host #20
0,00: VM #163 has been allocated to the host #20
0,00: VM #164 has been allocated to the host #20
0,00: VM #165 has been allocated to the host #20
0,00: VM #166 has been allocated to the host #20
0,00: VM #167 has been allocated to the host #20
0,00: VM #168 has been allocated to the host #21
0,00: VM #169 has been allocated to the host #21
0,00: VM #170 has been allocated to the host #21
0,00: VM #171 has been allocated to the host #21
0,00: VM #172 has been allocated to the host #21
0,00: VM #173 has been allocated to the host #21
0,00: VM #174 has been allocated to the host #21
0,00: VM #175 has been allocated to the host #21
0,00: VM #176 has been allocated to the host #22
0,00: VM #177 has been allocated to the host #22
0,00: VM #178 has been allocated to the host #22
0,00: VM #179 has been allocated to the host #22
0,00: VM #180 has been allocated to the host #22
0,00: VM #181 has been allocated to the host #22
0,00: VM #182 has been allocated to the host #22
0,00: VM #183 has been allocated to the host #22
0,00: VM #184 has been allocated to the host #23
0,00: VM #185 has been allocated to the host #23
0,00: VM #186 has been allocated to the host #23
0,00: VM #187 has been allocated to the host #23
0,00: VM #188 has been allocated to the host #23
0,00: VM #189 has been allocated to the host #23
0,00: VM #190 has been allocated to the host #23
0,00: VM #191 has been allocated to the host #23
0,00: VM #192 has been allocated to the host #24
0,00: VM #193 has been allocated to the host #24
0,00: VM #194 has been allocated to the host #24
0,00: VM #195 has been allocated to the host #24
0,00: VM #196 has been allocated to the host #24
0,00: VM #197 has been allocated to the host #24
0,00: VM #198 has been allocated to the host #24
0,00: VM #199 has been allocated to the host #24
0,00: VM #200 has been allocated to the host #25
0,00: VM #201 has been allocated to the host #25
0,00: VM #202 has been allocated to the host #25
0,00: VM #203 has been allocated to the host #25
0,00: VM #204 has been allocated to the host #25
0,00: VM #205 has been allocated to the host #25
0,00: VM #206 has been allocated to the host #25
0,00: VM #207 has been allocated to the host #25
0,00: VM #208 has been allocated to the host #26
0,00: VM #209 has been allocated to the host #26
0,00: VM #210 has been allocated to the host #26
0,00: VM #211 has been allocated to the host #26
0,00: VM #212 has been allocated to the host #26
0,00: VM #213 has been allocated to the host #26
0,00: VM #214 has been allocated to the host #26
0,00: VM #215 has been allocated to the host #26
0,00: VM #216 has been allocated to the host #27
0,00: VM #217 has been allocated to the host #27
0,00: VM #218 has been allocated to the host #27
0,00: VM #219 has been allocated to the host #27
0,00: VM #220 has been allocated to the host #27
0,00: VM #221 has been allocated to the host #27
0,00: VM #222 has been allocated to the host #27
0,00: VM #223 has been allocated to the host #27
0,00: VM #224 has been allocated to the host #28
0,00: VM #225 has been allocated to the host #28
0,00: VM #226 has been allocated to the host #28
0,00: VM #227 has been allocated to the host #28
0,00: VM #228 has been allocated to the host #28
0,00: VM #229 has been allocated to the host #28
0,00: VM #230 has been allocated to the host #28
0,00: VM #231 has been allocated to the host #28
0,00: VM #232 has been allocated to the host #29
0,00: VM #233 has been allocated to the host #29
0,00: VM #234 has been allocated to the host #29
0,00: VM #235 has been allocated to the host #29
0,00: VM #236 has been allocated to the host #29
0,00: VM #237 has been allocated to the host #29
0,00: VM #238 has been allocated to the host #29
0,00: VM #239 has been allocated to the host #29
0,00: VM #240 has been allocated to the host #30
0,00: VM #241 has been allocated to the host #30
0,00: VM #242 has been allocated to the host #30
0,00: VM #243 has been allocated to the host #30
0,00: VM #244 has been allocated to the host #30
0,00: VM #245 has been allocated to the host #30
0,00: VM #246 has been allocated to the host #30
0,00: VM #247 has been allocated to the host #30
0,00: VM #248 has been allocated to the host #31
0,00: VM #249 has been allocated to the host #31
0,00: VM #250 has been allocated to the host #31
0,00: VM #251 has been allocated to the host #31
0,00: VM #252 has been allocated to the host #31
0,00: VM #253 has been allocated to the host #31
0,00: VM #254 has been allocated to the host #31
0,00: VM #255 has been allocated to the host #31
0,00: VM #256 has been allocated to the host #32
0,00: VM #257 has been allocated to the host #32
0,00: VM #258 has been allocated to the host #32
0,00: VM #259 has been allocated to the host #32
0,00: VM #260 has been allocated to the host #32
0,00: VM #261 has been allocated to the host #32
0,00: VM #262 has been allocated to the host #32
0,00: VM #263 has been allocated to the host #32
0,00: VM #264 has been allocated to the host #33
0,00: VM #265 has been allocated to the host #33
0,00: VM #266 has been allocated to the host #33
0,00: VM #267 has been allocated to the host #33
0,00: VM #268 has been allocated to the host #33
0,00: VM #269 has been allocated to the host #33
0,00: VM #270 has been allocated to the host #33
0,00: VM #271 has been allocated to the host #33
0,00: VM #272 has been allocated to the host #34
0,00: VM #273 has been allocated to the host #34
0,00: VM #274 has been allocated to the host #34
0,00: VM #275 has been allocated to the host #34
0,00: VM #276 has been allocated to the host #34
0,00: VM #277 has been allocated to the host #34
0,00: VM #278 has been allocated to the host #34
0,00: VM #279 has been allocated to the host #34
0,00: VM #280 has been allocated to the host #35
0,00: VM #281 has been allocated to the host #35
0,00: VM #282 has been allocated to the host #35
0,00: VM #283 has been allocated to the host #35
0,00: VM #284 has been allocated to the host #35
0,00: VM #285 has been allocated to the host #35
0,00: VM #286 has been allocated to the host #35
0,00: VM #287 has been allocated to the host #35
0,00: VM #288 has been allocated to the host #36
0,00: VM #289 has been allocated to the host #36
0,00: VM #290 has been allocated to the host #36
0,00: VM #291 has been allocated to the host #36
0,00: VM #292 has been allocated to the host #36
0,00: VM #293 has been allocated to the host #36
0,00: VM #294 has been allocated to the host #36
0,00: VM #295 has been allocated to the host #36
0,00: VM #296 has been allocated to the host #37
0,00: VM #297 has been allocated to the host #37
0,00: VM #298 has been allocated to the host #37
0,00: VM #299 has been allocated to the host #37
0,00: VM #300 has been allocated to the host #37
0,00: VM #301 has been allocated to the host #37
0,00: VM #302 has been allocated to the host #37
0,00: VM #303 has been allocated to the host #38
0,00: VM #304 has been allocated to the host #38
0,00: VM #305 has been allocated to the host #38
0,00: VM #306 has been allocated to the host #38
0,00: VM #307 has been allocated to the host #38
0,00: VM #308 has been allocated to the host #39
0,00: VM #309 has been allocated to the host #39
0,00: VM #310 has been allocated to the host #39
0,00: VM #311 has been allocated to the host #39
0,00: VM #312 has been allocated to the host #39
0,00: VM #313 has been allocated to the host #40
0,00: VM #314 has been allocated to the host #40
0,00: VM #315 has been allocated to the host #40
0,00: VM #316 has been allocated to the host #40
0,00: VM #317 has been allocated to the host #40
0,00: VM #318 has been allocated to the host #41
0,00: VM #319 has been allocated to the host #41
0,00: VM #320 has been allocated to the host #41
0,00: VM #321 has been allocated to the host #41
0,00: VM #322 has been allocated to the host #41
0,00: VM #323 has been allocated to the host #42
0,00: VM #324 has been allocated to the host #42
0,00: VM #325 has been allocated to the host #42
0,00: VM #326 has been allocated to the host #42
0,00: VM #327 has been allocated to the host #42
0,00: VM #328 has been allocated to the host #43
0,00: VM #329 has been allocated to the host #43
0,00: VM #330 has been allocated to the host #43
0,00: VM #331 has been allocated to the host #43
0,00: VM #332 has been allocated to the host #43
0,00: VM #333 has been allocated to the host #44
0,00: VM #334 has been allocated to the host #44
0,00: VM #335 has been allocated to the host #44
0,00: VM #336 has been allocated to the host #44
0,00: VM #337 has been allocated to the host #44
0,00: VM #338 has been allocated to the host #45
0,00: VM #339 has been allocated to the host #45
0,00: VM #340 has been allocated to the host #45
0,00: VM #341 has been allocated to the host #45
0,00: VM #342 has been allocated to the host #45
0,00: VM #343 has been allocated to the host #46
0,00: VM #344 has been allocated to the host #46
0,00: VM #345 has been allocated to the host #46
0,00: VM #346 has been allocated to the host #46
0,00: VM #347 has been allocated to the host #46
0,00: VM #348 has been allocated to the host #47
0,00: VM #349 has been allocated to the host #47
0,00: VM #350 has been allocated to the host #47
0,00: VM #351 has been allocated to the host #47
0,00: VM #352 has been allocated to the host #47
0,00: VM #353 has been allocated to the host #48
0,00: VM #354 has been allocated to the host #48
0,00: VM #355 has been allocated to the host #48
0,00: VM #356 has been allocated to the host #48
0,00: VM #357 has been allocated to the host #48
0,00: VM #358 has been allocated to the host #49
0,00: VM #359 has been allocated to the host #49
0,00: VM #360 has been allocated to the host #49
0,00: VM #361 has been allocated to the host #49
0,00: VM #362 has been allocated to the host #49
0,00: VM #363 has been allocated to the host #50
0,00: VM #364 has been allocated to the host #50
0,00: VM #365 has been allocated to the host #50
0,00: VM #366 has been allocated to the host #50
0,00: VM #367 has been allocated to the host #50
0,00: VM #368 has been allocated to the host #51
0,00: VM #369 has been allocated to the host #51
0,00: VM #370 has been allocated to the host #51
0,00: VM #371 has been allocated to the host #51
0,00: VM #372 has been allocated to the host #51
0,00: VM #373 has been allocated to the host #52
0,00: VM #374 has been allocated to the host #52
0,00: VM #375 has been allocated to the host #52
0,00: VM #376 has been allocated to the host #52
0,00: VM #377 has been allocated to the host #52
0,00: VM #378 has been allocated to the host #53
0,00: VM #379 has been allocated to the host #53
0,00: VM #380 has been allocated to the host #53
0,00: VM #381 has been allocated to the host #53
0,00: VM #382 has been allocated to the host #53
0,00: VM #383 has been allocated to the host #54
0,00: VM #384 has been allocated to the host #54
0,00: VM #385 has been allocated to the host #54
0,00: VM #386 has been allocated to the host #54
0,00: VM #387 has been allocated to the host #54
0,00: VM #388 has been allocated to the host #55
0,00: VM #389 has been allocated to the host #55
0,00: VM #390 has been allocated to the host #55
0,00: VM #391 has been allocated to the host #55
0,00: VM #392 has been allocated to the host #55
0,00: VM #393 has been allocated to the host #56
0,00: VM #394 has been allocated to the host #56
0,00: VM #395 has been allocated to the host #56
0,00: VM #396 has been allocated to the host #56
0,00: VM #397 has been allocated to the host #56
0,00: VM #398 has been allocated to the host #57
0,00: VM #399 has been allocated to the host #57
0,00: VM #400 has been allocated to the host #57
0,00: VM #401 has been allocated to the host #57
0,00: VM #402 has been allocated to the host #57
0,00: VM #403 has been allocated to the host #58
0,00: VM #404 has been allocated to the host #58
0,00: VM #405 has been allocated to the host #58
0,00: VM #406 has been allocated to the host #58
0,00: VM #407 has been allocated to the host #58
0,00: VM #408 has been allocated to the host #59
0,00: VM #409 has been allocated to the host #59
0,00: VM #410 has been allocated to the host #59
0,00: VM #411 has been allocated to the host #59
0,00: VM #412 has been allocated to the host #59
0,00: VM #413 has been allocated to the host #60
0,00: VM #414 has been allocated to the host #60
0,00: VM #415 has been allocated to the host #60
0,00: VM #416 has been allocated to the host #60
0,00: VM #417 has been allocated to the host #60
0,00: VM #418 has been allocated to the host #61
0,00: VM #419 has been allocated to the host #61
0,00: VM #420 has been allocated to the host #61
0,00: VM #421 has been allocated to the host #61
0,00: VM #422 has been allocated to the host #61
0,00: VM #423 has been allocated to the host #62
0,00: VM #424 has been allocated to the host #62
0,00: VM #425 has been allocated to the host #62
0,00: VM #426 has been allocated to the host #62
0,00: VM #427 has been allocated to the host #62
0,00: VM #428 has been allocated to the host #63
0,00: VM #429 has been allocated to the host #63
0,00: VM #430 has been allocated to the host #63
0,00: VM #431 has been allocated to the host #63
0,00: VM #432 has been allocated to the host #63
0,00: VM #433 has been allocated to the host #64
0,00: VM #434 has been allocated to the host #64
0,00: VM #435 has been allocated to the host #64
0,00: VM #436 has been allocated to the host #64
0,00: VM #437 has been allocated to the host #64
0,00: VM #438 has been allocated to the host #65
0,00: VM #439 has been allocated to the host #65
0,00: VM #440 has been allocated to the host #65
0,00: VM #441 has been allocated to the host #65
0,00: VM #442 has been allocated to the host #65
0,00: VM #443 has been allocated to the host #66
0,00: VM #444 has been allocated to the host #66
0,00: VM #445 has been allocated to the host #66
0,00: VM #446 has been allocated to the host #66
0,00: VM #447 has been allocated to the host #66
0,00: VM #448 has been allocated to the host #67
0,00: VM #449 has been allocated to the host #67
0,00: VM #450 has been allocated to the host #67
0,00: VM #451 has been allocated to the host #67
0,00: VM #452 has been allocated to the host #67
0,00: VM #453 has been allocated to the host #68
0,00: VM #454 has been allocated to the host #68
0,00: VM #455 has been allocated to the host #68
0,00: VM #456 has been allocated to the host #68
0,00: VM #457 has been allocated to the host #68
0,00: VM #458 has been allocated to the host #69
0,00: VM #459 has been allocated to the host #69
0,00: VM #460 has been allocated to the host #69
0,00: VM #461 has been allocated to the host #69
0,00: VM #462 has been allocated to the host #69
0,00: VM #463 has been allocated to the host #70
0,00: VM #464 has been allocated to the host #70
0,00: VM #465 has been allocated to the host #70
0,00: VM #466 has been allocated to the host #70
0,00: VM #467 has been allocated to the host #70
0,00: VM #468 has been allocated to the host #71
0,00: VM #469 has been allocated to the host #71
0,00: VM #470 has been allocated to the host #71
0,00: VM #471 has been allocated to the host #71
0,00: VM #472 has been allocated to the host #71
0,00: VM #473 has been allocated to the host #72
0,00: VM #474 has been allocated to the host #72
0,00: VM #475 has been allocated to the host #72
0,00: VM #476 has been allocated to the host #72
0,00: VM #477 has been allocated to the host #72
0,00: VM #478 has been allocated to the host #73
0,00: VM #479 has been allocated to the host #73
0,00: VM #480 has been allocated to the host #73
0,00: VM #481 has been allocated to the host #73
0,00: VM #482 has been allocated to the host #73
0,00: VM #483 has been allocated to the host #74
0,00: VM #484 has been allocated to the host #74
0,00: VM #485 has been allocated to the host #74
0,00: VM #486 has been allocated to the host #74
0,00: VM #487 has been allocated to the host #74
0,00: VM #488 has been allocated to the host #75
0,00: VM #489 has been allocated to the host #75
0,00: VM #490 has been allocated to the host #75
0,00: VM #491 has been allocated to the host #75
0,00: VM #492 has been allocated to the host #75
0,00: VM #493 has been allocated to the host #76
0,00: VM #494 has been allocated to the host #76
0,00: VM #495 has been allocated to the host #76
0,00: VM #496 has been allocated to the host #76
0,00: VM #497 has been allocated to the host #76
0,00: VM #498 has been allocated to the host #77
0,00: VM #499 has been allocated to the host #77
0,00: VM #500 has been allocated to the host #77
0,00: VM #501 has been allocated to the host #77
0,00: VM #502 has been allocated to the host #77
0,00: VM #503 has been allocated to the host #78
0,00: VM #504 has been allocated to the host #78
0,00: VM #505 has been allocated to the host #78
0,00: VM #506 has been allocated to the host #78
0,00: VM #507 has been allocated to the host #78
0,00: VM #508 has been allocated to the host #79
0,00: VM #509 has been allocated to the host #79
0,00: VM #510 has been allocated to the host #79
0,00: VM #511 has been allocated to the host #79
0,00: VM #512 has been allocated to the host #79
0,00: VM #513 has been allocated to the host #80
0,00: VM #514 has been allocated to the host #80
0,00: VM #515 has been allocated to the host #80
0,00: VM #516 has been allocated to the host #80
0,00: VM #517 has been allocated to the host #80
0,00: VM #518 has been allocated to the host #81
0,00: VM #519 has been allocated to the host #81
0,00: VM #520 has been allocated to the host #81
0,00: VM #521 has been allocated to the host #81
0,00: VM #522 has been allocated to the host #81
0,00: VM #523 has been allocated to the host #82
0,00: VM #524 has been allocated to the host #82
0,00: VM #525 has been allocated to the host #82
0,00: VM #526 has been allocated to the host #82
0,00: VM #527 has been allocated to the host #82
0,00: VM #528 has been allocated to the host #83
0,00: VM #529 has been allocated to the host #83
0,00: VM #530 has been allocated to the host #83
0,00: VM #531 has been allocated to the host #83
0,00: VM #532 has been allocated to the host #83
0,00: VM #533 has been allocated to the host #84
0,00: VM #534 has been allocated to the host #84
0,00: VM #535 has been allocated to the host #84
0,00: VM #536 has been allocated to the host #84
0,00: VM #537 has been allocated to the host #84
0,00: VM #538 has been allocated to the host #85
0,00: VM #539 has been allocated to the host #85
0,00: VM #540 has been allocated to the host #85
0,00: VM #541 has been allocated to the host #85
0,00: VM #542 has been allocated to the host #85
0,00: VM #543 has been allocated to the host #86
0,00: VM #544 has been allocated to the host #86
0,00: VM #545 has been allocated to the host #86
0,00: VM #546 has been allocated to the host #86
0,00: VM #547 has been allocated to the host #86
0,00: VM #548 has been allocated to the host #87
0,00: VM #549 has been allocated to the host #87
0,00: VM #550 has been allocated to the host #87
0,00: VM #551 has been allocated to the host #87
0,00: VM #552 has been allocated to the host #87
0,00: VM #553 has been allocated to the host #88
0,00: VM #554 has been allocated to the host #88
0,00: VM #555 has been allocated to the host #88
0,00: VM #556 has been allocated to the host #88
0,00: VM #557 has been allocated to the host #88
0,00: VM #558 has been allocated to the host #89
0,00: VM #559 has been allocated to the host #89
0,00: VM #560 has been allocated to the host #89
0,00: VM #561 has been allocated to the host #89
0,00: VM #562 has been allocated to the host #89
0,00: VM #563 has been allocated to the host #90
0,00: VM #564 has been allocated to the host #90
0,00: VM #565 has been allocated to the host #90
0,00: VM #566 has been allocated to the host #90
0,00: VM #567 has been allocated to the host #90
0,00: VM #568 has been allocated to the host #91
0,00: VM #569 has been allocated to the host #91
0,00: VM #570 has been allocated to the host #91
0,00: VM #571 has been allocated to the host #91
0,00: VM #572 has been allocated to the host #91
0,00: VM #573 has been allocated to the host #92
0,00: VM #574 has been allocated to the host #92
0,00: VM #575 has been allocated to the host #92
0,00: VM #576 has been allocated to the host #92
0,00: VM #577 has been allocated to the host #92
0,00: VM #578 has been allocated to the host #93
0,00: VM #579 has been allocated to the host #93
0,00: VM #580 has been allocated to the host #93
0,00: VM #581 has been allocated to the host #93
0,00: VM #582 has been allocated to the host #93
0,00: VM #583 has been allocated to the host #94
0,00: VM #584 has been allocated to the host #94
0,00: VM #585 has been allocated to the host #94
0,00: VM #586 has been allocated to the host #94
0,00: VM #587 has been allocated to the host #94
0,00: VM #588 has been allocated to the host #95
0,00: VM #589 has been allocated to the host #95
0,00: VM #590 has been allocated to the host #95
0,00: VM #591 has been allocated to the host #95
0,00: VM #592 has been allocated to the host #95
0,00: VM #593 has been allocated to the host #96
0,00: VM #594 has been allocated to the host #96
0,00: VM #595 has been allocated to the host #96
0,00: VM #596 has been allocated to the host #96
0,00: VM #597 has been allocated to the host #96
0,00: VM #598 has been allocated to the host #97
0,00: VM #599 has been allocated to the host #97
0.1: Broker: VM #0 has been created in Datacenter #3, Host #0
0.1: Broker: VM #1 has been created in Datacenter #3, Host #0
0.1: Broker: VM #2 has been created in Datacenter #3, Host #0
0.1: Broker: VM #3 has been created in Datacenter #3, Host #0
0.1: Broker: VM #4 has been created in Datacenter #3, Host #0
0.1: Broker: VM #5 has been created in Datacenter #3, Host #0
0.1: Broker: VM #6 has been created in Datacenter #3, Host #0
0.1: Broker: VM #7 has been created in Datacenter #3, Host #0
0.1: Broker: VM #8 has been created in Datacenter #3, Host #1
0.1: Broker: VM #9 has been created in Datacenter #3, Host #1
0.1: Broker: VM #10 has been created in Datacenter #3, Host #1
0.1: Broker: VM #11 has been created in Datacenter #3, Host #1
0.1: Broker: VM #12 has been created in Datacenter #3, Host #1
0.1: Broker: VM #13 has been created in Datacenter #3, Host #1
0.1: Broker: VM #14 has been created in Datacenter #3, Host #1
0.1: Broker: VM #15 has been created in Datacenter #3, Host #1
0.1: Broker: VM #16 has been created in Datacenter #3, Host #2
0.1: Broker: VM #17 has been created in Datacenter #3, Host #2
0.1: Broker: VM #18 has been created in Datacenter #3, Host #2
0.1: Broker: VM #19 has been created in Datacenter #3, Host #2
0.1: Broker: VM #20 has been created in Datacenter #3, Host #2
0.1: Broker: VM #21 has been created in Datacenter #3, Host #2
0.1: Broker: VM #22 has been created in Datacenter #3, Host #2
0.1: Broker: VM #23 has been created in Datacenter #3, Host #2
0.1: Broker: VM #24 has been created in Datacenter #3, Host #3
0.1: Broker: VM #25 has been created in Datacenter #3, Host #3
0.1: Broker: VM #26 has been created in Datacenter #3, Host #3
0.1: Broker: VM #27 has been created in Datacenter #3, Host #3
0.1: Broker: VM #28 has been created in Datacenter #3, Host #3
0.1: Broker: VM #29 has been created in Datacenter #3, Host #3
0.1: Broker: VM #30 has been created in Datacenter #3, Host #3
0.1: Broker: VM #31 has been created in Datacenter #3, Host #3
0.1: Broker: VM #32 has been created in Datacenter #3, Host #4
0.1: Broker: VM #33 has been created in Datacenter #3, Host #4
0.1: Broker: VM #34 has been created in Datacenter #3, Host #4
0.1: Broker: VM #35 has been created in Datacenter #3, Host #4
0.1: Broker: VM #36 has been created in Datacenter #3, Host #4
0.1: Broker: VM #37 has been created in Datacenter #3, Host #4
0.1: Broker: VM #38 has been created in Datacenter #3, Host #4
0.1: Broker: VM #39 has been created in Datacenter #3, Host #4
0.1: Broker: VM #40 has been created in Datacenter #3, Host #5
0.1: Broker: VM #41 has been created in Datacenter #3, Host #5
0.1: Broker: VM #42 has been created in Datacenter #3, Host #5
0.1: Broker: VM #43 has been created in Datacenter #3, Host #5
0.1: Broker: VM #44 has been created in Datacenter #3, Host #5
0.1: Broker: VM #45 has been created in Datacenter #3, Host #5
0.1: Broker: VM #46 has been created in Datacenter #3, Host #5
0.1: Broker: VM #47 has been created in Datacenter #3, Host #5
0.1: Broker: VM #48 has been created in Datacenter #3, Host #6
0.1: Broker: VM #49 has been created in Datacenter #3, Host #6
0.1: Broker: VM #50 has been created in Datacenter #3, Host #6
0.1: Broker: VM #51 has been created in Datacenter #3, Host #6
0.1: Broker: VM #52 has been created in Datacenter #3, Host #6
0.1: Broker: VM #53 has been created in Datacenter #3, Host #6
0.1: Broker: VM #54 has been created in Datacenter #3, Host #6
0.1: Broker: VM #55 has been created in Datacenter #3, Host #6
0.1: Broker: VM #56 has been created in Datacenter #3, Host #7
0.1: Broker: VM #57 has been created in Datacenter #3, Host #7
0.1: Broker: VM #58 has been created in Datacenter #3, Host #7
0.1: Broker: VM #59 has been created in Datacenter #3, Host #7
0.1: Broker: VM #60 has been created in Datacenter #3, Host #7
0.1: Broker: VM #61 has been created in Datacenter #3, Host #7
0.1: Broker: VM #62 has been created in Datacenter #3, Host #7
0.1: Broker: VM #63 has been created in Datacenter #3, Host #7
0.1: Broker: VM #64 has been created in Datacenter #3, Host #8
0.1: Broker: VM #65 has been created in Datacenter #3, Host #8
0.1: Broker: VM #66 has been created in Datacenter #3, Host #8
0.1: Broker: VM #67 has been created in Datacenter #3, Host #8
0.1: Broker: VM #68 has been created in Datacenter #3, Host #8
0.1: Broker: VM #69 has been created in Datacenter #3, Host #8
0.1: Broker: VM #70 has been created in Datacenter #3, Host #8
0.1: Broker: VM #71 has been created in Datacenter #3, Host #8
0.1: Broker: VM #72 has been created in Datacenter #3, Host #9
0.1: Broker: VM #73 has been created in Datacenter #3, Host #9
0.1: Broker: VM #74 has been created in Datacenter #3, Host #9
0.1: Broker: VM #75 has been created in Datacenter #3, Host #9
0.1: Broker: VM #76 has been created in Datacenter #3, Host #9
0.1: Broker: VM #77 has been created in Datacenter #3, Host #9
0.1: Broker: VM #78 has been created in Datacenter #3, Host #9
0.1: Broker: VM #79 has been created in Datacenter #3, Host #9
0.1: Broker: VM #80 has been created in Datacenter #3, Host #10
0.1: Broker: VM #81 has been created in Datacenter #3, Host #10
0.1: Broker: VM #82 has been created in Datacenter #3, Host #10
0.1: Broker: VM #83 has been created in Datacenter #3, Host #10
0.1: Broker: VM #84 has been created in Datacenter #3, Host #10
0.1: Broker: VM #85 has been created in Datacenter #3, Host #10
0.1: Broker: VM #86 has been created in Datacenter #3, Host #10
0.1: Broker: VM #87 has been created in Datacenter #3, Host #10
0.1: Broker: VM #88 has been created in Datacenter #3, Host #11
0.1: Broker: VM #89 has been created in Datacenter #3, Host #11
0.1: Broker: VM #90 has been created in Datacenter #3, Host #11
0.1: Broker: VM #91 has been created in Datacenter #3, Host #11
0.1: Broker: VM #92 has been created in Datacenter #3, Host #11
0.1: Broker: VM #93 has been created in Datacenter #3, Host #11
0.1: Broker: VM #94 has been created in Datacenter #3, Host #11
0.1: Broker: VM #95 has been created in Datacenter #3, Host #11
0.1: Broker: VM #96 has been created in Datacenter #3, Host #12
0.1: Broker: VM #97 has been created in Datacenter #3, Host #12
0.1: Broker: VM #98 has been created in Datacenter #3, Host #12
0.1: Broker: VM #99 has been created in Datacenter #3, Host #12
0.1: Broker: VM #100 has been created in Datacenter #3, Host #12
0.1: Broker: VM #101 has been created in Datacenter #3, Host #12
0.1: Broker: VM #102 has been created in Datacenter #3, Host #12
0.1: Broker: VM #103 has been created in Datacenter #3, Host #12
0.1: Broker: VM #104 has been created in Datacenter #3, Host #13
0.1: Broker: VM #105 has been created in Datacenter #3, Host #13
0.1: Broker: VM #106 has been created in Datacenter #3, Host #13
0.1: Broker: VM #107 has been created in Datacenter #3, Host #13
0.1: Broker: VM #108 has been created in Datacenter #3, Host #13
0.1: Broker: VM #109 has been created in Datacenter #3, Host #13
0.1: Broker: VM #110 has been created in Datacenter #3, Host #13
0.1: Broker: VM #111 has been created in Datacenter #3, Host #13
0.1: Broker: VM #112 has been created in Datacenter #3, Host #14
0.1: Broker: VM #113 has been created in Datacenter #3, Host #14
0.1: Broker: VM #114 has been created in Datacenter #3, Host #14
0.1: Broker: VM #115 has been created in Datacenter #3, Host #14
0.1: Broker: VM #116 has been created in Datacenter #3, Host #14
0.1: Broker: VM #117 has been created in Datacenter #3, Host #14
0.1: Broker: VM #118 has been created in Datacenter #3, Host #14
0.1: Broker: VM #119 has been created in Datacenter #3, Host #14
0.1: Broker: VM #120 has been created in Datacenter #3, Host #15
0.1: Broker: VM #121 has been created in Datacenter #3, Host #15
0.1: Broker: VM #122 has been created in Datacenter #3, Host #15
0.1: Broker: VM #123 has been created in Datacenter #3, Host #15
0.1: Broker: VM #124 has been created in Datacenter #3, Host #15
0.1: Broker: VM #125 has been created in Datacenter #3, Host #15
0.1: Broker: VM #126 has been created in Datacenter #3, Host #15
0.1: Broker: VM #127 has been created in Datacenter #3, Host #15
0.1: Broker: VM #128 has been created in Datacenter #3, Host #16
0.1: Broker: VM #129 has been created in Datacenter #3, Host #16
0.1: Broker: VM #130 has been created in Datacenter #3, Host #16
0.1: Broker: VM #131 has been created in Datacenter #3, Host #16
0.1: Broker: VM #132 has been created in Datacenter #3, Host #16
0.1: Broker: VM #133 has been created in Datacenter #3, Host #16
0.1: Broker: VM #134 has been created in Datacenter #3, Host #16
0.1: Broker: VM #135 has been created in Datacenter #3, Host #16
0.1: Broker: VM #136 has been created in Datacenter #3, Host #17
0.1: Broker: VM #137 has been created in Datacenter #3, Host #17
0.1: Broker: VM #138 has been created in Datacenter #3, Host #17
0.1: Broker: VM #139 has been created in Datacenter #3, Host #17
0.1: Broker: VM #140 has been created in Datacenter #3, Host #17
0.1: Broker: VM #141 has been created in Datacenter #3, Host #17
0.1: Broker: VM #142 has been created in Datacenter #3, Host #17
0.1: Broker: VM #143 has been created in Datacenter #3, Host #17
0.1: Broker: VM #144 has been created in Datacenter #3, Host #18
0.1: Broker: VM #145 has been created in Datacenter #3, Host #18
0.1: Broker: VM #146 has been created in Datacenter #3, Host #18
0.1: Broker: VM #147 has been created in Datacenter #3, Host #18
0.1: Broker: VM #148 has been created in Datacenter #3, Host #18
0.1: Broker: VM #149 has been created in Datacenter #3, Host #18
0.1: Broker: VM #150 has been created in Datacenter #3, Host #18
0.1: Broker: VM #151 has been created in Datacenter #3, Host #18
0.1: Broker: VM #152 has been created in Datacenter #3, Host #19
0.1: Broker: VM #153 has been created in Datacenter #3, Host #19
0.1: Broker: VM #154 has been created in Datacenter #3, Host #19
0.1: Broker: VM #155 has been created in Datacenter #3, Host #19
0.1: Broker: VM #156 has been created in Datacenter #3, Host #19
0.1: Broker: VM #157 has been created in Datacenter #3, Host #19
0.1: Broker: VM #158 has been created in Datacenter #3, Host #19
0.1: Broker: VM #159 has been created in Datacenter #3, Host #19
0.1: Broker: VM #160 has been created in Datacenter #3, Host #20
0.1: Broker: VM #161 has been created in Datacenter #3, Host #20
0.1: Broker: VM #162 has been created in Datacenter #3, Host #20
0.1: Broker: VM #163 has been created in Datacenter #3, Host #20
0.1: Broker: VM #164 has been created in Datacenter #3, Host #20
0.1: Broker: VM #165 has been created in Datacenter #3, Host #20
0.1: Broker: VM #166 has been created in Datacenter #3, Host #20
0.1: Broker: VM #167 has been created in Datacenter #3, Host #20
0.1: Broker: VM #168 has been created in Datacenter #3, Host #21
0.1: Broker: VM #169 has been created in Datacenter #3, Host #21
0.1: Broker: VM #170 has been created in Datacenter #3, Host #21
0.1: Broker: VM #171 has been created in Datacenter #3, Host #21
0.1: Broker: VM #172 has been created in Datacenter #3, Host #21
0.1: Broker: VM #173 has been created in Datacenter #3, Host #21
0.1: Broker: VM #174 has been created in Datacenter #3, Host #21
0.1: Broker: VM #175 has been created in Datacenter #3, Host #21
0.1: Broker: VM #176 has been created in Datacenter #3, Host #22
0.1: Broker: VM #177 has been created in Datacenter #3, Host #22
0.1: Broker: VM #178 has been created in Datacenter #3, Host #22
0.1: Broker: VM #179 has been created in Datacenter #3, Host #22
0.1: Broker: VM #180 has been created in Datacenter #3, Host #22
0.1: Broker: VM #181 has been created in Datacenter #3, Host #22
0.1: Broker: VM #182 has been created in Datacenter #3, Host #22
0.1: Broker: VM #183 has been created in Datacenter #3, Host #22
0.1: Broker: VM #184 has been created in Datacenter #3, Host #23
0.1: Broker: VM #185 has been created in Datacenter #3, Host #23
0.1: Broker: VM #186 has been created in Datacenter #3, Host #23
0.1: Broker: VM #187 has been created in Datacenter #3, Host #23
0.1: Broker: VM #188 has been created in Datacenter #3, Host #23
0.1: Broker: VM #189 has been created in Datacenter #3, Host #23
0.1: Broker: VM #190 has been created in Datacenter #3, Host #23
0.1: Broker: VM #191 has been created in Datacenter #3, Host #23
0.1: Broker: VM #192 has been created in Datacenter #3, Host #24
0.1: Broker: VM #193 has been created in Datacenter #3, Host #24
0.1: Broker: VM #194 has been created in Datacenter #3, Host #24
0.1: Broker: VM #195 has been created in Datacenter #3, Host #24
0.1: Broker: VM #196 has been created in Datacenter #3, Host #24
0.1: Broker: VM #197 has been created in Datacenter #3, Host #24
0.1: Broker: VM #198 has been created in Datacenter #3, Host #24
0.1: Broker: VM #199 has been created in Datacenter #3, Host #24
0.1: Broker: VM #200 has been created in Datacenter #3, Host #25
0.1: Broker: VM #201 has been created in Datacenter #3, Host #25
0.1: Broker: VM #202 has been created in Datacenter #3, Host #25
0.1: Broker: VM #203 has been created in Datacenter #3, Host #25
0.1: Broker: VM #204 has been created in Datacenter #3, Host #25
0.1: Broker: VM #205 has been created in Datacenter #3, Host #25
0.1: Broker: VM #206 has been created in Datacenter #3, Host #25
0.1: Broker: VM #207 has been created in Datacenter #3, Host #25
0.1: Broker: VM #208 has been created in Datacenter #3, Host #26
0.1: Broker: VM #209 has been created in Datacenter #3, Host #26
0.1: Broker: VM #210 has been created in Datacenter #3, Host #26
0.1: Broker: VM #211 has been created in Datacenter #3, Host #26
0.1: Broker: VM #212 has been created in Datacenter #3, Host #26
0.1: Broker: VM #213 has been created in Datacenter #3, Host #26
0.1: Broker: VM #214 has been created in Datacenter #3, Host #26
0.1: Broker: VM #215 has been created in Datacenter #3, Host #26
0.1: Broker: VM #216 has been created in Datacenter #3, Host #27
0.1: Broker: VM #217 has been created in Datacenter #3, Host #27
0.1: Broker: VM #218 has been created in Datacenter #3, Host #27
0.1: Broker: VM #219 has been created in Datacenter #3, Host #27
0.1: Broker: VM #220 has been created in Datacenter #3, Host #27
0.1: Broker: VM #221 has been created in Datacenter #3, Host #27
0.1: Broker: VM #222 has been created in Datacenter #3, Host #27
0.1: Broker: VM #223 has been created in Datacenter #3, Host #27
0.1: Broker: VM #224 has been created in Datacenter #3, Host #28
0.1: Broker: VM #225 has been created in Datacenter #3, Host #28
0.1: Broker: VM #226 has been created in Datacenter #3, Host #28
0.1: Broker: VM #227 has been created in Datacenter #3, Host #28
0.1: Broker: VM #228 has been created in Datacenter #3, Host #28
0.1: Broker: VM #229 has been created in Datacenter #3, Host #28
0.1: Broker: VM #230 has been created in Datacenter #3, Host #28
0.1: Broker: VM #231 has been created in Datacenter #3, Host #28
0.1: Broker: VM #232 has been created in Datacenter #3, Host #29
0.1: Broker: VM #233 has been created in Datacenter #3, Host #29
0.1: Broker: VM #234 has been created in Datacenter #3, Host #29
0.1: Broker: VM #235 has been created in Datacenter #3, Host #29
0.1: Broker: VM #236 has been created in Datacenter #3, Host #29
0.1: Broker: VM #237 has been created in Datacenter #3, Host #29
0.1: Broker: VM #238 has been created in Datacenter #3, Host #29
0.1: Broker: VM #239 has been created in Datacenter #3, Host #29
0.1: Broker: VM #240 has been created in Datacenter #3, Host #30
0.1: Broker: VM #241 has been created in Datacenter #3, Host #30
0.1: Broker: VM #242 has been created in Datacenter #3, Host #30
0.1: Broker: VM #243 has been created in Datacenter #3, Host #30
0.1: Broker: VM #244 has been created in Datacenter #3, Host #30
0.1: Broker: VM #245 has been created in Datacenter #3, Host #30
0.1: Broker: VM #246 has been created in Datacenter #3, Host #30
0.1: Broker: VM #247 has been created in Datacenter #3, Host #30
0.1: Broker: VM #248 has been created in Datacenter #3, Host #31
0.1: Broker: VM #249 has been created in Datacenter #3, Host #31
0.1: Broker: VM #250 has been created in Datacenter #3, Host #31
0.1: Broker: VM #251 has been created in Datacenter #3, Host #31
0.1: Broker: VM #252 has been created in Datacenter #3, Host #31
0.1: Broker: VM #253 has been created in Datacenter #3, Host #31
0.1: Broker: VM #254 has been created in Datacenter #3, Host #31
0.1: Broker: VM #255 has been created in Datacenter #3, Host #31
0.1: Broker: VM #256 has been created in Datacenter #3, Host #32
0.1: Broker: VM #257 has been created in Datacenter #3, Host #32
0.1: Broker: VM #258 has been created in Datacenter #3, Host #32
0.1: Broker: VM #259 has been created in Datacenter #3, Host #32
0.1: Broker: VM #260 has been created in Datacenter #3, Host #32
0.1: Broker: VM #261 has been created in Datacenter #3, Host #32
0.1: Broker: VM #262 has been created in Datacenter #3, Host #32
0.1: Broker: VM #263 has been created in Datacenter #3, Host #32
0.1: Broker: VM #264 has been created in Datacenter #3, Host #33
0.1: Broker: VM #265 has been created in Datacenter #3, Host #33
0.1: Broker: VM #266 has been created in Datacenter #3, Host #33
0.1: Broker: VM #267 has been created in Datacenter #3, Host #33
0.1: Broker: VM #268 has been created in Datacenter #3, Host #33
0.1: Broker: VM #269 has been created in Datacenter #3, Host #33
0.1: Broker: VM #270 has been created in Datacenter #3, Host #33
0.1: Broker: VM #271 has been created in Datacenter #3, Host #33
0.1: Broker: VM #272 has been created in Datacenter #3, Host #34
0.1: Broker: VM #273 has been created in Datacenter #3, Host #34
0.1: Broker: VM #274 has been created in Datacenter #3, Host #34
0.1: Broker: VM #275 has been created in Datacenter #3, Host #34
0.1: Broker: VM #276 has been created in Datacenter #3, Host #34
0.1: Broker: VM #277 has been created in Datacenter #3, Host #34
0.1: Broker: VM #278 has been created in Datacenter #3, Host #34
0.1: Broker: VM #279 has been created in Datacenter #3, Host #34
0.1: Broker: VM #280 has been created in Datacenter #3, Host #35
0.1: Broker: VM #281 has been created in Datacenter #3, Host #35
0.1: Broker: VM #282 has been created in Datacenter #3, Host #35
0.1: Broker: VM #283 has been created in Datacenter #3, Host #35
0.1: Broker: VM #284 has been created in Datacenter #3, Host #35
0.1: Broker: VM #285 has been created in Datacenter #3, Host #35
0.1: Broker: VM #286 has been created in Datacenter #3, Host #35
0.1: Broker: VM #287 has been created in Datacenter #3, Host #35
0.1: Broker: VM #288 has been created in Datacenter #3, Host #36
0.1: Broker: VM #289 has been created in Datacenter #3, Host #36
0.1: Broker: VM #290 has been created in Datacenter #3, Host #36
0.1: Broker: VM #291 has been created in Datacenter #3, Host #36
0.1: Broker: VM #292 has been created in Datacenter #3, Host #36
0.1: Broker: VM #293 has been created in Datacenter #3, Host #36
0.1: Broker: VM #294 has been created in Datacenter #3, Host #36
0.1: Broker: VM #295 has been created in Datacenter #3, Host #36
0.1: Broker: VM #296 has been created in Datacenter #3, Host #37
0.1: Broker: VM #297 has been created in Datacenter #3, Host #37
0.1: Broker: VM #298 has been created in Datacenter #3, Host #37
0.1: Broker: VM #299 has been created in Datacenter #3, Host #37
0.1: Broker: VM #300 has been created in Datacenter #3, Host #37
0.1: Broker: VM #301 has been created in Datacenter #3, Host #37
0.1: Broker: VM #302 has been created in Datacenter #3, Host #37
0.1: Broker: VM #303 has been created in Datacenter #3, Host #38
0.1: Broker: VM #304 has been created in Datacenter #3, Host #38
0.1: Broker: VM #305 has been created in Datacenter #3, Host #38
0.1: Broker: VM #306 has been created in Datacenter #3, Host #38
0.1: Broker: VM #307 has been created in Datacenter #3, Host #38
0.1: Broker: VM #308 has been created in Datacenter #3, Host #39
0.1: Broker: VM #309 has been created in Datacenter #3, Host #39
0.1: Broker: VM #310 has been created in Datacenter #3, Host #39
0.1: Broker: VM #311 has been created in Datacenter #3, Host #39
0.1: Broker: VM #312 has been created in Datacenter #3, Host #39
0.1: Broker: VM #313 has been created in Datacenter #3, Host #40
0.1: Broker: VM #314 has been created in Datacenter #3, Host #40
0.1: Broker: VM #315 has been created in Datacenter #3, Host #40
0.1: Broker: VM #316 has been created in Datacenter #3, Host #40
0.1: Broker: VM #317 has been created in Datacenter #3, Host #40
0.1: Broker: VM #318 has been created in Datacenter #3, Host #41
0.1: Broker: VM #319 has been created in Datacenter #3, Host #41
0.1: Broker: VM #320 has been created in Datacenter #3, Host #41
0.1: Broker: VM #321 has been created in Datacenter #3, Host #41
0.1: Broker: VM #322 has been created in Datacenter #3, Host #41
0.1: Broker: VM #323 has been created in Datacenter #3, Host #42
0.1: Broker: VM #324 has been created in Datacenter #3, Host #42
0.1: Broker: VM #325 has been created in Datacenter #3, Host #42
0.1: Broker: VM #326 has been created in Datacenter #3, Host #42
0.1: Broker: VM #327 has been created in Datacenter #3, Host #42
0.1: Broker: VM #328 has been created in Datacenter #3, Host #43
0.1: Broker: VM #329 has been created in Datacenter #3, Host #43
0.1: Broker: VM #330 has been created in Datacenter #3, Host #43
0.1: Broker: VM #331 has been created in Datacenter #3, Host #43
0.1: Broker: VM #332 has been created in Datacenter #3, Host #43
0.1: Broker: VM #333 has been created in Datacenter #3, Host #44
0.1: Broker: VM #334 has been created in Datacenter #3, Host #44
0.1: Broker: VM #335 has been created in Datacenter #3, Host #44
0.1: Broker: VM #336 has been created in Datacenter #3, Host #44
0.1: Broker: VM #337 has been created in Datacenter #3, Host #44
0.1: Broker: VM #338 has been created in Datacenter #3, Host #45
0.1: Broker: VM #339 has been created in Datacenter #3, Host #45
0.1: Broker: VM #340 has been created in Datacenter #3, Host #45
0.1: Broker: VM #341 has been created in Datacenter #3, Host #45
0.1: Broker: VM #342 has been created in Datacenter #3, Host #45
0.1: Broker: VM #343 has been created in Datacenter #3, Host #46
0.1: Broker: VM #344 has been created in Datacenter #3, Host #46
0.1: Broker: VM #345 has been created in Datacenter #3, Host #46
0.1: Broker: VM #346 has been created in Datacenter #3, Host #46
0.1: Broker: VM #347 has been created in Datacenter #3, Host #46
0.1: Broker: VM #348 has been created in Datacenter #3, Host #47
0.1: Broker: VM #349 has been created in Datacenter #3, Host #47
0.1: Broker: VM #350 has been created in Datacenter #3, Host #47
0.1: Broker: VM #351 has been created in Datacenter #3, Host #47
0.1: Broker: VM #352 has been created in Datacenter #3, Host #47
0.1: Broker: VM #353 has been created in Datacenter #3, Host #48
0.1: Broker: VM #354 has been created in Datacenter #3, Host #48
0.1: Broker: VM #355 has been created in Datacenter #3, Host #48
0.1: Broker: VM #356 has been created in Datacenter #3, Host #48
0.1: Broker: VM #357 has been created in Datacenter #3, Host #48
0.1: Broker: VM #358 has been created in Datacenter #3, Host #49
0.1: Broker: VM #359 has been created in Datacenter #3, Host #49
0.1: Broker: VM #360 has been created in Datacenter #3, Host #49
0.1: Broker: VM #361 has been created in Datacenter #3, Host #49
0.1: Broker: VM #362 has been created in Datacenter #3, Host #49
0.1: Broker: VM #363 has been created in Datacenter #3, Host #50
0.1: Broker: VM #364 has been created in Datacenter #3, Host #50
0.1: Broker: VM #365 has been created in Datacenter #3, Host #50
0.1: Broker: VM #366 has been created in Datacenter #3, Host #50
0.1: Broker: VM #367 has been created in Datacenter #3, Host #50
0.1: Broker: VM #368 has been created in Datacenter #3, Host #51
0.1: Broker: VM #369 has been created in Datacenter #3, Host #51
0.1: Broker: VM #370 has been created in Datacenter #3, Host #51
0.1: Broker: VM #371 has been created in Datacenter #3, Host #51
0.1: Broker: VM #372 has been created in Datacenter #3, Host #51
0.1: Broker: VM #373 has been created in Datacenter #3, Host #52
0.1: Broker: VM #374 has been created in Datacenter #3, Host #52
0.1: Broker: VM #375 has been created in Datacenter #3, Host #52
0.1: Broker: VM #376 has been created in Datacenter #3, Host #52
0.1: Broker: VM #377 has been created in Datacenter #3, Host #52
0.1: Broker: VM #378 has been created in Datacenter #3, Host #53
0.1: Broker: VM #379 has been created in Datacenter #3, Host #53
0.1: Broker: VM #380 has been created in Datacenter #3, Host #53
0.1: Broker: VM #381 has been created in Datacenter #3, Host #53
0.1: Broker: VM #382 has been created in Datacenter #3, Host #53
0.1: Broker: VM #383 has been created in Datacenter #3, Host #54
0.1: Broker: VM #384 has been created in Datacenter #3, Host #54
0.1: Broker: VM #385 has been created in Datacenter #3, Host #54
0.1: Broker: VM #386 has been created in Datacenter #3, Host #54
0.1: Broker: VM #387 has been created in Datacenter #3, Host #54
0.1: Broker: VM #388 has been created in Datacenter #3, Host #55
0.1: Broker: VM #389 has been created in Datacenter #3, Host #55
0.1: Broker: VM #390 has been created in Datacenter #3, Host #55
0.1: Broker: VM #391 has been created in Datacenter #3, Host #55
0.1: Broker: VM #392 has been created in Datacenter #3, Host #55
0.1: Broker: VM #393 has been created in Datacenter #3, Host #56
0.1: Broker: VM #394 has been created in Datacenter #3, Host #56
0.1: Broker: VM #395 has been created in Datacenter #3, Host #56
0.1: Broker: VM #396 has been created in Datacenter #3, Host #56
0.1: Broker: VM #397 has been created in Datacenter #3, Host #56
0.1: Broker: VM #398 has been created in Datacenter #3, Host #57
0.1: Broker: VM #399 has been created in Datacenter #3, Host #57
0.1: Broker: VM #400 has been created in Datacenter #3, Host #57
0.1: Broker: VM #401 has been created in Datacenter #3, Host #57
0.1: Broker: VM #402 has been created in Datacenter #3, Host #57
0.1: Broker: VM #403 has been created in Datacenter #3, Host #58
0.1: Broker: VM #404 has been created in Datacenter #3, Host #58
0.1: Broker: VM #405 has been created in Datacenter #3, Host #58
0.1: Broker: VM #406 has been created in Datacenter #3, Host #58
0.1: Broker: VM #407 has been created in Datacenter #3, Host #58
0.1: Broker: VM #408 has been created in Datacenter #3, Host #59
0.1: Broker: VM #409 has been created in Datacenter #3, Host #59
0.1: Broker: VM #410 has been created in Datacenter #3, Host #59
0.1: Broker: VM #411 has been created in Datacenter #3, Host #59
0.1: Broker: VM #412 has been created in Datacenter #3, Host #59
0.1: Broker: VM #413 has been created in Datacenter #3, Host #60
0.1: Broker: VM #414 has been created in Datacenter #3, Host #60
0.1: Broker: VM #415 has been created in Datacenter #3, Host #60
0.1: Broker: VM #416 has been created in Datacenter #3, Host #60
0.1: Broker: VM #417 has been created in Datacenter #3, Host #60
0.1: Broker: VM #418 has been created in Datacenter #3, Host #61
0.1: Broker: VM #419 has been created in Datacenter #3, Host #61
0.1: Broker: VM #420 has been created in Datacenter #3, Host #61
0.1: Broker: VM #421 has been created in Datacenter #3, Host #61
0.1: Broker: VM #422 has been created in Datacenter #3, Host #61
0.1: Broker: VM #423 has been created in Datacenter #3, Host #62
0.1: Broker: VM #424 has been created in Datacenter #3, Host #62
0.1: Broker: VM #425 has been created in Datacenter #3, Host #62
0.1: Broker: VM #426 has been created in Datacenter #3, Host #62
0.1: Broker: VM #427 has been created in Datacenter #3, Host #62
0.1: Broker: VM #428 has been created in Datacenter #3, Host #63
0.1: Broker: VM #429 has been created in Datacenter #3, Host #63
0.1: Broker: VM #430 has been created in Datacenter #3, Host #63
0.1: Broker: VM #431 has been created in Datacenter #3, Host #63
0.1: Broker: VM #432 has been created in Datacenter #3, Host #63
0.1: Broker: VM #433 has been created in Datacenter #3, Host #64
0.1: Broker: VM #434 has been created in Datacenter #3, Host #64
0.1: Broker: VM #435 has been created in Datacenter #3, Host #64
0.1: Broker: VM #436 has been created in Datacenter #3, Host #64
0.1: Broker: VM #437 has been created in Datacenter #3, Host #64
0.1: Broker: VM #438 has been created in Datacenter #3, Host #65
0.1: Broker: VM #439 has been created in Datacenter #3, Host #65
0.1: Broker: VM #440 has been created in Datacenter #3, Host #65
0.1: Broker: VM #441 has been created in Datacenter #3, Host #65
0.1: Broker: VM #442 has been created in Datacenter #3, Host #65
0.1: Broker: VM #443 has been created in Datacenter #3, Host #66
0.1: Broker: VM #444 has been created in Datacenter #3, Host #66
0.1: Broker: VM #445 has been created in Datacenter #3, Host #66
0.1: Broker: VM #446 has been created in Datacenter #3, Host #66
0.1: Broker: VM #447 has been created in Datacenter #3, Host #66
0.1: Broker: VM #448 has been created in Datacenter #3, Host #67
0.1: Broker: VM #449 has been created in Datacenter #3, Host #67
0.1: Broker: VM #450 has been created in Datacenter #3, Host #67
0.1: Broker: VM #451 has been created in Datacenter #3, Host #67
0.1: Broker: VM #452 has been created in Datacenter #3, Host #67
0.1: Broker: VM #453 has been created in Datacenter #3, Host #68
0.1: Broker: VM #454 has been created in Datacenter #3, Host #68
0.1: Broker: VM #455 has been created in Datacenter #3, Host #68
0.1: Broker: VM #456 has been created in Datacenter #3, Host #68
0.1: Broker: VM #457 has been created in Datacenter #3, Host #68
0.1: Broker: VM #458 has been created in Datacenter #3, Host #69
0.1: Broker: VM #459 has been created in Datacenter #3, Host #69
0.1: Broker: VM #460 has been created in Datacenter #3, Host #69
0.1: Broker: VM #461 has been created in Datacenter #3, Host #69
0.1: Broker: VM #462 has been created in Datacenter #3, Host #69
0.1: Broker: VM #463 has been created in Datacenter #3, Host #70
0.1: Broker: VM #464 has been created in Datacenter #3, Host #70
0.1: Broker: VM #465 has been created in Datacenter #3, Host #70
0.1: Broker: VM #466 has been created in Datacenter #3, Host #70
0.1: Broker: VM #467 has been created in Datacenter #3, Host #70
0.1: Broker: VM #468 has been created in Datacenter #3, Host #71
0.1: Broker: VM #469 has been created in Datacenter #3, Host #71
0.1: Broker: VM #470 has been created in Datacenter #3, Host #71
0.1: Broker: VM #471 has been created in Datacenter #3, Host #71
0.1: Broker: VM #472 has been created in Datacenter #3, Host #71
0.1: Broker: VM #473 has been created in Datacenter #3, Host #72
0.1: Broker: VM #474 has been created in Datacenter #3, Host #72
0.1: Broker: VM #475 has been created in Datacenter #3, Host #72
0.1: Broker: VM #476 has been created in Datacenter #3, Host #72
0.1: Broker: VM #477 has been created in Datacenter #3, Host #72
0.1: Broker: VM #478 has been created in Datacenter #3, Host #73
0.1: Broker: VM #479 has been created in Datacenter #3, Host #73
0.1: Broker: VM #480 has been created in Datacenter #3, Host #73
0.1: Broker: VM #481 has been created in Datacenter #3, Host #73
0.1: Broker: VM #482 has been created in Datacenter #3, Host #73
0.1: Broker: VM #483 has been created in Datacenter #3, Host #74
0.1: Broker: VM #484 has been created in Datacenter #3, Host #74
0.1: Broker: VM #485 has been created in Datacenter #3, Host #74
0.1: Broker: VM #486 has been created in Datacenter #3, Host #74
0.1: Broker: VM #487 has been created in Datacenter #3, Host #74
0.1: Broker: VM #488 has been created in Datacenter #3, Host #75
0.1: Broker: VM #489 has been created in Datacenter #3, Host #75
0.1: Broker: VM #490 has been created in Datacenter #3, Host #75
0.1: Broker: VM #491 has been created in Datacenter #3, Host #75
0.1: Broker: VM #492 has been created in Datacenter #3, Host #75
0.1: Broker: VM #493 has been created in Datacenter #3, Host #76
0.1: Broker: VM #494 has been created in Datacenter #3, Host #76
0.1: Broker: VM #495 has been created in Datacenter #3, Host #76
0.1: Broker: VM #496 has been created in Datacenter #3, Host #76
0.1: Broker: VM #497 has been created in Datacenter #3, Host #76
0.1: Broker: VM #498 has been created in Datacenter #3, Host #77
0.1: Broker: VM #499 has been created in Datacenter #3, Host #77
0.1: Broker: VM #500 has been created in Datacenter #3, Host #77
0.1: Broker: VM #501 has been created in Datacenter #3, Host #77
0.1: Broker: VM #502 has been created in Datacenter #3, Host #77
0.1: Broker: VM #503 has been created in Datacenter #3, Host #78
0.1: Broker: VM #504 has been created in Datacenter #3, Host #78
0.1: Broker: VM #505 has been created in Datacenter #3, Host #78
0.1: Broker: VM #506 has been created in Datacenter #3, Host #78
0.1: Broker: VM #507 has been created in Datacenter #3, Host #78
0.1: Broker: VM #508 has been created in Datacenter #3, Host #79
0.1: Broker: VM #509 has been created in Datacenter #3, Host #79
0.1: Broker: VM #510 has been created in Datacenter #3, Host #79
0.1: Broker: VM #511 has been created in Datacenter #3, Host #79
0.1: Broker: VM #512 has been created in Datacenter #3, Host #79
0.1: Broker: VM #513 has been created in Datacenter #3, Host #80
0.1: Broker: VM #514 has been created in Datacenter #3, Host #80
0.1: Broker: VM #515 has been created in Datacenter #3, Host #80
0.1: Broker: VM #516 has been created in Datacenter #3, Host #80
0.1: Broker: VM #517 has been created in Datacenter #3, Host #80
0.1: Broker: VM #518 has been created in Datacenter #3, Host #81
0.1: Broker: VM #519 has been created in Datacenter #3, Host #81
0.1: Broker: VM #520 has been created in Datacenter #3, Host #81
0.1: Broker: VM #521 has been created in Datacenter #3, Host #81
0.1: Broker: VM #522 has been created in Datacenter #3, Host #81
0.1: Broker: VM #523 has been created in Datacenter #3, Host #82
0.1: Broker: VM #524 has been created in Datacenter #3, Host #82
0.1: Broker: VM #525 has been created in Datacenter #3, Host #82
0.1: Broker: VM #526 has been created in Datacenter #3, Host #82
0.1: Broker: VM #527 has been created in Datacenter #3, Host #82
0.1: Broker: VM #528 has been created in Datacenter #3, Host #83
0.1: Broker: VM #529 has been created in Datacenter #3, Host #83
0.1: Broker: VM #530 has been created in Datacenter #3, Host #83
0.1: Broker: VM #531 has been created in Datacenter #3, Host #83
0.1: Broker: VM #532 has been created in Datacenter #3, Host #83
0.1: Broker: VM #533 has been created in Datacenter #3, Host #84
0.1: Broker: VM #534 has been created in Datacenter #3, Host #84
0.1: Broker: VM #535 has been created in Datacenter #3, Host #84
0.1: Broker: VM #536 has been created in Datacenter #3, Host #84
0.1: Broker: VM #537 has been created in Datacenter #3, Host #84
0.1: Broker: VM #538 has been created in Datacenter #3, Host #85
0.1: Broker: VM #539 has been created in Datacenter #3, Host #85
0.1: Broker: VM #540 has been created in Datacenter #3, Host #85
0.1: Broker: VM #541 has been created in Datacenter #3, Host #85
0.1: Broker: VM #542 has been created in Datacenter #3, Host #85
0.1: Broker: VM #543 has been created in Datacenter #3, Host #86
0.1: Broker: VM #544 has been created in Datacenter #3, Host #86
0.1: Broker: VM #545 has been created in Datacenter #3, Host #86
0.1: Broker: VM #546 has been created in Datacenter #3, Host #86
0.1: Broker: VM #547 has been created in Datacenter #3, Host #86
0.1: Broker: VM #548 has been created in Datacenter #3, Host #87
0.1: Broker: VM #549 has been created in Datacenter #3, Host #87
0.1: Broker: VM #550 has been created in Datacenter #3, Host #87
0.1: Broker: VM #551 has been created in Datacenter #3, Host #87
0.1: Broker: VM #552 has been created in Datacenter #3, Host #87
0.1: Broker: VM #553 has been created in Datacenter #3, Host #88
0.1: Broker: VM #554 has been created in Datacenter #3, Host #88
0.1: Broker: VM #555 has been created in Datacenter #3, Host #88
0.1: Broker: VM #556 has been created in Datacenter #3, Host #88
0.1: Broker: VM #557 has been created in Datacenter #3, Host #88
0.1: Broker: VM #558 has been created in Datacenter #3, Host #89
0.1: Broker: VM #559 has been created in Datacenter #3, Host #89
0.1: Broker: VM #560 has been created in Datacenter #3, Host #89
0.1: Broker: VM #561 has been created in Datacenter #3, Host #89
0.1: Broker: VM #562 has been created in Datacenter #3, Host #89
0.1: Broker: VM #563 has been created in Datacenter #3, Host #90
0.1: Broker: VM #564 has been created in Datacenter #3, Host #90
0.1: Broker: VM #565 has been created in Datacenter #3, Host #90
0.1: Broker: VM #566 has been created in Datacenter #3, Host #90
0.1: Broker: VM #567 has been created in Datacenter #3, Host #90
0.1: Broker: VM #568 has been created in Datacenter #3, Host #91
0.1: Broker: VM #569 has been created in Datacenter #3, Host #91
0.1: Broker: VM #570 has been created in Datacenter #3, Host #91
0.1: Broker: VM #571 has been created in Datacenter #3, Host #91
0.1: Broker: VM #572 has been created in Datacenter #3, Host #91
0.1: Broker: VM #573 has been created in Datacenter #3, Host #92
0.1: Broker: VM #574 has been created in Datacenter #3, Host #92
0.1: Broker: VM #575 has been created in Datacenter #3, Host #92
0.1: Broker: VM #576 has been created in Datacenter #3, Host #92
0.1: Broker: VM #577 has been created in Datacenter #3, Host #92
0.1: Broker: VM #578 has been created in Datacenter #3, Host #93
0.1: Broker: VM #579 has been created in Datacenter #3, Host #93
0.1: Broker: VM #580 has been created in Datacenter #3, Host #93
0.1: Broker: VM #581 has been created in Datacenter #3, Host #93
0.1: Broker: VM #582 has been created in Datacenter #3, Host #93
0.1: Broker: VM #583 has been created in Datacenter #3, Host #94
0.1: Broker: VM #584 has been created in Datacenter #3, Host #94
0.1: Broker: VM #585 has been created in Datacenter #3, Host #94
0.1: Broker: VM #586 has been created in Datacenter #3, Host #94
0.1: Broker: VM #587 has been created in Datacenter #3, Host #94
0.1: Broker: VM #588 has been created in Datacenter #3, Host #95
0.1: Broker: VM #589 has been created in Datacenter #3, Host #95
0.1: Broker: VM #590 has been created in Datacenter #3, Host #95
0.1: Broker: VM #591 has been created in Datacenter #3, Host #95
0.1: Broker: VM #592 has been created in Datacenter #3, Host #95
0.1: Broker: VM #593 has been created in Datacenter #3, Host #96
0.1: Broker: VM #594 has been created in Datacenter #3, Host #96
0.1: Broker: VM #595 has been created in Datacenter #3, Host #96
0.1: Broker: VM #596 has been created in Datacenter #3, Host #96
0.1: Broker: VM #597 has been created in Datacenter #3, Host #96
0.1: Broker: VM #598 has been created in Datacenter #3, Host #97
0.1: Broker: VM #599 has been created in Datacenter #3, Host #97
0.1: Broker: Sending cloudlet 0 to VM #0
0.1: Broker: Sending cloudlet 1 to VM #1
0.1: Broker: Sending cloudlet 2 to VM #2
0.1: Broker: Sending cloudlet 3 to VM #3
0.1: Broker: Sending cloudlet 4 to VM #4
0.1: Broker: Sending cloudlet 5 to VM #5
0.1: Broker: Sending cloudlet 6 to VM #6
0.1: Broker: Sending cloudlet 7 to VM #7
0.1: Broker: Sending cloudlet 8 to VM #8
0.1: Broker: Sending cloudlet 9 to VM #9
0.1: Broker: Sending cloudlet 10 to VM #10
0.1: Broker: Sending cloudlet 11 to VM #11
0.1: Broker: Sending cloudlet 12 to VM #12
0.1: Broker: Sending cloudlet 13 to VM #13
0.1: Broker: Sending cloudlet 14 to VM #14
0.1: Broker: Sending cloudlet 15 to VM #15
