Initialising...
Simulation: Reached termination time.
Starting CloudSim version 3.0
Broker is starting...
Datacenter is starting...
Entities started.
0.0: Broker: Cloud Resource List received with 1 resource(s)
0.0: Broker: Trying to Create VM #0 in Datacenter
0.0: Broker: Trying to Create VM #1 in Datacenter
0.0: Broker: Trying to Create VM #2 in Datacenter
0.0: Broker: Trying to Create VM #3 in Datacenter
0.0: Broker: Trying to Create VM #4 in Datacenter
0.0: Broker: Trying to Create VM #5 in Datacenter
0.0: Broker: Trying to Create VM #6 in Datacenter
0.0: Broker: Trying to Create VM #7 in Datacenter
0.0: Broker: Trying to Create VM #8 in Datacenter
0.0: Broker: Trying to Create VM #9 in Datacenter
0.0: Broker: Trying to Create VM #10 in Datacenter
0.0: Broker: Trying to Create VM #11 in Datacenter
0.0: Broker: Trying to Create VM #12 in Datacenter
0.0: Broker: Trying to Create VM #13 in Datacenter
0.0: Broker: Trying to Create VM #14 in Datacenter
0.0: Broker: Trying to Create VM #15 in Datacenter
0,00: VM #0 has been allocated to the host #1
0,00: VM #1 has been allocated to the host #3
0,00: VM #2 has been allocated to the host #5
0,00: VM #3 has been allocated to the host #7
0,00: VM #4 has been allocated to the host #9
0,00: VM #5 has been allocated to the host #9
0,00: VM #6 has been allocated to the host #1
0,00: VM #7 has been allocated to the host #3
0,00: VM #8 has been allocated to the host #0
0,00: VM #9 has been allocated to the host #2
0,00: VM #10 has been allocated to the host #4
0,00: VM #11 has been allocated to the host #6
0,00: VM #12 has been allocated to the host #8
0,00: VM #13 has been allocated to the host #8
0,00: VM #14 has been allocated to the host #0
0,00: VM #15 has been allocated to the host #2
0.1: Broker: VM #0 has been created in Datacenter #3, Host #1
0.1: Broker: VM #1 has been created in Datacenter #3, Host #3
0.1: Broker: VM #2 has been created in Datacenter #3, Host #5
0.1: Broker: VM #3 has been created in Datacenter #3, Host #7
0.1: Broker: VM #4 has been created in Datacenter #3, Host #9
0.1: Broker: VM #5 has been created in Datacenter #3, Host #9
0.1: Broker: VM #6 has been created in Datacenter #3, Host #1
0.1: Broker: VM #7 has been created in Datacenter #3, Host #3
0.1: Broker: VM #8 has been created in Datacenter #3, Host #0
0.1: Broker: VM #9 has been created in Datacenter #3, Host #2
0.1: Broker: VM #10 has been created in Datacenter #3, Host #4
0.1: Broker: VM #11 has been created in Datacenter #3, Host #6
0.1: Broker: VM #12 has been created in Datacenter #3, Host #8
0.1: Broker: VM #13 has been created in Datacenter #3, Host #8
0.1: Broker: VM #14 has been created in Datacenter #3, Host #0
0.1: Broker: VM #15 has been created in Datacenter #3, Host #2
0.1: Broker: Sending cloudlet 0 to VM #0
0.1: Broker: Sending cloudlet 1 to VM #1
0.1: Broker: Sending cloudlet 2 to VM #2
0.1: Broker: Sending cloudlet 3 to VM #3
0.1: Broker: Sending cloudlet 4 to VM #4
0.1: Broker: Sending cloudlet 5 to VM #5
0.1: Broker: Sending cloudlet 6 to VM #6
0.1: Broker: Sending cloudlet 7 to VM #7
0.1: Broker: Sending cloudlet 8 to VM #8
0.1: Broker: Sending cloudlet 9 to VM #9
0.1: Broker: Sending cloudlet 10 to VM #10
0.1: Broker: Sending cloudlet 11 to VM #11
0.1: Broker: Sending cloudlet 12 to VM #12
0.1: Broker: Sending cloudlet 13 to VM #13
0.1: Broker: Sending cloudlet 14 to VM #14
0.1: Broker: Sending cloudlet 15 to VM #15


--------------------------------------------------------------


New resource usage for the time frame starting at 300,10:

300,10: [Host #0] IO processing of VM #8 elapsed time is 1,53396 s
300,10: [Host #0] IO processing of VM #14 elapsed time is 0,44717 s
300,10: [Host #0] Total allocated MIPS for VM #8 (Host #0) is 1000,00, was requested 1000,00 out of total 1000,00 (100,00%)
300,10: [Host #0] MIPS for VM #8 by PEs (2 * 1860.0). PE #0: 1000,00.
300,10: [Host #0] Total allocated MIPS for VM #14 (Host #0) is 500,00, was requested 500,00 out of total 500,00 (100,00%)
300,10: [Host #0] MIPS for VM #14 by PEs (2 * 1860.0). PE #0: 500,00.
300,10: [Host #0] utilization is 40,32%

300,10: [Host #1] IO processing of VM #0 elapsed time is 1,79623 s
300,10: [Host #1] IO processing of VM #6 elapsed time is 2,79811 s
300,10: [Host #1] Total allocated MIPS for VM #0 (Host #1) is 2500,00, was requested 2500,00 out of total 2500,00 (100,00%)
300,10: [Host #1] MIPS for VM #0 by PEs (2 * 2660.0). PE #0: 2500,00.
300,10: [Host #1] Total allocated MIPS for VM #6 (Host #1) is 2000,00, was requested 2000,00 out of total 2000,00 (100,00%)
300,10: [Host #1] MIPS for VM #6 by PEs (2 * 2660.0). PE #0: 160,00. PE #1: 1840,00.
300,10: [Host #1] utilization is 84,59%

300,10: [Host #2] IO processing of VM #9 elapsed time is 1,53396 s
300,10: [Host #2] IO processing of VM #15 elapsed time is 0,44717 s
300,10: [Host #2] Total allocated MIPS for VM #9 (Host #2) is 1000,00, was requested 1000,00 out of total 1000,00 (100,00%)
300,10: [Host #2] MIPS for VM #9 by PEs (2 * 1860.0). PE #0: 1000,00.
300,10: [Host #2] Total allocated MIPS for VM #15 (Host #2) is 500,00, was requested 500,00 out of total 500,00 (100,00%)
300,10: [Host #2] MIPS for VM #15 by PEs (2 * 1860.0). PE #0: 500,00.
300,10: [Host #2] utilization is 40,32%

300,10: [Host #3] IO processing of VM #1 elapsed time is 1,79623 s
300,10: [Host #3] IO processing of VM #7 elapsed time is 2,79811 s
300,10: [Host #3] Total allocated MIPS for VM #1 (Host #3) is 2500,00, was requested 2500,00 out of total 2500,00 (100,00%)
300,10: [Host #3] MIPS for VM #1 by PEs (2 * 2660.0). PE #0: 2500,00.
300,10: [Host #3] Total allocated MIPS for VM #7 (Host #3) is 2000,00, was requested 2000,00 out of total 2000,00 (100,00%)
300,10: [Host #3] MIPS for VM #7 by PEs (2 * 2660.0). PE #0: 160,00. PE #1: 1840,00.
300,10: [Host #3] utilization is 84,59%

300,10: [Host #4] IO processing of VM #10 elapsed time is 1,53396 s
300,10: [Host #4] Total allocated MIPS for VM #10 (Host #4) is 1000,00, was requested 1000,00 out of total 1000,00 (100,00%)
300,10: [Host #4] MIPS for VM #10 by PEs (2 * 1860.0). PE #0: 1000,00.
300,10: [Host #4] utilization is 26,88%

300,10: [Host #5] IO processing of VM #2 elapsed time is 1,79623 s
300,10: [Host #5] Total allocated MIPS for VM #2 (Host #5) is 2500,00, was requested 2500,00 out of total 2500,00 (100,00%)
300,10: [Host #5] MIPS for VM #2 by PEs (2 * 2660.0). PE #0: 2500,00.
300,10: [Host #5] utilization is 46,99%

300,10: [Host #6] IO processing of VM #11 elapsed time is 1,53396 s
300,10: [Host #6] Total allocated MIPS for VM #11 (Host #6) is 1000,00, was requested 1000,00 out of total 1000,00 (100,00%)
300,10: [Host #6] MIPS for VM #11 by PEs (2 * 1860.0). PE #0: 1000,00.
300,10: [Host #6] utilization is 26,88%

300,10: [Host #7] IO processing of VM #3 elapsed time is 1,79623 s
300,10: [Host #7] Total allocated MIPS for VM #3 (Host #7) is 2500,00, was requested 2500,00 out of total 2500,00 (100,00%)
300,10: [Host #7] MIPS for VM #3 by PEs (2 * 2660.0). PE #0: 2500,00.
300,10: [Host #7] utilization is 46,99%

300,10: [Host #8] IO processing of VM #12 elapsed time is 0,44717 s
300,10: [Host #8] IO processing of VM #13 elapsed time is 0,44717 s
300,10: [Host #8] Total allocated MIPS for VM #12 (Host #8) is 500,00, was requested 500,00 out of total 500,00 (100,00%)
300,10: [Host #8] MIPS for VM #12 by PEs (2 * 1860.0). PE #0: 500,00.
300,10: [Host #8] Total allocated MIPS for VM #13 (Host #8) is 500,00, was requested 500,00 out of total 500,00 (100,00%)
300,10: [Host #8] MIPS for VM #13 by PEs (2 * 1860.0). PE #0: 500,00.
300,10: [Host #8] utilization is 26,88%

300,10: [Host #9] IO processing of VM #4 elapsed time is 2,79811 s
300,10: [Host #9] IO processing of VM #5 elapsed time is 2,79811 s
300,10: [Host #9] Total allocated MIPS for VM #4 (Host #9) is 2000,00, was requested 2000,00 out of total 2000,00 (100,00%)
300,10: [Host #9] MIPS for VM #4 by PEs (2 * 2660.0). PE #0: 2000,00.
300,10: [Host #9] Total allocated MIPS for VM #5 (Host #9) is 2000,00, was requested 2000,00 out of total 2000,00 (100,00%)
300,10: [Host #9] MIPS for VM #5 by PEs (2 * 2660.0). PE #0: 660,00. PE #1: 1340,00.
300,10: [Host #9] utilization is 75,19%

Energy consumption for the last time frame from 0,00 to 300,10:

300,10: [Host #0] utilization at 0,00 was 0,00%, now is 40,32%
300,10: [Host #0] energy is 0,00 W*sec

300,10: [Host #1] utilization at 0,00 was 0,00%, now is 84,59%
300,10: [Host #1] energy is 0,00 W*sec

300,10: [Host #2] utilization at 0,00 was 0,00%, now is 40,32%
300,10: [Host #2] energy is 0,00 W*sec

300,10: [Host #3] utilization at 0,00 was 0,00%, now is 84,59%
300,10: [Host #3] energy is 0,00 W*sec

300,10: [Host #4] utilization at 0,00 was 0,00%, now is 26,88%
300,10: [Host #4] energy is 0,00 W*sec

300,10: [Host #5] utilization at 0,00 was 0,00%, now is 46,99%
300,10: [Host #5] energy is 0,00 W*sec

300,10: [Host #6] utilization at 0,00 was 0,00%, now is 26,88%
300,10: [Host #6] energy is 0,00 W*sec

300,10: [Host #7] utilization at 0,00 was 0,00%, now is 46,99%
300,10: [Host #7] energy is 0,00 W*sec

300,10: [Host #8] utilization at 0,00 was 0,00%, now is 26,88%
300,10: [Host #8] energy is 0,00 W*sec

300,10: [Host #9] utilization at 0,00 was 0,00%, now is 75,19%
300,10: [Host #9] energy is 0,00 W*sec

300,10: Data center's energy is 0,00 W*sec


Hamza: optimizeAllocation
Over-utilized hosts:

Reallocation of VMs from the over-utilized hosts:

Under-utilized host: host #9

Reallocation of VMs from the under-utilized host: 4 5 
VM #4 allocated to host #5
VM #5 allocated to host #7

Under-utilized host: host #8

Reallocation of VMs from the under-utilized host: 12 13 
VM #12 allocated to host #1
VM #13 allocated to host #3

Under-utilized host: host #6

Reallocation of VMs from the under-utilized host: 11 
VM #11 allocated to host #0

Under-utilized host: host #4

Reallocation of VMs from the under-utilized host: 10 
VM #10 allocated to host #2

300,10: Migration of VM #4 from Host #9 to Host #5 is started
300,10: [Host #5] Total allocated MIPS for VM #2 (Host #5) is 2500,00, was requested 2500,00 out of total 2500,00 (100,00%)
300,10: [Host #5] MIPS for VM #2 by PEs (2 * 2660.0). PE #0: 2500,00.
300,10: [Host #5] Total allocated MIPS for VM #4 (Host #9) is 200,00, was requested 2000,00 out of total 2000,00 (100,00%)
300,10: [Host #5] MIPS for VM #4 by PEs (2 * 2660.0). PE #0: 160,00. PE #1: 40,00.
300,10: [Host #5] VM #4 is being migrated to Host #5
300,10: [Host #9] Total allocated MIPS for VM #4 (Host #9) is 1800,00, was requested 2000,00 out of total 2000,00 (100,00%)
300,10: [Host #9] MIPS for VM #4 by PEs (2 * 2660.0). PE #0: 1800,00.
300,10: [Host #9] Under allocated MIPS for VM #4: 200,00
300,10: [Host #9] VM #4 is in migration
300,10: [Host #9] Total allocated MIPS for VM #5 (Host #9) is 2000,00, was requested 2000,00 out of total 2000,00 (100,00%)
300,10: [Host #9] MIPS for VM #5 by PEs (2 * 2660.0). PE #0: 860,00. PE #1: 1140,00.
300,10: Migration of VM #5 from Host #9 to Host #7 is started
300,10: [Host #7] Total allocated MIPS for VM #3 (Host #7) is 2500,00, was requested 2500,00 out of total 2500,00 (100,00%)
300,10: [Host #7] MIPS for VM #3 by PEs (2 * 2660.0). PE #0: 2500,00.
300,10: [Host #7] Total allocated MIPS for VM #5 (Host #9) is 200,00, was requested 2000,00 out of total 2000,00 (100,00%)
300,10: [Host #7] MIPS for VM #5 by PEs (2 * 2660.0). PE #0: 160,00. PE #1: 40,00.
300,10: [Host #7] VM #5 is being migrated to Host #7
300,10: [Host #9] Total allocated MIPS for VM #4 (Host #9) is 1800,00, was requested 2000,00 out of total 2000,00 (100,00%)
300,10: [Host #9] MIPS for VM #4 by PEs (2 * 2660.0). PE #0: 1800,00.
300,10: [Host #9] Under allocated MIPS for VM #4: 200,00
300,10: [Host #9] VM #4 is in migration
300,10: [Host #9] Total allocated MIPS for VM #5 (Host #9) is 1800,00, was requested 2000,00 out of total 2000,00 (100,00%)
300,10: [Host #9] MIPS for VM #5 by PEs (2 * 2660.0). PE #0: 860,00. PE #1: 940,00.
300,10: [Host #9] Under allocated MIPS for VM #5: 200,00
300,10: [Host #9] VM #5 is in migration
300,10: Migration of VM #12 from Host #8 to Host #1 is started
300,10: [Host #1] Total allocated MIPS for VM #0 (Host #1) is 2500,00, was requested 2500,00 out of total 2500,00 (100,00%)
300,10: [Host #1] MIPS for VM #0 by PEs (2 * 2660.0). PE #0: 2500,00.
300,10: [Host #1] Total allocated MIPS for VM #6 (Host #1) is 2000,00, was requested 2000,00 out of total 2000,00 (100,00%)
300,10: [Host #1] MIPS for VM #6 by PEs (2 * 2660.0). PE #0: 160,00. PE #1: 1840,00.
300,10: [Host #1] Total allocated MIPS for VM #12 (Host #8) is 50,00, was requested 500,00 out of total 500,00 (100,00%)
300,10: [Host #1] MIPS for VM #12 by PEs (2 * 2660.0). PE #1: 50,00.
300,10: [Host #1] VM #12 is being migrated to Host #1
300,10: [Host #8] Total allocated MIPS for VM #12 (Host #8) is 450,00, was requested 500,00 out of total 500,00 (100,00%)
300,10: [Host #8] MIPS for VM #12 by PEs (2 * 1860.0). PE #0: 450,00.
300,10: [Host #8] Under allocated MIPS for VM #12: 50,00
300,10: [Host #8] VM #12 is in migration
300,10: [Host #8] Total allocated MIPS for VM #13 (Host #8) is 500,00, was requested 500,00 out of total 500,00 (100,00%)
300,10: [Host #8] MIPS for VM #13 by PEs (2 * 1860.0). PE #0: 500,00.
300,10: Migration of VM #13 from Host #8 to Host #3 is started
300,10: [Host #3] Total allocated MIPS for VM #1 (Host #3) is 2500,00, was requested 2500,00 out of total 2500,00 (100,00%)
300,10: [Host #3] MIPS for VM #1 by PEs (2 * 2660.0). PE #0: 2500,00.
300,10: [Host #3] Total allocated MIPS for VM #7 (Host #3) is 2000,00, was requested 2000,00 out of total 2000,00 (100,00%)
300,10: [Host #3] MIPS for VM #7 by PEs (2 * 2660.0). PE #0: 110,00. PE #1: 1890,00.
300,10: [Host #3] Total allocated MIPS for VM #13 (Host #8) is 50,00, was requested 500,00 out of total 500,00 (100,00%)
300,10: [Host #3] MIPS for VM #13 by PEs (2 * 2660.0). PE #0: 50,00.
300,10: [Host #3] VM #13 is being migrated to Host #3
300,10: [Host #8] Total allocated MIPS for VM #12 (Host #8) is 450,00, was requested 500,00 out of total 500,00 (100,00%)
300,10: [Host #8] MIPS for VM #12 by PEs (2 * 1860.0). PE #0: 450,00.
300,10: [Host #8] Under allocated MIPS for VM #12: 50,00
300,10: [Host #8] VM #12 is in migration
300,10: [Host #8] Total allocated MIPS for VM #13 (Host #8) is 450,00, was requested 500,00 out of total 500,00 (100,00%)
300,10: [Host #8] MIPS for VM #13 by PEs (2 * 1860.0). PE #0: 450,00.
300,10: [Host #8] Under allocated MIPS for VM #13: 50,00
300,10: [Host #8] VM #13 is in migration
300,10: Migration of VM #11 from Host #6 to Host #0 is started
300,10: [Host #0] Total allocated MIPS for VM #8 (Host #0) is 1000,00, was requested 1000,00 out of total 1000,00 (100,00%)
300,10: [Host #0] MIPS for VM #8 by PEs (2 * 1860.0). PE #0: 1000,00.
300,10: [Host #0] Total allocated MIPS for VM #14 (Host #0) is 500,00, was requested 500,00 out of total 500,00 (100,00%)
300,10: [Host #0] MIPS for VM #14 by PEs (2 * 1860.0). PE #0: 500,00.
300,10: [Host #0] Total allocated MIPS for VM #11 (Host #6) is 100,00, was requested 1000,00 out of total 1000,00 (100,00%)
300,10: [Host #0] MIPS for VM #11 by PEs (2 * 1860.0). PE #0: 100,00.
300,10: [Host #0] VM #11 is being migrated to Host #0
300,10: [Host #6] Total allocated MIPS for VM #11 (Host #6) is 900,00, was requested 1000,00 out of total 1000,00 (100,00%)
300,10: [Host #6] MIPS for VM #11 by PEs (2 * 1860.0). PE #0: 900,00.
300,10: [Host #6] Under allocated MIPS for VM #11: 100,00
300,10: [Host #6] VM #11 is in migration
300,10: Migration of VM #10 from Host #4 to Host #2 is started
300,10: [Host #2] Total allocated MIPS for VM #9 (Host #2) is 1000,00, was requested 1000,00 out of total 1000,00 (100,00%)
300,10: [Host #2] MIPS for VM #9 by PEs (2 * 1860.0). PE #0: 1000,00.
300,10: [Host #2] Total allocated MIPS for VM #15 (Host #2) is 500,00, was requested 500,00 out of total 500,00 (100,00%)
300,10: [Host #2] MIPS for VM #15 by PEs (2 * 1860.0). PE #0: 500,00.
300,10: [Host #2] Total allocated MIPS for VM #10 (Host #4) is 100,00, was requested 1000,00 out of total 1000,00 (100,00%)
300,10: [Host #2] MIPS for VM #10 by PEs (2 * 1860.0). PE #0: 100,00.
300,10: [Host #2] VM #10 is being migrated to Host #2
300,10: [Host #4] Total allocated MIPS for VM #10 (Host #4) is 900,00, was requested 1000,00 out of total 1000,00 (100,00%)
300,10: [Host #4] MIPS for VM #10 by PEs (2 * 1860.0). PE #0: 900,00.
300,10: [Host #4] Under allocated MIPS for VM #10: 100,00
300,10: [Host #4] VM #10 is in migration
300.1: Broker: Cloudlet 1 received


--------------------------------------------------------------


New resource usage for the time frame starting at 340,10:

340,10: [Host #0] IO processing of VM #8 elapsed time is 1,53396 s
340,10: [Host #0] IO processing of VM #14 elapsed time is 0,44717 s
340,10: [Host #0] Total allocated MIPS for VM #8 (Host #0) is 1000,00, was requested 1000,00 out of total 1000,00 (100,00%)
340,10: [Host #0] MIPS for VM #8 by PEs (2 * 1860.0). PE #0: 1000,00.
340,10: [Host #0] Total allocated MIPS for VM #14 (Host #0) is 500,00, was requested 500,00 out of total 500,00 (100,00%)
340,10: [Host #0] MIPS for VM #14 by PEs (2 * 1860.0). PE #0: 500,00.
340,10: [Host #0] Total allocated MIPS for VM #11 (Host #6) is 100,00, was requested 1000,00 out of total 1000,00 (100,00%)
340,10: [Host #0] MIPS for VM #11 by PEs (2 * 1860.0). PE #0: 100,00.
340,10: [Host #0] VM #11 is being migrated to Host #0
340,10: [Host #0] utilization is 43,01%

340,10: [Host #1] IO processing of VM #0 elapsed time is 1,79623 s
340,10: [Host #1] IO processing of VM #6 elapsed time is 2,79811 s
340,10: [Host #1] Total allocated MIPS for VM #0 (Host #1) is 2500,00, was requested 2500,00 out of total 2500,00 (100,00%)
340,10: [Host #1] MIPS for VM #0 by PEs (2 * 2660.0). PE #0: 2500,00.
340,10: [Host #1] Total allocated MIPS for VM #6 (Host #1) is 2000,00, was requested 2000,00 out of total 2000,00 (100,00%)
340,10: [Host #1] MIPS for VM #6 by PEs (2 * 2660.0). PE #0: 160,00. PE #1: 1840,00.
340,10: [Host #1] Total allocated MIPS for VM #12 (Host #8) is 50,00, was requested 500,00 out of total 500,00 (100,00%)
340,10: [Host #1] MIPS for VM #12 by PEs (2 * 2660.0). PE #1: 50,00.
340,10: [Host #1] VM #12 is being migrated to Host #1
340,10: [Host #1] utilization is 85,53%

340,10: [Host #2] IO processing of VM #9 elapsed time is 1,53396 s
340,10: [Host #2] IO processing of VM #15 elapsed time is 0,44717 s
340,10: [Host #2] Total allocated MIPS for VM #9 (Host #2) is 1000,00, was requested 1000,00 out of total 1000,00 (100,00%)
340,10: [Host #2] MIPS for VM #9 by PEs (2 * 1860.0). PE #0: 1000,00.
340,10: [Host #2] Total allocated MIPS for VM #15 (Host #2) is 500,00, was requested 500,00 out of total 500,00 (100,00%)
340,10: [Host #2] MIPS for VM #15 by PEs (2 * 1860.0). PE #0: 500,00.
340,10: [Host #2] Total allocated MIPS for VM #10 (Host #4) is 100,00, was requested 1000,00 out of total 1000,00 (100,00%)
340,10: [Host #2] MIPS for VM #10 by PEs (2 * 1860.0). PE #0: 100,00.
340,10: [Host #2] VM #10 is being migrated to Host #2
340,10: [Host #2] utilization is 43,01%

340,10: [Host #3] IO processing of VM #1 elapsed time is 1,79623 s
340,10: [Host #3] IO processing of VM #7 elapsed time is 2,79811 s
340,10: [Host #3] Total allocated MIPS for VM #1 (Host #3) is 2500,00, was requested 2500,00 out of total 2500,00 (100,00%)
340,10: [Host #3] MIPS for VM #1 by PEs (2 * 2660.0). PE #0: 2500,00.
340,10: [Host #3] Total allocated MIPS for VM #7 (Host #3) is 2000,00, was requested 2000,00 out of total 2000,00 (100,00%)
340,10: [Host #3] MIPS for VM #7 by PEs (2 * 2660.0). PE #0: 110,00. PE #1: 1890,00.
340,10: [Host #3] Total allocated MIPS for VM #13 (Host #8) is 50,00, was requested 500,00 out of total 500,00 (100,00%)
340,10: [Host #3] MIPS for VM #13 by PEs (2 * 2660.0). PE #0: 50,00.
340,10: [Host #3] VM #13 is being migrated to Host #3
340,10: [Host #3] utilization is 85,53%

340,10: [Host #4] IO processing of VM #10 elapsed time is 1,53396 s
340,10: [Host #4] Total allocated MIPS for VM #10 (Host #4) is 900,00, was requested 1000,00 out of total 1000,00 (100,00%)
340,10: [Host #4] MIPS for VM #10 by PEs (2 * 1860.0). PE #0: 900,00.
340,10: [Host #4] Under allocated MIPS for VM #10: 100,00
340,10: [Host #4] VM #10 is in migration
340,10: [Host #4] utilization is 26,88%

340,10: [Host #5] IO processing of VM #2 elapsed time is 1,79623 s
340,10: [Host #5] Total allocated MIPS for VM #2 (Host #5) is 2500,00, was requested 2500,00 out of total 2500,00 (100,00%)
340,10: [Host #5] MIPS for VM #2 by PEs (2 * 2660.0). PE #0: 2500,00.
340,10: [Host #5] Total allocated MIPS for VM #4 (Host #9) is 200,00, was requested 2000,00 out of total 2000,00 (100,00%)
340,10: [Host #5] MIPS for VM #4 by PEs (2 * 2660.0). PE #0: 160,00. PE #1: 40,00.
340,10: [Host #5] VM #4 is being migrated to Host #5
340,10: [Host #5] utilization is 50,75%

340,10: [Host #6] IO processing of VM #11 elapsed time is 1,53396 s
340,10: [Host #6] Total allocated MIPS for VM #11 (Host #6) is 900,00, was requested 1000,00 out of total 1000,00 (100,00%)
340,10: [Host #6] MIPS for VM #11 by PEs (2 * 1860.0). PE #0: 900,00.
340,10: [Host #6] Under allocated MIPS for VM #11: 100,00
340,10: [Host #6] VM #11 is in migration
340,10: [Host #6] utilization is 26,88%

340,10: [Host #7] IO processing of VM #3 elapsed time is 1,79623 s
340,10: [Host #7] Total allocated MIPS for VM #3 (Host #7) is 2500,00, was requested 2500,00 out of total 2500,00 (100,00%)
340,10: [Host #7] MIPS for VM #3 by PEs (2 * 2660.0). PE #0: 2500,00.
340,10: [Host #7] Total allocated MIPS for VM #5 (Host #9) is 200,00, was requested 2000,00 out of total 2000,00 (100,00%)
340,10: [Host #7] MIPS for VM #5 by PEs (2 * 2660.0). PE #0: 160,00. PE #1: 40,00.
340,10: [Host #7] VM #5 is being migrated to Host #7
340,10: [Host #7] utilization is 50,75%

340,10: [Host #8] IO processing of VM #12 elapsed time is 0,44717 s
340,10: [Host #8] IO processing of VM #13 elapsed time is 0,44717 s
340,10: [Host #8] Total allocated MIPS for VM #12 (Host #8) is 450,00, was requested 500,00 out of total 500,00 (100,00%)
340,10: [Host #8] MIPS for VM #12 by PEs (2 * 1860.0). PE #0: 450,00.
340,10: [Host #8] Under allocated MIPS for VM #12: 50,00
340,10: [Host #8] VM #12 is in migration
340,10: [Host #8] Total allocated MIPS for VM #13 (Host #8) is 450,00, was requested 500,00 out of total 500,00 (100,00%)
340,10: [Host #8] MIPS for VM #13 by PEs (2 * 1860.0). PE #0: 450,00.
340,10: [Host #8] Under allocated MIPS for VM #13: 50,00
340,10: [Host #8] VM #13 is in migration
340,10: [Host #8] utilization is 26,88%

340,10: [Host #9] IO processing of VM #4 elapsed time is 2,79811 s
340,10: [Host #9] IO processing of VM #5 elapsed time is 2,79811 s
340,10: [Host #9] Total allocated MIPS for VM #4 (Host #9) is 1800,00, was requested 2000,00 out of total 2000,00 (100,00%)
340,10: [Host #9] MIPS for VM #4 by PEs (2 * 2660.0). PE #0: 1800,00.
340,10: [Host #9] Under allocated MIPS for VM #4: 200,00
340,10: [Host #9] VM #4 is in migration
340,10: [Host #9] Total allocated MIPS for VM #5 (Host #9) is 1800,00, was requested 2000,00 out of total 2000,00 (100,00%)
340,10: [Host #9] MIPS for VM #5 by PEs (2 * 2660.0). PE #0: 860,00. PE #1: 940,00.
340,10: [Host #9] Under allocated MIPS for VM #5: 200,00
340,10: [Host #9] VM #5 is in migration
340,10: [Host #9] utilization is 75,19%

Energy consumption for the last time frame from 300,10 to 340,10:

340,10: [Host #0] utilization at 300,10 was 43,01%, now is 43,01%
340,10: [Host #0] energy is 2688,17 W*sec

340,10: [Host #1] utilization at 300,10 was 85,53%, now is 85,53%
340,10: [Host #1] energy is 3368,42 W*sec

340,10: [Host #2] utilization at 300,10 was 43,01%, now is 43,01%
340,10: [Host #2] energy is 2688,17 W*sec

340,10: [Host #3] utilization at 300,10 was 85,53%, now is 85,53%
340,10: [Host #3] energy is 3368,42 W*sec

340,10: [Host #4] utilization at 300,10 was 26,88%, now is 26,88%
340,10: [Host #4] energy is 2430,11 W*sec

340,10: [Host #5] utilization at 300,10 was 50,75%, now is 50,75%
340,10: [Host #5] energy is 2812,03 W*sec

340,10: [Host #6] utilization at 300,10 was 26,88%, now is 26,88%
340,10: [Host #6] energy is 2430,11 W*sec

340,10: [Host #7] utilization at 300,10 was 50,75%, now is 50,75%
340,10: [Host #7] energy is 2812,03 W*sec

340,10: [Host #8] utilization at 300,10 was 26,88%, now is 26,88%
340,10: [Host #8] energy is 2430,11 W*sec

340,10: [Host #9] utilization at 300,10 was 75,19%, now is 75,19%
340,10: [Host #9] energy is 3203,01 W*sec

340,10: Data center's energy is 28230,58 W*sec

[MyStorageList.getDeviceContainsVm]: there is no device containing the vm 2-11
[MyStorageList.getDeviceContainsVm]: there is no device containing the vm 2-12
[MyStorageList.getDeviceContainsVm]: there is no device containing the vm 2-10
[MyStorageList.getDeviceContainsVm]: there is no device containing the vm 2-13
[MyStorageList.getDeviceContainsVm]: there is no device containing the vm 2-4
[MyStorageList.getDeviceContainsVm]: there is no device containing the vm 2-5

[MyStorageList.getDeviceContainsVm]: there is no device containing the vm 2-4
340,10: VM #4 has been allocated to the host #5
340,10: Migration of VM #4 to Host #5 is completed
[MyStorageList.getDeviceContainsVm]: there is no device containing the vm 2-5
340,10: VM #5 has been allocated to the host #7
340,10: Migration of VM #5 to Host #7 is completed
[MyStorageList.getDeviceContainsVm]: there is no device containing the vm 2-12
340,10: VM #12 has been allocated to the host #1
340,10: Migration of VM #12 to Host #1 is completed
[MyStorageList.getDeviceContainsVm]: there is no device containing the vm 2-13
340,10: VM #13 has been allocated to the host #3
340,10: Migration of VM #13 to Host #3 is completed
[MyStorageList.getDeviceContainsVm]: there is no device containing the vm 2-11
340,10: VM #11 has been allocated to the host #0
340,10: Migration of VM #11 to Host #0 is completed
[MyStorageList.getDeviceContainsVm]: there is no device containing the vm 2-10
340,10: VM #10 has been allocated to the host #2
340,10: Migration of VM #10 to Host #2 is completed


--------------------------------------------------------------


New resource usage for the time frame starting at 340,10:

340,10: [Host #0] IO processing of VM #8 elapsed time is 1,53396 s
340,10: [Host #0] IO processing of VM #14 elapsed time is 0,44717 s
340,10: [Host #0] IO processing of VM #11 elapsed time is 1,53396 s
340,10: [Host #0] Total allocated MIPS for VM #8 (Host #0) is 1000,00, was requested 1000,00 out of total 1000,00 (100,00%)
340,10: [Host #0] MIPS for VM #8 by PEs (2 * 1860.0). PE #0: 360,00. PE #1: 640,00.
340,10: [Host #0] Total allocated MIPS for VM #14 (Host #0) is 500,00, was requested 500,00 out of total 500,00 (100,00%)
340,10: [Host #0] MIPS for VM #14 by PEs (2 * 1860.0). PE #0: 500,00.
340,10: [Host #0] Total allocated MIPS for VM #11 (Host #0) is 1000,00, was requested 1000,00 out of total 1000,00 (100,00%)
340,10: [Host #0] MIPS for VM #11 by PEs (2 * 1860.0). PE #0: 1000,00.
340,10: [Host #0] utilization is 67,20%

340,10: [Host #1] IO processing of VM #0 elapsed time is 1,79623 s
340,10: [Host #1] IO processing of VM #6 elapsed time is 2,79811 s
340,10: [Host #1] IO processing of VM #12 elapsed time is 0,44717 s
340,10: [Host #1] Total allocated MIPS for VM #0 (Host #1) is 2500,00, was requested 2500,00 out of total 2500,00 (100,00%)
340,10: [Host #1] MIPS for VM #0 by PEs (2 * 2660.0). PE #0: 2500,00.
340,10: [Host #1] Total allocated MIPS for VM #6 (Host #1) is 2000,00, was requested 2000,00 out of total 2000,00 (100,00%)
340,10: [Host #1] MIPS for VM #6 by PEs (2 * 2660.0). PE #0: 160,00. PE #1: 1840,00.
340,10: [Host #1] Total allocated MIPS for VM #12 (Host #1) is 500,00, was requested 500,00 out of total 500,00 (100,00%)
340,10: [Host #1] MIPS for VM #12 by PEs (2 * 2660.0). PE #1: 500,00.
340,10: [Host #1] utilization is 93,98%

340,10: [Host #2] IO processing of VM #9 elapsed time is 1,53396 s
340,10: [Host #2] IO processing of VM #15 elapsed time is 0,44717 s
340,10: [Host #2] IO processing of VM #10 elapsed time is 1,53396 s
340,10: [Host #2] Total allocated MIPS for VM #9 (Host #2) is 1000,00, was requested 1000,00 out of total 1000,00 (100,00%)
340,10: [Host #2] MIPS for VM #9 by PEs (2 * 1860.0). PE #0: 360,00. PE #1: 640,00.
340,10: [Host #2] Total allocated MIPS for VM #15 (Host #2) is 500,00, was requested 500,00 out of total 500,00 (100,00%)
340,10: [Host #2] MIPS for VM #15 by PEs (2 * 1860.0). PE #0: 500,00.
340,10: [Host #2] Total allocated MIPS for VM #10 (Host #2) is 1000,00, was requested 1000,00 out of total 1000,00 (100,00%)
340,10: [Host #2] MIPS for VM #10 by PEs (2 * 1860.0). PE #0: 1000,00.
340,10: [Host #2] utilization is 67,20%

340,10: [Host #3] IO processing of VM #1 elapsed time is 1,79623 s
340,10: [Host #3] IO processing of VM #7 elapsed time is 2,79811 s
340,10: [Host #3] IO processing of VM #13 elapsed time is 0,44717 s
340,10: [Host #3] Total allocated MIPS for VM #1 (Host #3) is 2500,00, was requested 2500,00 out of total 2500,00 (100,00%)
340,10: [Host #3] MIPS for VM #1 by PEs (2 * 2660.0). PE #0: 2500,00.
340,10: [Host #3] Total allocated MIPS for VM #7 (Host #3) is 2000,00, was requested 2000,00 out of total 2000,00 (100,00%)
340,10: [Host #3] MIPS for VM #7 by PEs (2 * 2660.0). PE #1: 2000,00.
340,10: [Host #3] Total allocated MIPS for VM #13 (Host #3) is 500,00, was requested 500,00 out of total 500,00 (100,00%)
340,10: [Host #3] MIPS for VM #13 by PEs (2 * 2660.0). PE #0: 160,00. PE #1: 340,00.
340,10: [Host #3] utilization is 93,98%

340,10: [Host #4] utilization is 0,00%

340,10: [Host #5] IO processing of VM #2 elapsed time is 1,79623 s
340,10: [Host #5] IO processing of VM #4 elapsed time is 2,79811 s
340,10: [Host #5] Total allocated MIPS for VM #2 (Host #5) is 2500,00, was requested 2500,00 out of total 2500,00 (100,00%)
340,10: [Host #5] MIPS for VM #2 by PEs (2 * 2660.0). PE #0: 2500,00.
340,10: [Host #5] Total allocated MIPS for VM #4 (Host #5) is 2000,00, was requested 2000,00 out of total 2000,00 (100,00%)
340,10: [Host #5] MIPS for VM #4 by PEs (2 * 2660.0). PE #0: 160,00. PE #1: 1840,00.
340,10: [Host #5] utilization is 84,59%

340,10: [Host #6] utilization is 0,00%

340,10: [Host #7] IO processing of VM #3 elapsed time is 1,79623 s
340,10: [Host #7] IO processing of VM #5 elapsed time is 2,79811 s
340,10: [Host #7] Total allocated MIPS for VM #3 (Host #7) is 2500,00, was requested 2500,00 out of total 2500,00 (100,00%)
340,10: [Host #7] MIPS for VM #3 by PEs (2 * 2660.0). PE #0: 2500,00.
340,10: [Host #7] Total allocated MIPS for VM #5 (Host #7) is 2000,00, was requested 2000,00 out of total 2000,00 (100,00%)
340,10: [Host #7] MIPS for VM #5 by PEs (2 * 2660.0). PE #0: 160,00. PE #1: 1840,00.
340,10: [Host #7] utilization is 84,59%

340,10: [Host #8] utilization is 0,00%

340,10: [Host #9] utilization is 0,00%

340.1: Broker: Cloudlet 2 received


--------------------------------------------------------------


New resource usage for the time frame starting at 600,10:

600,10: [Host #0] IO processing of VM #8 elapsed time is 0,56792 s
600,10: [Host #0] IO processing of VM #14 elapsed time is 0,22642 s
600,10: [Host #0] IO processing of VM #11 elapsed time is 0,56792 s
600,10: [Host #0] Total allocated MIPS for VM #8 (Host #0) is 1000,00, was requested 1000,00 out of total 1000,00 (100,00%)
600,10: [Host #0] MIPS for VM #8 by PEs (2 * 1860.0). PE #0: 360,00. PE #1: 640,00.
600,10: [Host #0] Total allocated MIPS for VM #14 (Host #0) is 500,00, was requested 500,00 out of total 500,00 (100,00%)
600,10: [Host #0] MIPS for VM #14 by PEs (2 * 1860.0). PE #0: 500,00.
600,10: [Host #0] Total allocated MIPS for VM #11 (Host #0) is 1000,00, was requested 1000,00 out of total 1000,00 (100,00%)
600,10: [Host #0] MIPS for VM #11 by PEs (2 * 1860.0). PE #0: 1000,00.
600,10: [Host #0] utilization is 67,20%

600,10: [Host #1] IO processing of VM #0 elapsed time is 1,67170 s
600,10: [Host #1] IO processing of VM #6 elapsed time is 0,53396 s
600,10: [Host #1] IO processing of VM #12 elapsed time is 0,22642 s
600,10: [Host #1] Total allocated MIPS for VM #0 (Host #1) is 2500,00, was requested 2500,00 out of total 2500,00 (100,00%)
600,10: [Host #1] MIPS for VM #0 by PEs (2 * 2660.0). PE #0: 2500,00.
600,10: [Host #1] Total allocated MIPS for VM #6 (Host #1) is 2000,00, was requested 2000,00 out of total 2000,00 (100,00%)
600,10: [Host #1] MIPS for VM #6 by PEs (2 * 2660.0). PE #0: 160,00. PE #1: 1840,00.
600,10: [Host #1] Total allocated MIPS for VM #12 (Host #1) is 500,00, was requested 500,00 out of total 500,00 (100,00%)
600,10: [Host #1] MIPS for VM #12 by PEs (2 * 2660.0). PE #1: 500,00.
600,10: [Host #1] utilization is 93,98%

600,10: [Host #2] IO processing of VM #9 elapsed time is 0,56792 s
600,10: [Host #2] IO processing of VM #15 elapsed time is 0,22642 s
600,10: [Host #2] IO processing of VM #10 elapsed time is 0,56792 s
600,10: [Host #2] Total allocated MIPS for VM #9 (Host #2) is 1000,00, was requested 1000,00 out of total 1000,00 (100,00%)
600,10: [Host #2] MIPS for VM #9 by PEs (2 * 1860.0). PE #0: 360,00. PE #1: 640,00.
600,10: [Host #2] Total allocated MIPS for VM #15 (Host #2) is 500,00, was requested 500,00 out of total 500,00 (100,00%)
600,10: [Host #2] MIPS for VM #15 by PEs (2 * 1860.0). PE #0: 500,00.
600,10: [Host #2] Total allocated MIPS for VM #10 (Host #2) is 1000,00, was requested 1000,00 out of total 1000,00 (100,00%)
600,10: [Host #2] MIPS for VM #10 by PEs (2 * 1860.0). PE #0: 1000,00.
600,10: [Host #2] utilization is 67,20%

600,10: [Host #3] IO processing of VM #1 elapsed time is 1,67170 s
600,10: [Host #3] IO processing of VM #7 elapsed time is 0,53396 s
600,10: [Host #3] IO processing of VM #13 elapsed time is 0,22642 s
600,10: [Host #3] Total allocated MIPS for VM #1 (Host #3) is 2500,00, was requested 2500,00 out of total 2500,00 (100,00%)
600,10: [Host #3] MIPS for VM #1 by PEs (2 * 2660.0). PE #0: 2500,00.
600,10: [Host #3] Total allocated MIPS for VM #7 (Host #3) is 2000,00, was requested 2000,00 out of total 2000,00 (100,00%)
600,10: [Host #3] MIPS for VM #7 by PEs (2 * 2660.0). PE #1: 2000,00.
600,10: [Host #3] Total allocated MIPS for VM #13 (Host #3) is 500,00, was requested 500,00 out of total 500,00 (100,00%)
600,10: [Host #3] MIPS for VM #13 by PEs (2 * 2660.0). PE #0: 160,00. PE #1: 340,00.
600,10: [Host #3] utilization is 93,98%

600,10: [Host #4] utilization is 0,00%

600,10: [Host #5] IO processing of VM #2 elapsed time is 1,67170 s
600,10: [Host #5] IO processing of VM #4 elapsed time is 0,53396 s
600,10: [Host #5] Total allocated MIPS for VM #2 (Host #5) is 2500,00, was requested 2500,00 out of total 2500,00 (100,00%)
600,10: [Host #5] MIPS for VM #2 by PEs (2 * 2660.0). PE #0: 2500,00.
600,10: [Host #5] Total allocated MIPS for VM #4 (Host #5) is 2000,00, was requested 2000,00 out of total 2000,00 (100,00%)
600,10: [Host #5] MIPS for VM #4 by PEs (2 * 2660.0). PE #0: 160,00. PE #1: 1840,00.
600,10: [Host #5] utilization is 84,59%

600,10: [Host #6] utilization is 0,00%

600,10: [Host #7] IO processing of VM #3 elapsed time is 1,67170 s
600,10: [Host #7] IO processing of VM #5 elapsed time is 0,53396 s
600,10: [Host #7] Total allocated MIPS for VM #3 (Host #7) is 2500,00, was requested 2500,00 out of total 2500,00 (100,00%)
600,10: [Host #7] MIPS for VM #3 by PEs (2 * 2660.0). PE #0: 2500,00.
600,10: [Host #7] Total allocated MIPS for VM #5 (Host #7) is 2000,00, was requested 2000,00 out of total 2000,00 (100,00%)
600,10: [Host #7] MIPS for VM #5 by PEs (2 * 2660.0). PE #0: 160,00. PE #1: 1840,00.
600,10: [Host #7] utilization is 84,59%

600,10: [Host #8] utilization is 0,00%

600,10: [Host #9] utilization is 0,00%

Energy consumption for the last time frame from 340,10 to 600,10:

600,10: [Host #0] utilization at 340,10 was 67,20%, now is 67,20%
600,10: [Host #0] energy is 19989,25 W*sec

600,10: [Host #1] utilization at 340,10 was 93,98%, now is 93,98%
600,10: [Host #1] energy is 22774,44 W*sec

600,10: [Host #2] utilization at 340,10 was 67,20%, now is 67,20%
600,10: [Host #2] energy is 19989,25 W*sec

600,10: [Host #3] utilization at 340,10 was 93,98%, now is 93,98%
600,10: [Host #3] energy is 22774,44 W*sec

600,10: [Host #4] utilization at 340,10 was 0,00%, now is 0,00%
600,10: [Host #4] energy is 0,00 W*sec

600,10: [Host #5] utilization at 340,10 was 84,59%, now is 84,59%
600,10: [Host #5] energy is 21796,99 W*sec

600,10: [Host #6] utilization at 340,10 was 0,00%, now is 0,00%
600,10: [Host #6] energy is 0,00 W*sec

600,10: [Host #7] utilization at 340,10 was 84,59%, now is 84,59%
600,10: [Host #7] energy is 21796,99 W*sec

600,10: [Host #8] utilization at 340,10 was 0,00%, now is 0,00%
600,10: [Host #8] energy is 0,00 W*sec

600,10: [Host #9] utilization at 340,10 was 0,00%, now is 0,00%
600,10: [Host #9] energy is 0,00 W*sec

600,10: Data center's energy is 129121,35 W*sec


Hamza: optimizeAllocation
Over-utilized hosts:
Host #1
Host #3

Reallocation of VMs from the over-utilized hosts:
[VmScheduler.vmCreate] Allocation of VM #6 to Host #0 failed by RAM
VM #6 allocated to host #0
[VmScheduler.vmCreate] Allocation of VM #7 to Host #0 failed by RAM
VM #7 allocated to host #0
[VmScheduler.vmCreate] Allocation of VM #6 to Host #2 failed by RAM
VM #6 allocated to host #2
[VmScheduler.vmCreate] Allocation of VM #7 to Host #0 failed by RAM
VM #7 allocated to host #0
VM #6 allocated to host #4
[VmScheduler.vmCreate] Allocation of VM #7 to Host #0 failed by RAM
VM #7 allocated to host #0
[VmScheduler.vmCreate] Allocation of VM #6 to Host #5 failed by RAM
VM #6 allocated to host #5
[VmScheduler.vmCreate] Allocation of VM #7 to Host #0 failed by RAM
VM #7 allocated to host #0
VM #6 allocated to host #6
[VmScheduler.vmCreate] Allocation of VM #7 to Host #0 failed by RAM
VM #7 allocated to host #0
[VmScheduler.vmCreate] Allocation of VM #6 to Host #7 failed by RAM
VM #6 allocated to host #7
[VmScheduler.vmCreate] Allocation of VM #7 to Host #0 failed by RAM
VM #7 allocated to host #0
VM #6 allocated to host #8
[VmScheduler.vmCreate] Allocation of VM #7 to Host #0 failed by RAM
VM #7 allocated to host #0
VM #6 allocated to host #9
[VmScheduler.vmCreate] Allocation of VM #7 to Host #0 failed by RAM
VM #7 allocated to host #0
[VmScheduler.vmCreate] Allocation of VM #6 to Host #0 failed by RAM
VM #6 allocated to host #0
[VmScheduler.vmCreate] Allocation of VM #7 to Host #2 failed by RAM
VM #7 allocated to host #2
[VmScheduler.vmCreate] Allocation of VM #6 to Host #2 failed by RAM
VM #6 allocated to host #2
[VmScheduler.vmCreate] Allocation of VM #7 to Host #2 failed by RAM
VM #7 allocated to host #2
VM #6 allocated to host #4
[VmScheduler.vmCreate] Allocation of VM #7 to Host #2 failed by RAM
VM #7 allocated to host #2
[VmScheduler.vmCreate] Allocation of VM #6 to Host #5 failed by RAM
VM #6 allocated to host #5
[VmScheduler.vmCreate] Allocation of VM #7 to Host #2 failed by RAM
VM #7 allocated to host #2
VM #6 allocated to host #6
[VmScheduler.vmCreate] Allocation of VM #7 to Host #2 failed by RAM
VM #7 allocated to host #2
[VmScheduler.vmCreate] Allocation of VM #6 to Host #7 failed by RAM
VM #6 allocated to host #7
[VmScheduler.vmCreate] Allocation of VM #7 to Host #2 failed by RAM
VM #7 allocated to host #2
VM #6 allocated to host #8
[VmScheduler.vmCreate] Allocation of VM #7 to Host #2 failed by RAM
VM #7 allocated to host #2
VM #6 allocated to host #9
[VmScheduler.vmCreate] Allocation of VM #7 to Host #2 failed by RAM
VM #7 allocated to host #2
[VmScheduler.vmCreate] Allocation of VM #6 to Host #0 failed by RAM
VM #6 allocated to host #0
VM #7 allocated to host #4
[VmScheduler.vmCreate] Allocation of VM #6 to Host #2 failed by RAM
VM #6 allocated to host #2
VM #7 allocated to host #4
VM #6 allocated to host #4
VM #7 allocated to host #4
[VmScheduler.vmCreate] Allocation of VM #6 to Host #5 failed by RAM
VM #6 allocated to host #5
VM #7 allocated to host #4
VM #6 allocated to host #6
VM #7 allocated to host #4
[VmScheduler.vmCreate] Allocation of VM #6 to Host #7 failed by RAM
VM #6 allocated to host #7
VM #7 allocated to host #4
VM #6 allocated to host #8
VM #7 allocated to host #4
VM #6 allocated to host #9
VM #7 allocated to host #4
[VmScheduler.vmCreate] Allocation of VM #6 to Host #0 failed by RAM
VM #6 allocated to host #0
[VmScheduler.vmCreate] Allocation of VM #7 to Host #5 failed by RAM
VM #7 allocated to host #5
[VmScheduler.vmCreate] Allocation of VM #6 to Host #2 failed by RAM
VM #6 allocated to host #2
[VmScheduler.vmCreate] Allocation of VM #7 to Host #5 failed by RAM
VM #7 allocated to host #5
VM #6 allocated to host #4
[VmScheduler.vmCreate] Allocation of VM #7 to Host #5 failed by RAM
VM #7 allocated to host #5
[VmScheduler.vmCreate] Allocation of VM #6 to Host #5 failed by RAM
VM #6 allocated to host #5
[VmScheduler.vmCreate] Allocation of VM #7 to Host #5 failed by RAM
VM #7 allocated to host #5
VM #6 allocated to host #6
[VmScheduler.vmCreate] Allocation of VM #7 to Host #5 failed by RAM
VM #7 allocated to host #5
[VmScheduler.vmCreate] Allocation of VM #6 to Host #7 failed by RAM
VM #6 allocated to host #7
[VmScheduler.vmCreate] Allocation of VM #7 to Host #5 failed by RAM
VM #7 allocated to host #5
VM #6 allocated to host #8
[VmScheduler.vmCreate] Allocation of VM #7 to Host #5 failed by RAM
VM #7 allocated to host #5
VM #6 allocated to host #9
[VmScheduler.vmCreate] Allocation of VM #7 to Host #5 failed by RAM
VM #7 allocated to host #5
[VmScheduler.vmCreate] Allocation of VM #6 to Host #0 failed by RAM
VM #6 allocated to host #0
VM #7 allocated to host #6
[VmScheduler.vmCreate] Allocation of VM #6 to Host #2 failed by RAM
VM #6 allocated to host #2
VM #7 allocated to host #6
VM #6 allocated to host #4
VM #7 allocated to host #6
[VmScheduler.vmCreate] Allocation of VM #6 to Host #5 failed by RAM
VM #6 allocated to host #5
VM #7 allocated to host #6
VM #6 allocated to host #6
VM #7 allocated to host #6
[VmScheduler.vmCreate] Allocation of VM #6 to Host #7 failed by RAM
VM #6 allocated to host #7
VM #7 allocated to host #6
VM #6 allocated to host #8
VM #7 allocated to host #6
VM #6 allocated to host #9
VM #7 allocated to host #6
[VmScheduler.vmCreate] Allocation of VM #6 to Host #0 failed by RAM
VM #6 allocated to host #0
[VmScheduler.vmCreate] Allocation of VM #7 to Host #7 failed by RAM
VM #7 allocated to host #7
[VmScheduler.vmCreate] Allocation of VM #6 to Host #2 failed by RAM
VM #6 allocated to host #2
[VmScheduler.vmCreate] Allocation of VM #7 to Host #7 failed by RAM
VM #7 allocated to host #7
VM #6 allocated to host #4
[VmScheduler.vmCreate] Allocation of VM #7 to Host #7 failed by RAM
VM #7 allocated to host #7
[VmScheduler.vmCreate] Allocation of VM #6 to Host #5 failed by RAM
VM #6 allocated to host #5
[VmScheduler.vmCreate] Allocation of VM #7 to Host #7 failed by RAM
VM #7 allocated to host #7
VM #6 allocated to host #6
[VmScheduler.vmCreate] Allocation of VM #7 to Host #7 failed by RAM
VM #7 allocated to host #7
[VmScheduler.vmCreate] Allocation of VM #6 to Host #7 failed by RAM
VM #6 allocated to host #7
[VmScheduler.vmCreate] Allocation of VM #7 to Host #7 failed by RAM
VM #7 allocated to host #7
VM #6 allocated to host #8
[VmScheduler.vmCreate] Allocation of VM #7 to Host #7 failed by RAM
VM #7 allocated to host #7
VM #6 allocated to host #9
[VmScheduler.vmCreate] Allocation of VM #7 to Host #7 failed by RAM
VM #7 allocated to host #7
[VmScheduler.vmCreate] Allocation of VM #6 to Host #0 failed by RAM
VM #6 allocated to host #0
VM #7 allocated to host #8
[VmScheduler.vmCreate] Allocation of VM #6 to Host #2 failed by RAM
VM #6 allocated to host #2
VM #7 allocated to host #8
VM #6 allocated to host #4
VM #7 allocated to host #8
[VmScheduler.vmCreate] Allocation of VM #6 to Host #5 failed by RAM
VM #6 allocated to host #5
VM #7 allocated to host #8
VM #6 allocated to host #6
VM #7 allocated to host #8
[VmScheduler.vmCreate] Allocation of VM #6 to Host #7 failed by RAM
VM #6 allocated to host #7
VM #7 allocated to host #8
VM #6 allocated to host #8
VM #7 allocated to host #8
VM #6 allocated to host #9
VM #7 allocated to host #8
[VmScheduler.vmCreate] Allocation of VM #6 to Host #0 failed by RAM
VM #6 allocated to host #0
VM #7 allocated to host #9
[VmScheduler.vmCreate] Allocation of VM #6 to Host #2 failed by RAM
VM #6 allocated to host #2
VM #7 allocated to host #9
VM #6 allocated to host #4
VM #7 allocated to host #9
[VmScheduler.vmCreate] Allocation of VM #6 to Host #5 failed by RAM
VM #6 allocated to host #5
VM #7 allocated to host #9
VM #6 allocated to host #6
VM #7 allocated to host #9
[VmScheduler.vmCreate] Allocation of VM #6 to Host #7 failed by RAM
VM #6 allocated to host #7
VM #7 allocated to host #9
VM #6 allocated to host #8
VM #7 allocated to host #9
VM #6 allocated to host #9
VM #7 allocated to host #9

Under-utilized host: host #7

Reallocation of VMs from the under-utilized host: 3 5 
Not all VMs can be reallocated from the host, reallocation cancelled

Under-utilized host: host #5

Reallocation of VMs from the under-utilized host: 2 4 
Not all VMs can be reallocated from the host, reallocation cancelled

Under-utilized host: host #2

Reallocation of VMs from the under-utilized host: 9 15 10 
Not all VMs can be reallocated from the host, reallocation cancelled

Under-utilized host: host #0

Reallocation of VMs from the under-utilized host: 8 14 11 
Not all VMs can be reallocated from the host, reallocation cancelled

[MyStorageList.getDeviceContainsVm]: there is no device containing the vm 2-6
[MyStorageList.getDeviceContainsVm]: there is no device containing the vm 2-7
[MyStorageList.getDeviceContainsVm]: there is no device containing the vm 2-6
[MyStorageList.getDeviceContainsVm]: there is no device containing the vm 2-7
[MyStorageList.getDeviceContainsVm]: there is no device containing the vm 2-7
[MyStorageList.getDeviceContainsVm]: there is no device containing the vm 2-7
[MyStorageList.getDeviceContainsVm]: there is no device containing the vm 2-7
[MyStorageList.getDeviceContainsVm]: there is no device containing the vm 2-7
[MyStorageList.getDeviceContainsVm]: there is no device containing the vm 2-7
[MyStorageList.getDeviceContainsVm]: there is no device containing the vm 2-6
[MyStorageList.getDeviceContainsVm]: there is no device containing the vm 2-6
[MyStorageList.getDeviceContainsVm]: there is no device containing the vm 2-6
[MyStorageList.getDeviceContainsVm]: there is no device containing the vm 2-6
[MyStorageList.getDeviceContainsVm]: there is no device containing the vm 2-6
[MyStorageList.getDeviceContainsVm]: there is no device containing the vm 2-6
[MyStorageList.getDeviceContainsVm]: there is no device containing the vm 2-6
[MyStorageList.getDeviceContainsVm]: there is no device containing the vm 2-6
[MyStorageList.getDeviceContainsVm]: there is no device containing the vm 2-7
[MyStorageList.getDeviceContainsVm]: there is no device containing the vm 2-7
[MyStorageList.getDeviceContainsVm]: there is no device containing the vm 2-7
[MyStorageList.getDeviceContainsVm]: there is no device containing the vm 2-6
[MyStorageList.getDeviceContainsVm]: there is no device containing the vm 2-7
[MyStorageList.getDeviceContainsVm]: there is no device containing the vm 2-7
[MyStorageList.getDeviceContainsVm]: there is no device containing the vm 2-7
[MyStorageList.getDeviceContainsVm]: there is no device containing the vm 2-7
[MyStorageList.getDeviceContainsVm]: there is no device containing the vm 2-6
[MyStorageList.getDeviceContainsVm]: there is no device containing the vm 2-6
[MyStorageList.getDeviceContainsVm]: there is no device containing the vm 2-6
[MyStorageList.getDeviceContainsVm]: there is no device containing the vm 2-6
[MyStorageList.getDeviceContainsVm]: there is no device containing the vm 2-6
[MyStorageList.getDeviceContainsVm]: there is no device containing the vm 2-6
[MyStorageList.getDeviceContainsVm]: there is no device containing the vm 2-6
[MyStorageList.getDeviceContainsVm]: there is no device containing the vm 2-6
[MyStorageList.getDeviceContainsVm]: there is no device containing the vm 2-7
[MyStorageList.getDeviceContainsVm]: there is no device containing the vm 2-7
[MyStorageList.getDeviceContainsVm]: there is no device containing the vm 2-7
[MyStorageList.getDeviceContainsVm]: there is no device containing the vm 2-7
[MyStorageList.getDeviceContainsVm]: there is no device containing the vm 2-7
[MyStorageList.getDeviceContainsVm]: there is no device containing the vm 2-6
[MyStorageList.getDeviceContainsVm]: there is no device containing the vm 2-7
[MyStorageList.getDeviceContainsVm]: there is no device containing the vm 2-7
[MyStorageList.getDeviceContainsVm]: there is no device containing the vm 2-6
[MyStorageList.getDeviceContainsVm]: there is no device containing the vm 2-6
[MyStorageList.getDeviceContainsVm]: there is no device containing the vm 2-6
[MyStorageList.getDeviceContainsVm]: there is no device containing the vm 2-6
[MyStorageList.getDeviceContainsVm]: there is no device containing the vm 2-6
[MyStorageList.getDeviceContainsVm]: there is no device containing the vm 2-6
[MyStorageList.getDeviceContainsVm]: there is no device containing the vm 2-6
[MyStorageList.getDeviceContainsVm]: there is no device containing the vm 2-7
[MyStorageList.getDeviceContainsVm]: there is no device containing the vm 2-7
[MyStorageList.getDeviceContainsVm]: there is no device containing the vm 2-7
[MyStorageList.getDeviceContainsVm]: there is no device containing the vm 2-7
[MyStorageList.getDeviceContainsVm]: there is no device containing the vm 2-7
[MyStorageList.getDeviceContainsVm]: there is no device containing the vm 2-7
[MyStorageList.getDeviceContainsVm]: there is no device containing the vm 2-6
[MyStorageList.getDeviceContainsVm]: there is no device containing the vm 2-7
600.1: Broker: Cloudlet 6 received
600.1: Broker: Cloudlet 4 received


--------------------------------------------------------------


New resource usage for the time frame starting at 900,10:

900,10: [Host #0] IO processing of VM #8 elapsed time is 1,53208 s
900,10: [Host #0] IO processing of VM #14 elapsed time is 1,66226 s
900,10: [Host #0] IO processing of VM #11 elapsed time is 1,53208 s
900,10: [Host #0] Total allocated MIPS for VM #8 (Host #0) is 1000,00, was requested 1000,00 out of total 1000,00 (100,00%)
900,10: [Host #0] MIPS for VM #8 by PEs (2 * 1860.0). PE #0: 360,00. PE #1: 640,00.
900,10: [Host #0] Total allocated MIPS for VM #14 (Host #0) is 500,00, was requested 500,00 out of total 500,00 (100,00%)
900,10: [Host #0] MIPS for VM #14 by PEs (2 * 1860.0). PE #0: 500,00.
900,10: [Host #0] Total allocated MIPS for VM #11 (Host #0) is 1000,00, was requested 1000,00 out of total 1000,00 (100,00%)
900,10: [Host #0] MIPS for VM #11 by PEs (2 * 1860.0). PE #0: 1000,00.
900,10: [Host #0] utilization is 67,20%

900,10: [Host #1] IO processing of VM #0 elapsed time is 2,86415 s
900,10: [Host #1] IO processing of VM #6 elapsed time is 0,37547 s
900,10: [Host #1] IO processing of VM #12 elapsed time is 1,66226 s
900,10: [Host #1] Total allocated MIPS for VM #0 (Host #1) is 2500,00, was requested 2500,00 out of total 2500,00 (100,00%)
900,10: [Host #1] MIPS for VM #0 by PEs (2 * 2660.0). PE #0: 2500,00.
900,10: [Host #1] Total allocated MIPS for VM #6 (Host #1) is 2000,00, was requested 2000,00 out of total 2000,00 (100,00%)
900,10: [Host #1] MIPS for VM #6 by PEs (2 * 2660.0). PE #0: 160,00. PE #1: 1840,00.
900,10: [Host #1] Total allocated MIPS for VM #12 (Host #1) is 500,00, was requested 500,00 out of total 500,00 (100,00%)
900,10: [Host #1] MIPS for VM #12 by PEs (2 * 2660.0). PE #1: 500,00.
900,10: [Host #1] utilization is 93,98%

900,10: [Host #2] IO processing of VM #9 elapsed time is 1,53208 s
900,10: [Host #2] IO processing of VM #15 elapsed time is 1,66226 s
900,10: [Host #2] IO processing of VM #10 elapsed time is 1,53208 s
900,10: [Host #2] Total allocated MIPS for VM #9 (Host #2) is 1000,00, was requested 1000,00 out of total 1000,00 (100,00%)
900,10: [Host #2] MIPS for VM #9 by PEs (2 * 1860.0). PE #0: 360,00. PE #1: 640,00.
900,10: [Host #2] Total allocated MIPS for VM #15 (Host #2) is 500,00, was requested 500,00 out of total 500,00 (100,00%)
900,10: [Host #2] MIPS for VM #15 by PEs (2 * 1860.0). PE #0: 500,00.
900,10: [Host #2] Total allocated MIPS for VM #10 (Host #2) is 1000,00, was requested 1000,00 out of total 1000,00 (100,00%)
900,10: [Host #2] MIPS for VM #10 by PEs (2 * 1860.0). PE #0: 1000,00.
900,10: [Host #2] utilization is 67,20%

900,10: [Host #3] IO processing of VM #1 elapsed time is 2,86415 s
900,10: [Host #3] IO processing of VM #7 elapsed time is 0,37547 s
900,10: [Host #3] IO processing of VM #13 elapsed time is 1,66226 s
900,10: [Host #3] Total allocated MIPS for VM #1 (Host #3) is 2500,00, was requested 2500,00 out of total 2500,00 (100,00%)
900,10: [Host #3] MIPS for VM #1 by PEs (2 * 2660.0). PE #0: 2500,00.
900,10: [Host #3] Total allocated MIPS for VM #7 (Host #3) is 2000,00, was requested 2000,00 out of total 2000,00 (100,00%)
900,10: [Host #3] MIPS for VM #7 by PEs (2 * 2660.0). PE #1: 2000,00.
900,10: [Host #3] Total allocated MIPS for VM #13 (Host #3) is 500,00, was requested 500,00 out of total 500,00 (100,00%)
900,10: [Host #3] MIPS for VM #13 by PEs (2 * 2660.0). PE #0: 160,00. PE #1: 340,00.
900,10: [Host #3] utilization is 93,98%

900,10: [Host #4] utilization is 0,00%

900,10: [Host #5] IO processing of VM #2 elapsed time is 2,86415 s
900,10: [Host #5] IO processing of VM #4 elapsed time is 0,37547 s
900,10: [Host #5] Total allocated MIPS for VM #2 (Host #5) is 2500,00, was requested 2500,00 out of total 2500,00 (100,00%)
900,10: [Host #5] MIPS for VM #2 by PEs (2 * 2660.0). PE #0: 2500,00.
900,10: [Host #5] Total allocated MIPS for VM #4 (Host #5) is 2000,00, was requested 2000,00 out of total 2000,00 (100,00%)
900,10: [Host #5] MIPS for VM #4 by PEs (2 * 2660.0). PE #0: 160,00. PE #1: 1840,00.
900,10: [Host #5] utilization is 84,59%

900,10: [Host #6] utilization is 0,00%

900,10: [Host #7] IO processing of VM #3 elapsed time is 2,86415 s
900,10: [Host #7] IO processing of VM #5 elapsed time is 0,37547 s
900,10: [Host #7] Total allocated MIPS for VM #3 (Host #7) is 2500,00, was requested 2500,00 out of total 2500,00 (100,00%)
900,10: [Host #7] MIPS for VM #3 by PEs (2 * 2660.0). PE #0: 2500,00.
900,10: [Host #7] Total allocated MIPS for VM #5 (Host #7) is 2000,00, was requested 2000,00 out of total 2000,00 (100,00%)
900,10: [Host #7] MIPS for VM #5 by PEs (2 * 2660.0). PE #0: 160,00. PE #1: 1840,00.
900,10: [Host #7] utilization is 84,59%

900,10: [Host #8] utilization is 0,00%

900,10: [Host #9] utilization is 0,00%

Energy consumption for the last time frame from 600,10 to 900,10:

900,10: [Host #0] utilization at 600,10 was 67,20%, now is 67,20%
900,10: [Host #0] energy is 23064,52 W*sec

900,10: [Host #1] utilization at 600,10 was 93,98%, now is 93,98%
900,10: [Host #1] energy is 26278,20 W*sec

900,10: [Host #2] utilization at 600,10 was 67,20%, now is 67,20%
900,10: [Host #2] energy is 23064,52 W*sec

900,10: [Host #3] utilization at 600,10 was 93,98%, now is 93,98%
900,10: [Host #3] energy is 26278,20 W*sec

900,10: [Host #4] utilization at 600,10 was 0,00%, now is 0,00%
900,10: [Host #4] energy is 0,00 W*sec

900,10: [Host #5] utilization at 600,10 was 84,59%, now is 84,59%
900,10: [Host #5] energy is 25150,38 W*sec

900,10: [Host #6] utilization at 600,10 was 0,00%, now is 0,00%
900,10: [Host #6] energy is 0,00 W*sec

900,10: [Host #7] utilization at 600,10 was 84,59%, now is 84,59%
900,10: [Host #7] energy is 25150,38 W*sec

900,10: [Host #8] utilization at 600,10 was 0,00%, now is 0,00%
900,10: [Host #8] energy is 0,00 W*sec

900,10: [Host #9] utilization at 600,10 was 0,00%, now is 0,00%
900,10: [Host #9] energy is 0,00 W*sec

900,10: Data center's energy is 148986,18 W*sec


Hamza: optimizeAllocation
Over-utilized hosts:
Host #1
Host #3

Reallocation of VMs from the over-utilized hosts:
[VmScheduler.vmCreate] Allocation of VM #0 to Host #0 failed by RAM
VM #0 allocated to host #0
[VmScheduler.vmCreate] Allocation of VM #13 to Host #0 failed by RAM
VM #13 allocated to host #0
[VmScheduler.vmCreate] Allocation of VM #0 to Host #2 failed by RAM
VM #0 allocated to host #2
[VmScheduler.vmCreate] Allocation of VM #13 to Host #0 failed by RAM
VM #13 allocated to host #0
VM #0 allocated to host #4
[VmScheduler.vmCreate] Allocation of VM #13 to Host #0 failed by RAM
VM #13 allocated to host #0
VM #0 allocated to host #5
[VmScheduler.vmCreate] Allocation of VM #13 to Host #0 failed by RAM
VM #13 allocated to host #0
VM #0 allocated to host #6
[VmScheduler.vmCreate] Allocation of VM #13 to Host #0 failed by RAM
VM #13 allocated to host #0
VM #0 allocated to host #7
[VmScheduler.vmCreate] Allocation of VM #13 to Host #0 failed by RAM
VM #13 allocated to host #0
VM #0 allocated to host #8
[VmScheduler.vmCreate] Allocation of VM #13 to Host #0 failed by RAM
VM #13 allocated to host #0
VM #0 allocated to host #9
[VmScheduler.vmCreate] Allocation of VM #13 to Host #0 failed by RAM
VM #13 allocated to host #0
[VmScheduler.vmCreate] Allocation of VM #0 to Host #0 failed by RAM
VM #0 allocated to host #0
[VmScheduler.vmCreate] Allocation of VM #13 to Host #2 failed by RAM
VM #13 allocated to host #2
[VmScheduler.vmCreate] Allocation of VM #0 to Host #2 failed by RAM
VM #0 allocated to host #2
[VmScheduler.vmCreate] Allocation of VM #13 to Host #2 failed by RAM
VM #13 allocated to host #2
VM #0 allocated to host #4
[VmScheduler.vmCreate] Allocation of VM #13 to Host #2 failed by RAM
VM #13 allocated to host #2
VM #0 allocated to host #5
[VmScheduler.vmCreate] Allocation of VM #13 to Host #2 failed by RAM
VM #13 allocated to host #2
VM #0 allocated to host #6
[VmScheduler.vmCreate] Allocation of VM #13 to Host #2 failed by RAM
VM #13 allocated to host #2
VM #0 allocated to host #7
[VmScheduler.vmCreate] Allocation of VM #13 to Host #2 failed by RAM
VM #13 allocated to host #2
VM #0 allocated to host #8
[VmScheduler.vmCreate] Allocation of VM #13 to Host #2 failed by RAM
VM #13 allocated to host #2
VM #0 allocated to host #9
[VmScheduler.vmCreate] Allocation of VM #13 to Host #2 failed by RAM
VM #13 allocated to host #2
[VmScheduler.vmCreate] Allocation of VM #0 to Host #0 failed by RAM
VM #0 allocated to host #0
VM #13 allocated to host #4
[VmScheduler.vmCreate] Allocation of VM #0 to Host #2 failed by RAM
VM #0 allocated to host #2
VM #13 allocated to host #4
VM #0 allocated to host #4
VM #13 allocated to host #4
VM #0 allocated to host #5
VM #13 allocated to host #4
VM #0 allocated to host #6
VM #13 allocated to host #4
VM #0 allocated to host #7
VM #13 allocated to host #4
VM #0 allocated to host #8
VM #13 allocated to host #4
VM #0 allocated to host #9
VM #13 allocated to host #4
[VmScheduler.vmCreate] Allocation of VM #0 to Host #0 failed by RAM
VM #0 allocated to host #0
VM #13 allocated to host #5
[VmScheduler.vmCreate] Allocation of VM #0 to Host #2 failed by RAM
VM #0 allocated to host #2
VM #13 allocated to host #5
VM #0 allocated to host #4
VM #13 allocated to host #5
VM #0 allocated to host #5
VM #13 allocated to host #5
VM #0 allocated to host #6
VM #13 allocated to host #5
VM #0 allocated to host #7
VM #13 allocated to host #5
VM #0 allocated to host #8
VM #13 allocated to host #5
VM #0 allocated to host #9
VM #13 allocated to host #5
[VmScheduler.vmCreate] Allocation of VM #0 to Host #0 failed by RAM
VM #0 allocated to host #0
VM #13 allocated to host #6
[VmScheduler.vmCreate] Allocation of VM #0 to Host #2 failed by RAM
VM #0 allocated to host #2
VM #13 allocated to host #6
VM #0 allocated to host #4
VM #13 allocated to host #6
VM #0 allocated to host #5
VM #13 allocated to host #6
VM #0 allocated to host #6
VM #13 allocated to host #6
VM #0 allocated to host #7
VM #13 allocated to host #6
VM #0 allocated to host #8
VM #13 allocated to host #6
VM #0 allocated to host #9
VM #13 allocated to host #6
[VmScheduler.vmCreate] Allocation of VM #0 to Host #0 failed by RAM
VM #0 allocated to host #0
VM #13 allocated to host #7
[VmScheduler.vmCreate] Allocation of VM #0 to Host #2 failed by RAM
VM #0 allocated to host #2
VM #13 allocated to host #7
VM #0 allocated to host #4
VM #13 allocated to host #7
VM #0 allocated to host #5
VM #13 allocated to host #7
VM #0 allocated to host #6
VM #13 allocated to host #7
VM #0 allocated to host #7
VM #13 allocated to host #7
VM #0 allocated to host #8
VM #13 allocated to host #7
VM #0 allocated to host #9
VM #13 allocated to host #7
[VmScheduler.vmCreate] Allocation of VM #0 to Host #0 failed by RAM
VM #0 allocated to host #0
VM #13 allocated to host #8
[VmScheduler.vmCreate] Allocation of VM #0 to Host #2 failed by RAM
VM #0 allocated to host #2
VM #13 allocated to host #8
VM #0 allocated to host #4
VM #13 allocated to host #8
VM #0 allocated to host #5
VM #13 allocated to host #8
VM #0 allocated to host #6
VM #13 allocated to host #8
VM #0 allocated to host #7
VM #13 allocated to host #8
VM #0 allocated to host #8
VM #13 allocated to host #8
VM #0 allocated to host #9
VM #13 allocated to host #8
[VmScheduler.vmCreate] Allocation of VM #0 to Host #0 failed by RAM
VM #0 allocated to host #0
VM #13 allocated to host #9
[VmScheduler.vmCreate] Allocation of VM #0 to Host #2 failed by RAM
VM #0 allocated to host #2
VM #13 allocated to host #9
VM #0 allocated to host #4
VM #13 allocated to host #9
VM #0 allocated to host #5
VM #13 allocated to host #9
VM #0 allocated to host #6
VM #13 allocated to host #9
VM #0 allocated to host #7
VM #13 allocated to host #9
VM #0 allocated to host #8
VM #13 allocated to host #9
VM #0 allocated to host #9
VM #13 allocated to host #9

Under-utilized host: host #2

Reallocation of VMs from the under-utilized host: 9 15 10 
Not all VMs can be reallocated from the host, reallocation cancelled

Under-utilized host: host #0

Reallocation of VMs from the under-utilized host: 8 14 11 
Not all VMs can be reallocated from the host, reallocation cancelled

[MyStorageList.getDeviceContainsVm]: there is no device containing the vm 2-0
[MyStorageList.getDeviceContainsVm]: there is no device containing the vm 2-13
[MyStorageList.getDeviceContainsVm]: there is no device containing the vm 2-0
[MyStorageList.getDeviceContainsVm]: there is no device containing the vm 2-13
[MyStorageList.getDeviceContainsVm]: there is no device containing the vm 2-13
[MyStorageList.getDeviceContainsVm]: there is no device containing the vm 2-13
[MyStorageList.getDeviceContainsVm]: there is no device containing the vm 2-13
[MyStorageList.getDeviceContainsVm]: there is no device containing the vm 2-13
[MyStorageList.getDeviceContainsVm]: there is no device containing the vm 2-13
[MyStorageList.getDeviceContainsVm]: there is no device containing the vm 2-0
[MyStorageList.getDeviceContainsVm]: there is no device containing the vm 2-0
[MyStorageList.getDeviceContainsVm]: there is no device containing the vm 2-0
[MyStorageList.getDeviceContainsVm]: there is no device containing the vm 2-0
[MyStorageList.getDeviceContainsVm]: there is no device containing the vm 2-0
[MyStorageList.getDeviceContainsVm]: there is no device containing the vm 2-0
[MyStorageList.getDeviceContainsVm]: there is no device containing the vm 2-0
[MyStorageList.getDeviceContainsVm]: there is no device containing the vm 2-13
[MyStorageList.getDeviceContainsVm]: there is no device containing the vm 2-13
[MyStorageList.getDeviceContainsVm]: there is no device containing the vm 2-0
[MyStorageList.getDeviceContainsVm]: there is no device containing the vm 2-13
[MyStorageList.getDeviceContainsVm]: there is no device containing the vm 2-13
[MyStorageList.getDeviceContainsVm]: there is no device containing the vm 2-13
[MyStorageList.getDeviceContainsVm]: there is no device containing the vm 2-13
[MyStorageList.getDeviceContainsVm]: there is no device containing the vm 2-13
[MyStorageList.getDeviceContainsVm]: there is no device containing the vm 2-0
[MyStorageList.getDeviceContainsVm]: there is no device containing the vm 2-0
[MyStorageList.getDeviceContainsVm]: there is no device containing the vm 2-0
[MyStorageList.getDeviceContainsVm]: there is no device containing the vm 2-0
[MyStorageList.getDeviceContainsVm]: there is no device containing the vm 2-0
[MyStorageList.getDeviceContainsVm]: there is no device containing the vm 2-0
[MyStorageList.getDeviceContainsVm]: there is no device containing the vm 2-0
[MyStorageList.getDeviceContainsVm]: there is no device containing the vm 2-13
[MyStorageList.getDeviceContainsVm]: there is no device containing the vm 2-13
[MyStorageList.getDeviceContainsVm]: there is no device containing the vm 2-13
[MyStorageList.getDeviceContainsVm]: there is no device containing the vm 2-0
[MyStorageList.getDeviceContainsVm]: there is no device containing the vm 2-13
[MyStorageList.getDeviceContainsVm]: there is no device containing the vm 2-13
[MyStorageList.getDeviceContainsVm]: there is no device containing the vm 2-13
[MyStorageList.getDeviceContainsVm]: there is no device containing the vm 2-13
[MyStorageList.getDeviceContainsVm]: there is no device containing the vm 2-0
[MyStorageList.getDeviceContainsVm]: there is no device containing the vm 2-0
[MyStorageList.getDeviceContainsVm]: there is no device containing the vm 2-0
[MyStorageList.getDeviceContainsVm]: there is no device containing the vm 2-0
[MyStorageList.getDeviceContainsVm]: there is no device containing the vm 2-0
[MyStorageList.getDeviceContainsVm]: there is no device containing the vm 2-0
[MyStorageList.getDeviceContainsVm]: there is no device containing the vm 2-0
[MyStorageList.getDeviceContainsVm]: there is no device containing the vm 2-13
[MyStorageList.getDeviceContainsVm]: there is no device containing the vm 2-13
[MyStorageList.getDeviceContainsVm]: there is no device containing the vm 2-13
[MyStorageList.getDeviceContainsVm]: there is no device containing the vm 2-13
[MyStorageList.getDeviceContainsVm]: there is no device containing the vm 2-0
[MyStorageList.getDeviceContainsVm]: there is no device containing the vm 2-13
[MyStorageList.getDeviceContainsVm]: there is no device containing the vm 2-13
[MyStorageList.getDeviceContainsVm]: there is no device containing the vm 2-13
[MyStorageList.getDeviceContainsVm]: there is no device containing the vm 2-0
[MyStorageList.getDeviceContainsVm]: there is no device containing the vm 2-0
[MyStorageList.getDeviceContainsVm]: there is no device containing the vm 2-0
[MyStorageList.getDeviceContainsVm]: there is no device containing the vm 2-0
[MyStorageList.getDeviceContainsVm]: there is no device containing the vm 2-0
[MyStorageList.getDeviceContainsVm]: there is no device containing the vm 2-0
[MyStorageList.getDeviceContainsVm]: there is no device containing the vm 2-0
[MyStorageList.getDeviceContainsVm]: there is no device containing the vm 2-13
[MyStorageList.getDeviceContainsVm]: there is no device containing the vm 2-13
[MyStorageList.getDeviceContainsVm]: there is no device containing the vm 2-13
[MyStorageList.getDeviceContainsVm]: there is no device containing the vm 2-13
[MyStorageList.getDeviceContainsVm]: there is no device containing the vm 2-13
[MyStorageList.getDeviceContainsVm]: there is no device containing the vm 2-0
[MyStorageList.getDeviceContainsVm]: there is no device containing the vm 2-13
[MyStorageList.getDeviceContainsVm]: there is no device containing the vm 2-13
[MyStorageList.getDeviceContainsVm]: there is no device containing the vm 2-0
[MyStorageList.getDeviceContainsVm]: there is no device containing the vm 2-0
[MyStorageList.getDeviceContainsVm]: there is no device containing the vm 2-0
[MyStorageList.getDeviceContainsVm]: there is no device containing the vm 2-0
[MyStorageList.getDeviceContainsVm]: there is no device containing the vm 2-0
[MyStorageList.getDeviceContainsVm]: there is no device containing the vm 2-0
[MyStorageList.getDeviceContainsVm]: there is no device containing the vm 2-0
[MyStorageList.getDeviceContainsVm]: there is no device containing the vm 2-13
[MyStorageList.getDeviceContainsVm]: there is no device containing the vm 2-13
[MyStorageList.getDeviceContainsVm]: there is no device containing the vm 2-13
[MyStorageList.getDeviceContainsVm]: there is no device containing the vm 2-13
[MyStorageList.getDeviceContainsVm]: there is no device containing the vm 2-13
[MyStorageList.getDeviceContainsVm]: there is no device containing the vm 2-13
[MyStorageList.getDeviceContainsVm]: there is no device containing the vm 2-0
[MyStorageList.getDeviceContainsVm]: there is no device containing the vm 2-13
900.1: Broker: Cloudlet 10 received


--------------------------------------------------------------


New resource usage for the time frame starting at 1200,10:

1200,10: [Host #0] IO processing of VM #8 elapsed time is 0,56792 s
1200,10: [Host #0] IO processing of VM #14 elapsed time is 0,54717 s
1200,10: [Host #0] IO processing of VM #11 elapsed time is 0,56792 s
1200,10: [Host #0] Total allocated MIPS for VM #8 (Host #0) is 1000,00, was requested 1000,00 out of total 1000,00 (100,00%)
1200,10: [Host #0] MIPS for VM #8 by PEs (2 * 1860.0). PE #0: 360,00. PE #1: 640,00.
1200,10: [Host #0] Total allocated MIPS for VM #14 (Host #0) is 500,00, was requested 500,00 out of total 500,00 (100,00%)
1200,10: [Host #0] MIPS for VM #14 by PEs (2 * 1860.0). PE #0: 500,00.
1200,10: [Host #0] Total allocated MIPS for VM #11 (Host #0) is 1000,00, was requested 1000,00 out of total 1000,00 (100,00%)
1200,10: [Host #0] MIPS for VM #11 by PEs (2 * 1860.0). PE #0: 1000,00.
1200,10: [Host #0] utilization is 67,20%

1200,10: [Host #1] IO processing of VM #0 elapsed time is 1,60189 s
1200,10: [Host #1] IO processing of VM #6 elapsed time is 2,98868 s
1200,10: [Host #1] IO processing of VM #12 elapsed time is 0,54717 s
1200,10: [Host #1] Total allocated MIPS for VM #0 (Host #1) is 2500,00, was requested 2500,00 out of total 2500,00 (100,00%)
1200,10: [Host #1] MIPS for VM #0 by PEs (2 * 2660.0). PE #0: 2500,00.
1200,10: [Host #1] Total allocated MIPS for VM #6 (Host #1) is 2000,00, was requested 2000,00 out of total 2000,00 (100,00%)
1200,10: [Host #1] MIPS for VM #6 by PEs (2 * 2660.0). PE #0: 160,00. PE #1: 1840,00.
1200,10: [Host #1] Total allocated MIPS for VM #12 (Host #1) is 500,00, was requested 500,00 out of total 500,00 (100,00%)
1200,10: [Host #1] MIPS for VM #12 by PEs (2 * 2660.0). PE #1: 500,00.
1200,10: [Host #1] utilization is 93,98%

1200,10: [Host #2] IO processing of VM #9 elapsed time is 0,56792 s
1200,10: [Host #2] IO processing of VM #15 elapsed time is 0,54717 s
1200,10: [Host #2] IO processing of VM #10 elapsed time is 0,56792 s
1200,10: [Host #2] Total allocated MIPS for VM #9 (Host #2) is 1000,00, was requested 1000,00 out of total 1000,00 (100,00%)
1200,10: [Host #2] MIPS for VM #9 by PEs (2 * 1860.0). PE #0: 360,00. PE #1: 640,00.
1200,10: [Host #2] Total allocated MIPS for VM #15 (Host #2) is 500,00, was requested 500,00 out of total 500,00 (100,00%)
1200,10: [Host #2] MIPS for VM #15 by PEs (2 * 1860.0). PE #0: 500,00.
1200,10: [Host #2] Total allocated MIPS for VM #10 (Host #2) is 1000,00, was requested 1000,00 out of total 1000,00 (100,00%)
1200,10: [Host #2] MIPS for VM #10 by PEs (2 * 1860.0). PE #0: 1000,00.
1200,10: [Host #2] utilization is 67,20%

1200,10: [Host #3] IO processing of VM #1 elapsed time is 1,60189 s
1200,10: [Host #3] IO processing of VM #7 elapsed time is 2,98868 s
1200,10: [Host #3] IO processing of VM #13 elapsed time is 0,54717 s
1200,10: [Host #3] Total allocated MIPS for VM #1 (Host #3) is 2500,00, was requested 2500,00 out of total 2500,00 (100,00%)
1200,10: [Host #3] MIPS for VM #1 by PEs (2 * 2660.0). PE #0: 2500,00.
1200,10: [Host #3] Total allocated MIPS for VM #7 (Host #3) is 2000,00, was requested 2000,00 out of total 2000,00 (100,00%)
1200,10: [Host #3] MIPS for VM #7 by PEs (2 * 2660.0). PE #1: 2000,00.
1200,10: [Host #3] Total allocated MIPS for VM #13 (Host #3) is 500,00, was requested 500,00 out of total 500,00 (100,00%)
1200,10: [Host #3] MIPS for VM #13 by PEs (2 * 2660.0). PE #0: 160,00. PE #1: 340,00.
1200,10: [Host #3] utilization is 93,98%

1200,10: [Host #4] utilization is 0,00%

1200,10: [Host #5] IO processing of VM #2 elapsed time is 1,60189 s
1200,10: [Host #5] IO processing of VM #4 elapsed time is 2,98868 s
1200,10: [Host #5] Total allocated MIPS for VM #2 (Host #5) is 2500,00, was requested 2500,00 out of total 2500,00 (100,00%)
1200,10: [Host #5] MIPS for VM #2 by PEs (2 * 2660.0). PE #0: 2500,00.
1200,10: [Host #5] Total allocated MIPS for VM #4 (Host #5) is 2000,00, was requested 2000,00 out of total 2000,00 (100,00%)
1200,10: [Host #5] MIPS for VM #4 by PEs (2 * 2660.0). PE #0: 160,00. PE #1: 1840,00.
1200,10: [Host #5] utilization is 84,59%

1200,10: [Host #6] utilization is 0,00%

1200,10: [Host #7] IO processing of VM #3 elapsed time is 1,60189 s
1200,10: [Host #7] IO processing of VM #5 elapsed time is 2,98868 s
1200,10: [Host #7] Total allocated MIPS for VM #3 (Host #7) is 2500,00, was requested 2500,00 out of total 2500,00 (100,00%)
1200,10: [Host #7] MIPS for VM #3 by PEs (2 * 2660.0). PE #0: 2500,00.
1200,10: [Host #7] Total allocated MIPS for VM #5 (Host #7) is 2000,00, was requested 2000,00 out of total 2000,00 (100,00%)
1200,10: [Host #7] MIPS for VM #5 by PEs (2 * 2660.0). PE #0: 160,00. PE #1: 1840,00.
1200,10: [Host #7] utilization is 84,59%

1200,10: [Host #8] utilization is 0,00%

1200,10: [Host #9] utilization is 0,00%

Energy consumption for the last time frame from 900,10 to 1200,10:

1200,10: [Host #0] utilization at 900,10 was 67,20%, now is 67,20%
1200,10: [Host #0] energy is 23064,52 W*sec

1200,10: [Host #1] utilization at 900,10 was 93,98%, now is 93,98%
1200,10: [Host #1] energy is 26278,20 W*sec

1200,10: [Host #2] utilization at 900,10 was 67,20%, now is 67,20%
1200,10: [Host #2] energy is 23064,52 W*sec

1200,10: [Host #3] utilization at 900,10 was 93,98%, now is 93,98%
1200,10: [Host #3] energy is 26278,20 W*sec

1200,10: [Host #4] utilization at 900,10 was 0,00%, now is 0,00%
1200,10: [Host #4] energy is 0,00 W*sec

1200,10: [Host #5] utilization at 900,10 was 84,59%, now is 84,59%
1200,10: [Host #5] energy is 25150,38 W*sec

1200,10: [Host #6] utilization at 900,10 was 0,00%, now is 0,00%
1200,10: [Host #6] energy is 0,00 W*sec

1200,10: [Host #7] utilization at 900,10 was 84,59%, now is 84,59%
1200,10: [Host #7] energy is 25150,38 W*sec

1200,10: [Host #8] utilization at 900,10 was 0,00%, now is 0,00%
1200,10: [Host #8] energy is 0,00 W*sec

1200,10: [Host #9] utilization at 900,10 was 0,00%, now is 0,00%
1200,10: [Host #9] energy is 0,00 W*sec

1200,10: Data center's energy is 148986,18 W*sec


Hamza: optimizeAllocation
Over-utilized hosts:
Host #1
Host #3

Reallocation of VMs from the over-utilized hosts:
[VmScheduler.vmCreate] Allocation of VM #6 to Host #0 failed by RAM
VM #6 allocated to host #0
[VmScheduler.vmCreate] Allocation of VM #1 to Host #0 failed by RAM
VM #1 allocated to host #0
[VmScheduler.vmCreate] Allocation of VM #6 to Host #2 failed by RAM
VM #6 allocated to host #2
[VmScheduler.vmCreate] Allocation of VM #1 to Host #0 failed by RAM
VM #1 allocated to host #0
VM #6 allocated to host #4
[VmScheduler.vmCreate] Allocation of VM #1 to Host #0 failed by RAM
VM #1 allocated to host #0
[VmScheduler.vmCreate] Allocation of VM #6 to Host #5 failed by RAM
VM #6 allocated to host #5
[VmScheduler.vmCreate] Allocation of VM #1 to Host #0 failed by RAM
VM #1 allocated to host #0
VM #6 allocated to host #6
[VmScheduler.vmCreate] Allocation of VM #1 to Host #0 failed by RAM
VM #1 allocated to host #0
[VmScheduler.vmCreate] Allocation of VM #6 to Host #7 failed by RAM
VM #6 allocated to host #7
[VmScheduler.vmCreate] Allocation of VM #1 to Host #0 failed by RAM
VM #1 allocated to host #0
VM #6 allocated to host #8
[VmScheduler.vmCreate] Allocation of VM #1 to Host #0 failed by RAM
VM #1 allocated to host #0
VM #6 allocated to host #9
[VmScheduler.vmCreate] Allocation of VM #1 to Host #0 failed by RAM
VM #1 allocated to host #0
[VmScheduler.vmCreate] Allocation of VM #6 to Host #0 failed by RAM
VM #6 allocated to host #0
[VmScheduler.vmCreate] Allocation of VM #1 to Host #2 failed by RAM
VM #1 allocated to host #2
[VmScheduler.vmCreate] Allocation of VM #6 to Host #2 failed by RAM
VM #6 allocated to host #2
[VmScheduler.vmCreate] Allocation of VM #1 to Host #2 failed by RAM
VM #1 allocated to host #2
VM #6 allocated to host #4
[VmScheduler.vmCreate] Allocation of VM #1 to Host #2 failed by RAM
VM #1 allocated to host #2
[VmScheduler.vmCreate] Allocation of VM #6 to Host #5 failed by RAM
VM #6 allocated to host #5
[VmScheduler.vmCreate] Allocation of VM #1 to Host #2 failed by RAM
VM #1 allocated to host #2
VM #6 allocated to host #6
[VmScheduler.vmCreate] Allocation of VM #1 to Host #2 failed by RAM
VM #1 allocated to host #2
[VmScheduler.vmCreate] Allocation of VM #6 to Host #7 failed by RAM
VM #6 allocated to host #7
[VmScheduler.vmCreate] Allocation of VM #1 to Host #2 failed by RAM
VM #1 allocated to host #2
VM #6 allocated to host #8
[VmScheduler.vmCreate] Allocation of VM #1 to Host #2 failed by RAM
VM #1 allocated to host #2
VM #6 allocated to host #9
[VmScheduler.vmCreate] Allocation of VM #1 to Host #2 failed by RAM
VM #1 allocated to host #2
[VmScheduler.vmCreate] Allocation of VM #6 to Host #0 failed by RAM
VM #6 allocated to host #0
VM #1 allocated to host #4
[VmScheduler.vmCreate] Allocation of VM #6 to Host #2 failed by RAM
VM #6 allocated to host #2
VM #1 allocated to host #4
VM #6 allocated to host #4
VM #1 allocated to host #4
[VmScheduler.vmCreate] Allocation of VM #6 to Host #5 failed by RAM
VM #6 allocated to host #5
VM #1 allocated to host #4
VM #6 allocated to host #6
VM #1 allocated to host #4
[VmScheduler.vmCreate] Allocation of VM #6 to Host #7 failed by RAM
VM #6 allocated to host #7
VM #1 allocated to host #4
VM #6 allocated to host #8
VM #1 allocated to host #4
VM #6 allocated to host #9
VM #1 allocated to host #4
[VmScheduler.vmCreate] Allocation of VM #6 to Host #0 failed by RAM
VM #6 allocated to host #0
VM #1 allocated to host #5
[VmScheduler.vmCreate] Allocation of VM #6 to Host #2 failed by RAM
VM #6 allocated to host #2
VM #1 allocated to host #5
VM #6 allocated to host #4
VM #1 allocated to host #5
[VmScheduler.vmCreate] Allocation of VM #6 to Host #5 failed by RAM
VM #6 allocated to host #5
VM #1 allocated to host #5
VM #6 allocated to host #6
VM #1 allocated to host #5
[VmScheduler.vmCreate] Allocation of VM #6 to Host #7 failed by RAM
VM #6 allocated to host #7
VM #1 allocated to host #5
VM #6 allocated to host #8
VM #1 allocated to host #5
VM #6 allocated to host #9
VM #1 allocated to host #5
[VmScheduler.vmCreate] Allocation of VM #6 to Host #0 failed by RAM
VM #6 allocated to host #0
VM #1 allocated to host #6
[VmScheduler.vmCreate] Allocation of VM #6 to Host #2 failed by RAM
VM #6 allocated to host #2
VM #1 allocated to host #6
VM #6 allocated to host #4
VM #1 allocated to host #6
[VmScheduler.vmCreate] Allocation of VM #6 to Host #5 failed by RAM
VM #6 allocated to host #5
VM #1 allocated to host #6
VM #6 allocated to host #6
VM #1 allocated to host #6
[VmScheduler.vmCreate] Allocation of VM #6 to Host #7 failed by RAM
VM #6 allocated to host #7
VM #1 allocated to host #6
VM #6 allocated to host #8
VM #1 allocated to host #6
VM #6 allocated to host #9
VM #1 allocated to host #6
[VmScheduler.vmCreate] Allocation of VM #6 to Host #0 failed by RAM
VM #6 allocated to host #0
VM #1 allocated to host #7
[VmScheduler.vmCreate] Allocation of VM #6 to Host #2 failed by RAM
VM #6 allocated to host #2
VM #1 allocated to host #7
VM #6 allocated to host #4
VM #1 allocated to host #7
[VmScheduler.vmCreate] Allocation of VM #6 to Host #5 failed by RAM
VM #6 allocated to host #5
VM #1 allocated to host #7
VM #6 allocated to host #6
VM #1 allocated to host #7
[VmScheduler.vmCreate] Allocation of VM #6 to Host #7 failed by RAM
VM #6 allocated to host #7
VM #1 allocated to host #7
VM #6 allocated to host #8
VM #1 allocated to host #7
VM #6 allocated to host #9
VM #1 allocated to host #7
[VmScheduler.vmCreate] Allocation of VM #6 to Host #0 failed by RAM
VM #6 allocated to host #0
VM #1 allocated to host #8
[VmScheduler.vmCreate] Allocation of VM #6 to Host #2 failed by RAM
VM #6 allocated to host #2
VM #1 allocated to host #8
VM #6 allocated to host #4
VM #1 allocated to host #8
[VmScheduler.vmCreate] Allocation of VM #6 to Host #5 failed by RAM
VM #6 allocated to host #5
VM #1 allocated to host #8
VM #6 allocated to host #6
VM #1 allocated to host #8
[VmScheduler.vmCreate] Allocation of VM #6 to Host #7 failed by RAM
VM #6 allocated to host #7
VM #1 allocated to host #8
VM #6 allocated to host #8
VM #1 allocated to host #8
VM #6 allocated to host #9
VM #1 allocated to host #8
[VmScheduler.vmCreate] Allocation of VM #6 to Host #0 failed by RAM
VM #6 allocated to host #0
VM #1 allocated to host #9
[VmScheduler.vmCreate] Allocation of VM #6 to Host #2 failed by RAM
VM #6 allocated to host #2
VM #1 allocated to host #9
VM #6 allocated to host #4
VM #1 allocated to host #9
[VmScheduler.vmCreate] Allocation of VM #6 to Host #5 failed by RAM
VM #6 allocated to host #5
VM #1 allocated to host #9
VM #6 allocated to host #6
VM #1 allocated to host #9
[VmScheduler.vmCreate] Allocation of VM #6 to Host #7 failed by RAM
VM #6 allocated to host #7
VM #1 allocated to host #9
VM #6 allocated to host #8
VM #1 allocated to host #9
VM #6 allocated to host #9
VM #1 allocated to host #9

Under-utilized host: host #2

Reallocation of VMs from the under-utilized host: 9 15 10 
Not all VMs can be reallocated from the host, reallocation cancelled

Under-utilized host: host #0

Reallocation of VMs from the under-utilized host: 8 14 11 
Not all VMs can be reallocated from the host, reallocation cancelled

[MyStorageList.getDeviceContainsVm]: there is no device containing the vm 2-6
[MyStorageList.getDeviceContainsVm]: there is no device containing the vm 2-1
[MyStorageList.getDeviceContainsVm]: there is no device containing the vm 2-6
[MyStorageList.getDeviceContainsVm]: there is no device containing the vm 2-1
[MyStorageList.getDeviceContainsVm]: there is no device containing the vm 2-1
[MyStorageList.getDeviceContainsVm]: there is no device containing the vm 2-1
[MyStorageList.getDeviceContainsVm]: there is no device containing the vm 2-1
[MyStorageList.getDeviceContainsVm]: there is no device containing the vm 2-1
[MyStorageList.getDeviceContainsVm]: there is no device containing the vm 2-1
[MyStorageList.getDeviceContainsVm]: there is no device containing the vm 2-6
[MyStorageList.getDeviceContainsVm]: there is no device containing the vm 2-6
[MyStorageList.getDeviceContainsVm]: there is no device containing the vm 2-6
[MyStorageList.getDeviceContainsVm]: there is no device containing the vm 2-6
[MyStorageList.getDeviceContainsVm]: there is no device containing the vm 2-6
[MyStorageList.getDeviceContainsVm]: there is no device containing the vm 2-1
[MyStorageList.getDeviceContainsVm]: there is no device containing the vm 2-1
[MyStorageList.getDeviceContainsVm]: there is no device containing the vm 2-1
[MyStorageList.getDeviceContainsVm]: there is no device containing the vm 2-1
[MyStorageList.getDeviceContainsVm]: there is no device containing the vm 2-1
[MyStorageList.getDeviceContainsVm]: there is no device containing the vm 2-1
[MyStorageList.getDeviceContainsVm]: there is no device containing the vm 2-1
[MyStorageList.getDeviceContainsVm]: there is no device containing the vm 2-6
[MyStorageList.getDeviceContainsVm]: there is no device containing the vm 2-6
[MyStorageList.getDeviceContainsVm]: there is no device containing the vm 2-6
[MyStorageList.getDeviceContainsVm]: there is no device containing the vm 2-1
[MyStorageList.getDeviceContainsVm]: there is no device containing the vm 2-1
[MyStorageList.getDeviceContainsVm]: there is no device containing the vm 2-1
[MyStorageList.getDeviceContainsVm]: there is no device containing the vm 2-6
[MyStorageList.getDeviceContainsVm]: there is no device containing the vm 2-1
[MyStorageList.getDeviceContainsVm]: there is no device containing the vm 2-1
[MyStorageList.getDeviceContainsVm]: there is no device containing the vm 2-1
[MyStorageList.getDeviceContainsVm]: there is no device containing the vm 2-1
[MyStorageList.getDeviceContainsVm]: there is no device containing the vm 2-6
[MyStorageList.getDeviceContainsVm]: there is no device containing the vm 2-6
[MyStorageList.getDeviceContainsVm]: there is no device containing the vm 2-6
[MyStorageList.getDeviceContainsVm]: there is no device containing the vm 2-1
[MyStorageList.getDeviceContainsVm]: there is no device containing the vm 2-1
[MyStorageList.getDeviceContainsVm]: there is no device containing the vm 2-1
[MyStorageList.getDeviceContainsVm]: there is no device containing the vm 2-1
[MyStorageList.getDeviceContainsVm]: there is no device containing the vm 2-1
[MyStorageList.getDeviceContainsVm]: there is no device containing the vm 2-1
[MyStorageList.getDeviceContainsVm]: there is no device containing the vm 2-1
[MyStorageList.getDeviceContainsVm]: there is no device containing the vm 2-6
[MyStorageList.getDeviceContainsVm]: there is no device containing the vm 2-6
[MyStorageList.getDeviceContainsVm]: there is no device containing the vm 2-6
[MyStorageList.getDeviceContainsVm]: there is no device containing the vm 2-6
[MyStorageList.getDeviceContainsVm]: there is no device containing the vm 2-6
[MyStorageList.getDeviceContainsVm]: there is no device containing the vm 2-1
[MyStorageList.getDeviceContainsVm]: there is no device containing the vm 2-1
[MyStorageList.getDeviceContainsVm]: there is no device containing the vm 2-1
[MyStorageList.getDeviceContainsVm]: there is no device containing the vm 2-1
[MyStorageList.getDeviceContainsVm]: there is no device containing the vm 2-1
[MyStorageList.getDeviceContainsVm]: there is no device containing the vm 2-6
[MyStorageList.getDeviceContainsVm]: there is no device containing the vm 2-1
[MyStorageList.getDeviceContainsVm]: there is no device containing the vm 2-1
[MyStorageList.getDeviceContainsVm]: there is no device containing the vm 2-6
[MyStorageList.getDeviceContainsVm]: there is no device containing the vm 2-6
[MyStorageList.getDeviceContainsVm]: there is no device containing the vm 2-6
[MyStorageList.getDeviceContainsVm]: there is no device containing the vm 2-6
[MyStorageList.getDeviceContainsVm]: there is no device containing the vm 2-6
[MyStorageList.getDeviceContainsVm]: there is no device containing the vm 2-6
[MyStorageList.getDeviceContainsVm]: there is no device containing the vm 2-6
[MyStorageList.getDeviceContainsVm]: there is no device containing the vm 2-1
[MyStorageList.getDeviceContainsVm]: there is no device containing the vm 2-1
[MyStorageList.getDeviceContainsVm]: there is no device containing the vm 2-1
[MyStorageList.getDeviceContainsVm]: there is no device containing the vm 2-1
[MyStorageList.getDeviceContainsVm]: there is no device containing the vm 2-1
[MyStorageList.getDeviceContainsVm]: there is no device containing the vm 2-1
[MyStorageList.getDeviceContainsVm]: there is no device containing the vm 2-6
[MyStorageList.getDeviceContainsVm]: there is no device containing the vm 2-1
1200.1: Broker: Cloudlet 0 received
1200.1: Broker: Cloudlet 3 received


--------------------------------------------------------------


New resource usage for the time frame starting at 1500,10:

1500,10: [Host #0] IO processing of VM #8 elapsed time is 1,53208 s
1500,10: [Host #0] IO processing of VM #14 elapsed time is 0,48491 s
1500,10: [Host #0] IO processing of VM #11 elapsed time is 1,53208 s
1500,10: [Host #0] Total allocated MIPS for VM #8 (Host #0) is 1000,00, was requested 1000,00 out of total 1000,00 (100,00%)
1500,10: [Host #0] MIPS for VM #8 by PEs (2 * 1860.0). PE #0: 360,00. PE #1: 640,00.
1500,10: [Host #0] Total allocated MIPS for VM #14 (Host #0) is 500,00, was requested 500,00 out of total 500,00 (100,00%)
1500,10: [Host #0] MIPS for VM #14 by PEs (2 * 1860.0). PE #0: 500,00.
1500,10: [Host #0] Total allocated MIPS for VM #11 (Host #0) is 1000,00, was requested 1000,00 out of total 1000,00 (100,00%)
1500,10: [Host #0] MIPS for VM #11 by PEs (2 * 1860.0). PE #0: 1000,00.
1500,10: [Host #0] utilization is 67,20%

1500,10: [Host #1] IO processing of VM #0 elapsed time is 2,93396 s
1500,10: [Host #1] IO processing of VM #6 elapsed time is 0,25283 s
1500,10: [Host #1] IO processing of VM #12 elapsed time is 0,48491 s
1500,10: [Host #1] Total allocated MIPS for VM #0 (Host #1) is 2500,00, was requested 2500,00 out of total 2500,00 (100,00%)
1500,10: [Host #1] MIPS for VM #0 by PEs (2 * 2660.0). PE #0: 2500,00.
1500,10: [Host #1] Total allocated MIPS for VM #6 (Host #1) is 2000,00, was requested 2000,00 out of total 2000,00 (100,00%)
1500,10: [Host #1] MIPS for VM #6 by PEs (2 * 2660.0). PE #0: 160,00. PE #1: 1840,00.
1500,10: [Host #1] Total allocated MIPS for VM #12 (Host #1) is 500,00, was requested 500,00 out of total 500,00 (100,00%)
1500,10: [Host #1] MIPS for VM #12 by PEs (2 * 2660.0). PE #1: 500,00.
1500,10: [Host #1] utilization is 93,98%

1500,10: [Host #2] IO processing of VM #9 elapsed time is 1,53208 s
1500,10: [Host #2] IO processing of VM #15 elapsed time is 0,48491 s
1500,10: [Host #2] IO processing of VM #10 elapsed time is 1,53208 s
1500,10: [Host #2] Total allocated MIPS for VM #9 (Host #2) is 1000,00, was requested 1000,00 out of total 1000,00 (100,00%)
1500,10: [Host #2] MIPS for VM #9 by PEs (2 * 1860.0). PE #0: 360,00. PE #1: 640,00.
1500,10: [Host #2] Total allocated MIPS for VM #15 (Host #2) is 500,00, was requested 500,00 out of total 500,00 (100,00%)
1500,10: [Host #2] MIPS for VM #15 by PEs (2 * 1860.0). PE #0: 500,00.
1500,10: [Host #2] Total allocated MIPS for VM #10 (Host #2) is 1000,00, was requested 1000,00 out of total 1000,00 (100,00%)
1500,10: [Host #2] MIPS for VM #10 by PEs (2 * 1860.0). PE #0: 1000,00.
1500,10: [Host #2] utilization is 67,20%

1500,10: [Host #3] IO processing of VM #1 elapsed time is 2,93396 s
1500,10: [Host #3] IO processing of VM #7 elapsed time is 0,25283 s
1500,10: [Host #3] IO processing of VM #13 elapsed time is 0,48491 s
1500,10: [Host #3] Total allocated MIPS for VM #1 (Host #3) is 2500,00, was requested 2500,00 out of total 2500,00 (100,00%)
1500,10: [Host #3] MIPS for VM #1 by PEs (2 * 2660.0). PE #0: 2500,00.
1500,10: [Host #3] Total allocated MIPS for VM #7 (Host #3) is 2000,00, was requested 2000,00 out of total 2000,00 (100,00%)
1500,10: [Host #3] MIPS for VM #7 by PEs (2 * 2660.0). PE #1: 2000,00.
1500,10: [Host #3] Total allocated MIPS for VM #13 (Host #3) is 500,00, was requested 500,00 out of total 500,00 (100,00%)
1500,10: [Host #3] MIPS for VM #13 by PEs (2 * 2660.0). PE #0: 160,00. PE #1: 340,00.
1500,10: [Host #3] utilization is 93,98%

1500,10: [Host #4] utilization is 0,00%

1500,10: [Host #5] IO processing of VM #2 elapsed time is 2,93396 s
1500,10: [Host #5] IO processing of VM #4 elapsed time is 0,25283 s
1500,10: [Host #5] Total allocated MIPS for VM #2 (Host #5) is 2500,00, was requested 2500,00 out of total 2500,00 (100,00%)
1500,10: [Host #5] MIPS for VM #2 by PEs (2 * 2660.0). PE #0: 2500,00.
1500,10: [Host #5] Total allocated MIPS for VM #4 (Host #5) is 2000,00, was requested 2000,00 out of total 2000,00 (100,00%)
1500,10: [Host #5] MIPS for VM #4 by PEs (2 * 2660.0). PE #0: 160,00. PE #1: 1840,00.
1500,10: [Host #5] utilization is 84,59%

1500,10: [Host #6] utilization is 0,00%

1500,10: [Host #7] IO processing of VM #3 elapsed time is 2,93396 s
1500,10: [Host #7] IO processing of VM #5 elapsed time is 0,25283 s
1500,10: [Host #7] Total allocated MIPS for VM #3 (Host #7) is 2500,00, was requested 2500,00 out of total 2500,00 (100,00%)
1500,10: [Host #7] MIPS for VM #3 by PEs (2 * 2660.0). PE #0: 2500,00.
1500,10: [Host #7] Total allocated MIPS for VM #5 (Host #7) is 2000,00, was requested 2000,00 out of total 2000,00 (100,00%)
1500,10: [Host #7] MIPS for VM #5 by PEs (2 * 2660.0). PE #0: 160,00. PE #1: 1840,00.
1500,10: [Host #7] utilization is 84,59%

1500,10: [Host #8] utilization is 0,00%

1500,10: [Host #9] utilization is 0,00%

Energy consumption for the last time frame from 1200,10 to 1500,10:

1500,10: [Host #0] utilization at 1200,10 was 67,20%, now is 67,20%
1500,10: [Host #0] energy is 23064,52 W*sec

1500,10: [Host #1] utilization at 1200,10 was 93,98%, now is 93,98%
1500,10: [Host #1] energy is 26278,20 W*sec

1500,10: [Host #2] utilization at 1200,10 was 67,20%, now is 67,20%
1500,10: [Host #2] energy is 23064,52 W*sec

1500,10: [Host #3] utilization at 1200,10 was 93,98%, now is 93,98%
1500,10: [Host #3] energy is 26278,20 W*sec

1500,10: [Host #4] utilization at 1200,10 was 0,00%, now is 0,00%
1500,10: [Host #4] energy is 0,00 W*sec

1500,10: [Host #5] utilization at 1200,10 was 84,59%, now is 84,59%
1500,10: [Host #5] energy is 25150,38 W*sec

1500,10: [Host #6] utilization at 1200,10 was 0,00%, now is 0,00%
1500,10: [Host #6] energy is 0,00 W*sec

1500,10: [Host #7] utilization at 1200,10 was 84,59%, now is 84,59%
1500,10: [Host #7] energy is 25150,38 W*sec

1500,10: [Host #8] utilization at 1200,10 was 0,00%, now is 0,00%
1500,10: [Host #8] energy is 0,00 W*sec

1500,10: [Host #9] utilization at 1200,10 was 0,00%, now is 0,00%
1500,10: [Host #9] energy is 0,00 W*sec

1500,10: Data center's energy is 148986,18 W*sec


Hamza: optimizeAllocation
Over-utilized hosts:
Host #1
Host #3

Reallocation of VMs from the over-utilized hosts:
[VmScheduler.vmCreate] Allocation of VM #6 to Host #0 failed by RAM
VM #6 allocated to host #0
[VmScheduler.vmCreate] Allocation of VM #13 to Host #0 failed by RAM
VM #13 allocated to host #0
[VmScheduler.vmCreate] Allocation of VM #6 to Host #2 failed by RAM
VM #6 allocated to host #2
[VmScheduler.vmCreate] Allocation of VM #13 to Host #0 failed by RAM
VM #13 allocated to host #0
VM #6 allocated to host #4
[VmScheduler.vmCreate] Allocation of VM #13 to Host #0 failed by RAM
VM #13 allocated to host #0
[VmScheduler.vmCreate] Allocation of VM #6 to Host #5 failed by RAM
VM #6 allocated to host #5
[VmScheduler.vmCreate] Allocation of VM #13 to Host #0 failed by RAM
VM #13 allocated to host #0
VM #6 allocated to host #6
[VmScheduler.vmCreate] Allocation of VM #13 to Host #0 failed by RAM
VM #13 allocated to host #0
[VmScheduler.vmCreate] Allocation of VM #6 to Host #7 failed by RAM
VM #6 allocated to host #7
[VmScheduler.vmCreate] Allocation of VM #13 to Host #0 failed by RAM
VM #13 allocated to host #0
VM #6 allocated to host #8
[VmScheduler.vmCreate] Allocation of VM #13 to Host #0 failed by RAM
VM #13 allocated to host #0
VM #6 allocated to host #9
[VmScheduler.vmCreate] Allocation of VM #13 to Host #0 failed by RAM
VM #13 allocated to host #0
[VmScheduler.vmCreate] Allocation of VM #6 to Host #0 failed by RAM
VM #6 allocated to host #0
[VmScheduler.vmCreate] Allocation of VM #13 to Host #2 failed by RAM
VM #13 allocated to host #2
[VmScheduler.vmCreate] Allocation of VM #6 to Host #2 failed by RAM
VM #6 allocated to host #2
[VmScheduler.vmCreate] Allocation of VM #13 to Host #2 failed by RAM
VM #13 allocated to host #2
VM #6 allocated to host #4
[VmScheduler.vmCreate] Allocation of VM #13 to Host #2 failed by RAM
VM #13 allocated to host #2
[VmScheduler.vmCreate] Allocation of VM #6 to Host #5 failed by RAM
VM #6 allocated to host #5
[VmScheduler.vmCreate] Allocation of VM #13 to Host #2 failed by RAM
VM #13 allocated to host #2
VM #6 allocated to host #6
[VmScheduler.vmCreate] Allocation of VM #13 to Host #2 failed by RAM
VM #13 allocated to host #2
[VmScheduler.vmCreate] Allocation of VM #6 to Host #7 failed by RAM
VM #6 allocated to host #7
[VmScheduler.vmCreate] Allocation of VM #13 to Host #2 failed by RAM
VM #13 allocated to host #2
VM #6 allocated to host #8
[VmScheduler.vmCreate] Allocation of VM #13 to Host #2 failed by RAM
VM #13 allocated to host #2
VM #6 allocated to host #9
[VmScheduler.vmCreate] Allocation of VM #13 to Host #2 failed by RAM
VM #13 allocated to host #2
[VmScheduler.vmCreate] Allocation of VM #6 to Host #0 failed by RAM
VM #6 allocated to host #0
VM #13 allocated to host #4
[VmScheduler.vmCreate] Allocation of VM #6 to Host #2 failed by RAM
VM #6 allocated to host #2
VM #13 allocated to host #4
VM #6 allocated to host #4
VM #13 allocated to host #4
[VmScheduler.vmCreate] Allocation of VM #6 to Host #5 failed by RAM
VM #6 allocated to host #5
VM #13 allocated to host #4
VM #6 allocated to host #6
VM #13 allocated to host #4
[VmScheduler.vmCreate] Allocation of VM #6 to Host #7 failed by RAM
VM #6 allocated to host #7
VM #13 allocated to host #4
VM #6 allocated to host #8
VM #13 allocated to host #4
VM #6 allocated to host #9
VM #13 allocated to host #4
[VmScheduler.vmCreate] Allocation of VM #6 to Host #0 failed by RAM
VM #6 allocated to host #0
VM #13 allocated to host #5
[VmScheduler.vmCreate] Allocation of VM #6 to Host #2 failed by RAM
VM #6 allocated to host #2
VM #13 allocated to host #5
VM #6 allocated to host #4
VM #13 allocated to host #5
[VmScheduler.vmCreate] Allocation of VM #6 to Host #5 failed by RAM
VM #6 allocated to host #5
VM #13 allocated to host #5
VM #6 allocated to host #6
VM #13 allocated to host #5
[VmScheduler.vmCreate] Allocation of VM #6 to Host #7 failed by RAM
VM #6 allocated to host #7
VM #13 allocated to host #5
VM #6 allocated to host #8
VM #13 allocated to host #5
VM #6 allocated to host #9
VM #13 allocated to host #5
[VmScheduler.vmCreate] Allocation of VM #6 to Host #0 failed by RAM
VM #6 allocated to host #0
VM #13 allocated to host #6
[VmScheduler.vmCreate] Allocation of VM #6 to Host #2 failed by RAM
VM #6 allocated to host #2
VM #13 allocated to host #6
VM #6 allocated to host #4
VM #13 allocated to host #6
[VmScheduler.vmCreate] Allocation of VM #6 to Host #5 failed by RAM
VM #6 allocated to host #5
VM #13 allocated to host #6
VM #6 allocated to host #6
VM #13 allocated to host #6
[VmScheduler.vmCreate] Allocation of VM #6 to Host #7 failed by RAM
VM #6 allocated to host #7
VM #13 allocated to host #6
VM #6 allocated to host #8
VM #13 allocated to host #6
VM #6 allocated to host #9
VM #13 allocated to host #6
[VmScheduler.vmCreate] Allocation of VM #6 to Host #0 failed by RAM
VM #6 allocated to host #0
VM #13 allocated to host #7
[VmScheduler.vmCreate] Allocation of VM #6 to Host #2 failed by RAM
VM #6 allocated to host #2
VM #13 allocated to host #7
VM #6 allocated to host #4
VM #13 allocated to host #7
[VmScheduler.vmCreate] Allocation of VM #6 to Host #5 failed by RAM
VM #6 allocated to host #5
VM #13 allocated to host #7
VM #6 allocated to host #6
VM #13 allocated to host #7
[VmScheduler.vmCreate] Allocation of VM #6 to Host #7 failed by RAM
VM #6 allocated to host #7
VM #13 allocated to host #7
VM #6 allocated to host #8
VM #13 allocated to host #7
VM #6 allocated to host #9
VM #13 allocated to host #7
[VmScheduler.vmCreate] Allocation of VM #6 to Host #0 failed by RAM
VM #6 allocated to host #0
VM #13 allocated to host #8
[VmScheduler.vmCreate] Allocation of VM #6 to Host #2 failed by RAM
VM #6 allocated to host #2
VM #13 allocated to host #8
VM #6 allocated to host #4
VM #13 allocated to host #8
[VmScheduler.vmCreate] Allocation of VM #6 to Host #5 failed by RAM
VM #6 allocated to host #5
VM #13 allocated to host #8
VM #6 allocated to host #6
VM #13 allocated to host #8
[VmScheduler.vmCreate] Allocation of VM #6 to Host #7 failed by RAM
VM #6 allocated to host #7
VM #13 allocated to host #8
VM #6 allocated to host #8
VM #13 allocated to host #8
VM #6 allocated to host #9
VM #13 allocated to host #8
[VmScheduler.vmCreate] Allocation of VM #6 to Host #0 failed by RAM
VM #6 allocated to host #0
VM #13 allocated to host #9
[VmScheduler.vmCreate] Allocation of VM #6 to Host #2 failed by RAM
VM #6 allocated to host #2
