Initialising...
Simulation: Reached termination time.
Starting CloudSim version 3.0
Broker is starting...
Datacenter is starting...
Entities started.
0.0: Broker: Cloud Resource List received with 1 resource(s)
0.0: Broker: Trying to Create VM #0 in Datacenter
0.0: Broker: Trying to Create VM #1 in Datacenter
0.0: Broker: Trying to Create VM #2 in Datacenter
0.0: Broker: Trying to Create VM #3 in Datacenter
0.0: Broker: Trying to Create VM #4 in Datacenter
0.0: Broker: Trying to Create VM #5 in Datacenter
0.0: Broker: Trying to Create VM #6 in Datacenter
0.0: Broker: Trying to Create VM #7 in Datacenter
0.0: Broker: Trying to Create VM #8 in Datacenter
0.0: Broker: Trying to Create VM #9 in Datacenter
0,00: VM #0 has been allocated to the host #0
0,00: VM #1 has been allocated to the host #2
0,00: VM #2 has been allocated to the host #4
0,00: VM #3 has been allocated to the host #6
0,00: VM #4 has been allocated to the host #8
0,00: VM #5 has been allocated to the host #1
0,00: VM #6 has been allocated to the host #0
0,00: VM #7 has been allocated to the host #2
0,00: VM #8 has been allocated to the host #4
0,00: VM #9 has been allocated to the host #6
0.1: Broker: VM #0 has been created in Datacenter #3, Host #0
0.1: Broker: VM #1 has been created in Datacenter #3, Host #2
0.1: Broker: VM #2 has been created in Datacenter #3, Host #4
0.1: Broker: VM #3 has been created in Datacenter #3, Host #6
0.1: Broker: VM #4 has been created in Datacenter #3, Host #8
0.1: Broker: VM #5 has been created in Datacenter #3, Host #1
0.1: Broker: VM #6 has been created in Datacenter #3, Host #0
0.1: Broker: VM #7 has been created in Datacenter #3, Host #2
0.1: Broker: VM #8 has been created in Datacenter #3, Host #4
0.1: Broker: VM #9 has been created in Datacenter #3, Host #6
0.1: Broker: Sending cloudlet 0 to VM #0
0.1: Broker: Sending cloudlet 1 to VM #1
0.1: Broker: Sending cloudlet 2 to VM #2
0.1: Broker: Sending cloudlet 3 to VM #3
0.1: Broker: Sending cloudlet 4 to VM #4
0.1: Broker: Sending cloudlet 5 to VM #5
0.1: Broker: Sending cloudlet 6 to VM #6
0.1: Broker: Sending cloudlet 7 to VM #7
0.1: Broker: Sending cloudlet 8 to VM #8
0.1: Broker: Sending cloudlet 9 to VM #9


--------------------------------------------------------------


New resource usage for the time frame starting at 300,10:

300,10: [Host #0] IO processing of VM #0 elapsed time is 1,79623 s
300,10: [Host #0] IO processing of VM #6 elapsed time is 2,79811 s
300,10: [Host #0] Total allocated MIPS for VM #0 (Host #0) is 500,00, was requested 500,00 out of total 500,00 (100,00%)
300,10: [Host #0] MIPS for VM #0 by PEs (2 * 2660.0). PE #0: 500,00.
300,10: [Host #0] Total allocated MIPS for VM #6 (Host #0) is 2000,00, was requested 2000,00 out of total 2000,00 (100,00%)
300,10: [Host #0] MIPS for VM #6 by PEs (2 * 2660.0). PE #0: 2000,00.
300,10: [Host #0] utilization is 46,99%

300,10: [Host #1] IO processing of VM #5 elapsed time is 1,61887 s
300,10: [Host #1] Total allocated MIPS for VM #5 (Host #1) is 1000,00, was requested 1000,00 out of total 1000,00 (100,00%)
300,10: [Host #1] MIPS for VM #5 by PEs (2 * 1860.0). PE #0: 1000,00.
300,10: [Host #1] utilization is 26,88%

300,10: [Host #2] IO processing of VM #1 elapsed time is 1,79623 s
300,10: [Host #2] IO processing of VM #7 elapsed time is 2,79811 s
300,10: [Host #2] Total allocated MIPS for VM #1 (Host #2) is 500,00, was requested 500,00 out of total 500,00 (100,00%)
300,10: [Host #2] MIPS for VM #1 by PEs (2 * 2660.0). PE #0: 500,00.
300,10: [Host #2] Total allocated MIPS for VM #7 (Host #2) is 2000,00, was requested 2000,00 out of total 2000,00 (100,00%)
300,10: [Host #2] MIPS for VM #7 by PEs (2 * 2660.0). PE #0: 2000,00.
300,10: [Host #2] utilization is 46,99%

300,10: [Host #3] utilization is 0,00%

300,10: [Host #4] IO processing of VM #2 elapsed time is 1,79623 s
300,10: [Host #4] IO processing of VM #8 elapsed time is 2,79811 s
300,10: [Host #4] Total allocated MIPS for VM #2 (Host #4) is 500,00, was requested 500,00 out of total 500,00 (100,00%)
300,10: [Host #4] MIPS for VM #2 by PEs (2 * 2660.0). PE #0: 500,00.
300,10: [Host #4] Total allocated MIPS for VM #8 (Host #4) is 2000,00, was requested 2000,00 out of total 2000,00 (100,00%)
300,10: [Host #4] MIPS for VM #8 by PEs (2 * 2660.0). PE #0: 2000,00.
300,10: [Host #4] utilization is 46,99%

300,10: [Host #5] utilization is 0,00%

300,10: [Host #6] IO processing of VM #3 elapsed time is 1,61887 s
300,10: [Host #6] IO processing of VM #9 elapsed time is 0,44528 s
300,10: [Host #6] Total allocated MIPS for VM #3 (Host #6) is 1000,00, was requested 1000,00 out of total 1000,00 (100,00%)
300,10: [Host #6] MIPS for VM #3 by PEs (2 * 2660.0). PE #0: 1000,00.
300,10: [Host #6] Total allocated MIPS for VM #9 (Host #6) is 2500,00, was requested 2500,00 out of total 2500,00 (100,00%)
300,10: [Host #6] MIPS for VM #9 by PEs (2 * 2660.0). PE #0: 1660,00. PE #1: 840,00.
300,10: [Host #6] utilization is 65,79%

300,10: [Host #7] utilization is 0,00%

300,10: [Host #8] IO processing of VM #4 elapsed time is 1,61887 s
300,10: [Host #8] Total allocated MIPS for VM #4 (Host #8) is 1000,00, was requested 1000,00 out of total 1000,00 (100,00%)
300,10: [Host #8] MIPS for VM #4 by PEs (2 * 2660.0). PE #0: 1000,00.
300,10: [Host #8] utilization is 18,80%

300,10: [Host #9] utilization is 0,00%

Energy consumption for the last time frame from 0,00 to 300,10:

300,10: [Host #0] utilization at 0,00 was 0,00%, now is 46,99%
300,10: [Host #0] energy is 0,00 W*sec

300,10: [Host #1] utilization at 0,00 was 0,00%, now is 26,88%
300,10: [Host #1] energy is 0,00 W*sec

300,10: [Host #2] utilization at 0,00 was 0,00%, now is 46,99%
300,10: [Host #2] energy is 0,00 W*sec

300,10: [Host #3] utilization at 0,00 was 0,00%, now is 0,00%
300,10: [Host #3] energy is 0,00 W*sec

300,10: [Host #4] utilization at 0,00 was 0,00%, now is 46,99%
300,10: [Host #4] energy is 0,00 W*sec

300,10: [Host #5] utilization at 0,00 was 0,00%, now is 0,00%
300,10: [Host #5] energy is 0,00 W*sec

300,10: [Host #6] utilization at 0,00 was 0,00%, now is 65,79%
300,10: [Host #6] energy is 0,00 W*sec

300,10: [Host #7] utilization at 0,00 was 0,00%, now is 0,00%
300,10: [Host #7] energy is 0,00 W*sec

300,10: [Host #8] utilization at 0,00 was 0,00%, now is 18,80%
300,10: [Host #8] energy is 0,00 W*sec

300,10: [Host #9] utilization at 0,00 was 0,00%, now is 0,00%
300,10: [Host #9] energy is 0,00 W*sec

300,10: Data center's energy is 0,00 W*sec


Hamza: optimizeAllocation
Over-utilized hosts:

Reallocation of VMs from the over-utilized hosts:

Under-utilized host: host #8

Reallocation of VMs from the under-utilized host: 4 
VM #4 allocated to host #6

Under-utilized host: host #4

Reallocation of VMs from the under-utilized host: 2 8 
VM #8 allocated to host #0
VM #2 allocated to host #2

Under-utilized host: host #1

Reallocation of VMs from the under-utilized host: 5 
VM #5 allocated to host #2

300,10: Migration of VM #4 from Host #8 to Host #6 is started
300,10: [Host #6] Total allocated MIPS for VM #3 (Host #6) is 1000,00, was requested 1000,00 out of total 1000,00 (100,00%)
300,10: [Host #6] MIPS for VM #3 by PEs (2 * 2660.0). PE #0: 1000,00.
300,10: [Host #6] Total allocated MIPS for VM #9 (Host #6) is 2500,00, was requested 2500,00 out of total 2500,00 (100,00%)
300,10: [Host #6] MIPS for VM #9 by PEs (2 * 2660.0). PE #0: 1560,00. PE #1: 940,00.
300,10: [Host #6] Total allocated MIPS for VM #4 (Host #8) is 100,00, was requested 1000,00 out of total 1000,00 (100,00%)
300,10: [Host #6] MIPS for VM #4 by PEs (2 * 2660.0). PE #0: 100,00.
300,10: [Host #6] VM #4 is being migrated to Host #6
300,10: [Host #8] Total allocated MIPS for VM #4 (Host #8) is 900,00, was requested 1000,00 out of total 1000,00 (100,00%)
300,10: [Host #8] MIPS for VM #4 by PEs (2 * 2660.0). PE #0: 900,00.
300,10: [Host #8] Under allocated MIPS for VM #4: 100,00
300,10: [Host #8] VM #4 is in migration
300,10: Migration of VM #8 from Host #4 to Host #0 is started
300,10: [Host #0] Total allocated MIPS for VM #0 (Host #0) is 500,00, was requested 500,00 out of total 500,00 (100,00%)
300,10: [Host #0] MIPS for VM #0 by PEs (2 * 2660.0). PE #0: 500,00.
300,10: [Host #0] Total allocated MIPS for VM #6 (Host #0) is 2000,00, was requested 2000,00 out of total 2000,00 (100,00%)
300,10: [Host #0] MIPS for VM #6 by PEs (2 * 2660.0). PE #0: 2000,00.
300,10: [Host #0] Total allocated MIPS for VM #8 (Host #4) is 200,00, was requested 2000,00 out of total 2000,00 (100,00%)
300,10: [Host #0] MIPS for VM #8 by PEs (2 * 2660.0). PE #0: 160,00. PE #1: 40,00.
300,10: [Host #0] VM #8 is being migrated to Host #0
300,10: [Host #4] Total allocated MIPS for VM #2 (Host #4) is 500,00, was requested 500,00 out of total 500,00 (100,00%)
300,10: [Host #4] MIPS for VM #2 by PEs (2 * 2660.0). PE #0: 500,00.
300,10: [Host #4] Total allocated MIPS for VM #8 (Host #4) is 1800,00, was requested 2000,00 out of total 2000,00 (100,00%)
300,10: [Host #4] MIPS for VM #8 by PEs (2 * 2660.0). PE #0: 1800,00.
300,10: [Host #4] Under allocated MIPS for VM #8: 200,00
300,10: [Host #4] VM #8 is in migration
300,10: Migration of VM #2 from Host #4 to Host #2 is started
300,10: [Host #2] Total allocated MIPS for VM #1 (Host #2) is 500,00, was requested 500,00 out of total 500,00 (100,00%)
300,10: [Host #2] MIPS for VM #1 by PEs (2 * 2660.0). PE #0: 500,00.
300,10: [Host #2] Total allocated MIPS for VM #7 (Host #2) is 2000,00, was requested 2000,00 out of total 2000,00 (100,00%)
300,10: [Host #2] MIPS for VM #7 by PEs (2 * 2660.0). PE #0: 2000,00.
300,10: [Host #2] Total allocated MIPS for VM #2 (Host #4) is 50,00, was requested 500,00 out of total 500,00 (100,00%)
300,10: [Host #2] MIPS for VM #2 by PEs (2 * 2660.0). PE #0: 50,00.
300,10: [Host #2] VM #2 is being migrated to Host #2
300,10: [Host #4] Total allocated MIPS for VM #2 (Host #4) is 450,00, was requested 500,00 out of total 500,00 (100,00%)
300,10: [Host #4] MIPS for VM #2 by PEs (2 * 2660.0). PE #0: 450,00.
300,10: [Host #4] Under allocated MIPS for VM #2: 50,00
300,10: [Host #4] VM #2 is in migration
300,10: [Host #4] Total allocated MIPS for VM #8 (Host #4) is 1800,00, was requested 2000,00 out of total 2000,00 (100,00%)
300,10: [Host #4] MIPS for VM #8 by PEs (2 * 2660.0). PE #0: 1800,00.
300,10: [Host #4] Under allocated MIPS for VM #8: 200,00
300,10: [Host #4] VM #8 is in migration
300,10: Migration of VM #5 from Host #1 to Host #2 is started
300,10: [Host #2] Total allocated MIPS for VM #1 (Host #2) is 500,00, was requested 500,00 out of total 500,00 (100,00%)
300,10: [Host #2] MIPS for VM #1 by PEs (2 * 2660.0). PE #0: 500,00.
300,10: [Host #2] Total allocated MIPS for VM #7 (Host #2) is 2000,00, was requested 2000,00 out of total 2000,00 (100,00%)
300,10: [Host #2] MIPS for VM #7 by PEs (2 * 2660.0). PE #0: 2000,00.
300,10: [Host #2] Total allocated MIPS for VM #2 (Host #4) is 50,00, was requested 500,00 out of total 500,00 (100,00%)
300,10: [Host #2] MIPS for VM #2 by PEs (2 * 2660.0). PE #0: 50,00.
300,10: [Host #2] VM #2 is being migrated to Host #2
300,10: [Host #2] Total allocated MIPS for VM #5 (Host #1) is 100,00, was requested 1000,00 out of total 1000,00 (100,00%)
300,10: [Host #2] MIPS for VM #5 by PEs (2 * 2660.0). PE #0: 100,00.
300,10: [Host #2] VM #5 is being migrated to Host #2
300,10: [Host #1] Total allocated MIPS for VM #5 (Host #1) is 900,00, was requested 1000,00 out of total 1000,00 (100,00%)
300,10: [Host #1] MIPS for VM #5 by PEs (2 * 1860.0). PE #0: 900,00.
300,10: [Host #1] Under allocated MIPS for VM #5: 100,00
300,10: [Host #1] VM #5 is in migration


--------------------------------------------------------------


New resource usage for the time frame starting at 340,10:

340,10: [Host #0] IO processing of VM #0 elapsed time is 1,79623 s
340,10: [Host #0] IO processing of VM #6 elapsed time is 2,79811 s
340,10: [Host #0] Total allocated MIPS for VM #0 (Host #0) is 500,00, was requested 500,00 out of total 500,00 (100,00%)
340,10: [Host #0] MIPS for VM #0 by PEs (2 * 2660.0). PE #0: 500,00.
340,10: [Host #0] Total allocated MIPS for VM #6 (Host #0) is 2000,00, was requested 2000,00 out of total 2000,00 (100,00%)
340,10: [Host #0] MIPS for VM #6 by PEs (2 * 2660.0). PE #0: 2000,00.
340,10: [Host #0] Total allocated MIPS for VM #8 (Host #4) is 200,00, was requested 2000,00 out of total 2000,00 (100,00%)
340,10: [Host #0] MIPS for VM #8 by PEs (2 * 2660.0). PE #0: 160,00. PE #1: 40,00.
340,10: [Host #0] VM #8 is being migrated to Host #0
340,10: [Host #0] utilization is 50,75%

340,10: [Host #1] IO processing of VM #5 elapsed time is 1,61887 s
340,10: [Host #1] Total allocated MIPS for VM #5 (Host #1) is 900,00, was requested 1000,00 out of total 1000,00 (100,00%)
340,10: [Host #1] MIPS for VM #5 by PEs (2 * 1860.0). PE #0: 900,00.
340,10: [Host #1] Under allocated MIPS for VM #5: 100,00
340,10: [Host #1] VM #5 is in migration
340,10: [Host #1] utilization is 26,88%

340,10: [Host #2] IO processing of VM #1 elapsed time is 1,79623 s
340,10: [Host #2] IO processing of VM #7 elapsed time is 2,79811 s
340,10: [Host #2] Total allocated MIPS for VM #1 (Host #2) is 500,00, was requested 500,00 out of total 500,00 (100,00%)
340,10: [Host #2] MIPS for VM #1 by PEs (2 * 2660.0). PE #0: 500,00.
340,10: [Host #2] Total allocated MIPS for VM #7 (Host #2) is 2000,00, was requested 2000,00 out of total 2000,00 (100,00%)
340,10: [Host #2] MIPS for VM #7 by PEs (2 * 2660.0). PE #0: 2000,00.
340,10: [Host #2] Total allocated MIPS for VM #2 (Host #4) is 50,00, was requested 500,00 out of total 500,00 (100,00%)
340,10: [Host #2] MIPS for VM #2 by PEs (2 * 2660.0). PE #0: 50,00.
340,10: [Host #2] VM #2 is being migrated to Host #2
340,10: [Host #2] Total allocated MIPS for VM #5 (Host #1) is 100,00, was requested 1000,00 out of total 1000,00 (100,00%)
340,10: [Host #2] MIPS for VM #5 by PEs (2 * 2660.0). PE #0: 100,00.
340,10: [Host #2] VM #5 is being migrated to Host #2
340,10: [Host #2] utilization is 49,81%

340,10: [Host #3] utilization is 0,00%

340,10: [Host #4] IO processing of VM #2 elapsed time is 1,79623 s
340,10: [Host #4] IO processing of VM #8 elapsed time is 2,79811 s
340,10: [Host #4] Total allocated MIPS for VM #2 (Host #4) is 450,00, was requested 500,00 out of total 500,00 (100,00%)
340,10: [Host #4] MIPS for VM #2 by PEs (2 * 2660.0). PE #0: 450,00.
340,10: [Host #4] Under allocated MIPS for VM #2: 50,00
340,10: [Host #4] VM #2 is in migration
340,10: [Host #4] Total allocated MIPS for VM #8 (Host #4) is 1800,00, was requested 2000,00 out of total 2000,00 (100,00%)
340,10: [Host #4] MIPS for VM #8 by PEs (2 * 2660.0). PE #0: 1800,00.
340,10: [Host #4] Under allocated MIPS for VM #8: 200,00
340,10: [Host #4] VM #8 is in migration
340,10: [Host #4] utilization is 46,99%

340,10: [Host #5] utilization is 0,00%

340,10: [Host #6] IO processing of VM #3 elapsed time is 1,61887 s
340,10: [Host #6] IO processing of VM #9 elapsed time is 0,44528 s
340,10: [Host #6] Total allocated MIPS for VM #3 (Host #6) is 1000,00, was requested 1000,00 out of total 1000,00 (100,00%)
340,10: [Host #6] MIPS for VM #3 by PEs (2 * 2660.0). PE #0: 1000,00.
340,10: [Host #6] Total allocated MIPS for VM #9 (Host #6) is 2500,00, was requested 2500,00 out of total 2500,00 (100,00%)
340,10: [Host #6] MIPS for VM #9 by PEs (2 * 2660.0). PE #0: 1560,00. PE #1: 940,00.
340,10: [Host #6] Total allocated MIPS for VM #4 (Host #8) is 100,00, was requested 1000,00 out of total 1000,00 (100,00%)
340,10: [Host #6] MIPS for VM #4 by PEs (2 * 2660.0). PE #0: 100,00.
340,10: [Host #6] VM #4 is being migrated to Host #6
340,10: [Host #6] utilization is 67,67%

340,10: [Host #7] utilization is 0,00%

340,10: [Host #8] IO processing of VM #4 elapsed time is 1,61887 s
340,10: [Host #8] Total allocated MIPS for VM #4 (Host #8) is 900,00, was requested 1000,00 out of total 1000,00 (100,00%)
340,10: [Host #8] MIPS for VM #4 by PEs (2 * 2660.0). PE #0: 900,00.
340,10: [Host #8] Under allocated MIPS for VM #4: 100,00
340,10: [Host #8] VM #4 is in migration
340,10: [Host #8] utilization is 18,80%

340,10: [Host #9] utilization is 0,00%

Energy consumption for the last time frame from 300,10 to 340,10:

340,10: [Host #0] utilization at 300,10 was 50,75%, now is 50,75%
340,10: [Host #0] energy is 2812,03 W*sec

340,10: [Host #1] utilization at 300,10 was 26,88%, now is 26,88%
340,10: [Host #1] energy is 2430,11 W*sec

340,10: [Host #2] utilization at 300,10 was 49,81%, now is 49,81%
340,10: [Host #2] energy is 2796,99 W*sec

340,10: [Host #3] utilization at 300,10 was 0,00%, now is 0,00%
340,10: [Host #3] energy is 0,00 W*sec

340,10: [Host #4] utilization at 300,10 was 46,99%, now is 46,99%
340,10: [Host #4] energy is 2751,88 W*sec

340,10: [Host #5] utilization at 300,10 was 0,00%, now is 0,00%
340,10: [Host #5] energy is 0,00 W*sec

340,10: [Host #6] utilization at 300,10 was 67,67%, now is 67,67%
340,10: [Host #6] energy is 3082,71 W*sec

340,10: [Host #7] utilization at 300,10 was 0,00%, now is 0,00%
340,10: [Host #7] energy is 0,00 W*sec

340,10: [Host #8] utilization at 300,10 was 18,80%, now is 18,80%
340,10: [Host #8] energy is 2300,75 W*sec

340,10: [Host #9] utilization at 300,10 was 0,00%, now is 0,00%
340,10: [Host #9] energy is 0,00 W*sec

340,10: Data center's energy is 16174,47 W*sec

[MyStorageList.getDeviceContainsVm]: there is no device containing the vm 2-8
[MyStorageList.getDeviceContainsVm]: there is no device containing the vm 2-2
[MyStorageList.getDeviceContainsVm]: there is no device containing the vm 2-5
[MyStorageList.getDeviceContainsVm]: there is no device containing the vm 2-4

[MyStorageList.getDeviceContainsVm]: there is no device containing the vm 2-4
340,10: VM #4 has been allocated to the host #6
340,10: Migration of VM #4 to Host #6 is completed
[MyStorageList.getDeviceContainsVm]: there is no device containing the vm 2-8
340,10: VM #8 has been allocated to the host #0
340,10: Migration of VM #8 to Host #0 is completed
[MyStorageList.getDeviceContainsVm]: there is no device containing the vm 2-2
340,10: VM #2 has been allocated to the host #2
340,10: Migration of VM #2 to Host #2 is completed
[MyStorageList.getDeviceContainsVm]: there is no device containing the vm 2-5
340,10: VM #5 has been allocated to the host #2
340,10: Migration of VM #5 to Host #2 is completed


--------------------------------------------------------------


New resource usage for the time frame starting at 340,10:

340,10: [Host #0] IO processing of VM #0 elapsed time is 1,79623 s
340,10: [Host #0] IO processing of VM #6 elapsed time is 2,79811 s
340,10: [Host #0] IO processing of VM #8 elapsed time is 2,79811 s
340,10: [Host #0] Total allocated MIPS for VM #0 (Host #0) is 500,00, was requested 500,00 out of total 500,00 (100,00%)
340,10: [Host #0] MIPS for VM #0 by PEs (2 * 2660.0). PE #0: 500,00.
340,10: [Host #0] Total allocated MIPS for VM #6 (Host #0) is 2000,00, was requested 2000,00 out of total 2000,00 (100,00%)
340,10: [Host #0] MIPS for VM #6 by PEs (2 * 2660.0). PE #0: 2000,00.
340,10: [Host #0] Total allocated MIPS for VM #8 (Host #0) is 2000,00, was requested 2000,00 out of total 2000,00 (100,00%)
340,10: [Host #0] MIPS for VM #8 by PEs (2 * 2660.0). PE #0: 160,00. PE #1: 1840,00.
340,10: [Host #0] utilization is 84,59%

340,10: [Host #1] utilization is 0,00%

340,10: [Host #2] IO processing of VM #1 elapsed time is 1,79623 s
340,10: [Host #2] IO processing of VM #7 elapsed time is 2,79811 s
340,10: [Host #2] IO processing of VM #2 elapsed time is 1,79623 s
340,10: [Host #2] IO processing of VM #5 elapsed time is 1,61887 s
340,10: [Host #2] Total allocated MIPS for VM #1 (Host #2) is 500,00, was requested 500,00 out of total 500,00 (100,00%)
340,10: [Host #2] MIPS for VM #1 by PEs (2 * 2660.0). PE #0: 500,00.
340,10: [Host #2] Total allocated MIPS for VM #7 (Host #2) is 2000,00, was requested 2000,00 out of total 2000,00 (100,00%)
340,10: [Host #2] MIPS for VM #7 by PEs (2 * 2660.0). PE #0: 660,00. PE #1: 1340,00.
340,10: [Host #2] Total allocated MIPS for VM #2 (Host #2) is 500,00, was requested 500,00 out of total 500,00 (100,00%)
340,10: [Host #2] MIPS for VM #2 by PEs (2 * 2660.0). PE #0: 500,00.
340,10: [Host #2] Total allocated MIPS for VM #5 (Host #2) is 1000,00, was requested 1000,00 out of total 1000,00 (100,00%)
340,10: [Host #2] MIPS for VM #5 by PEs (2 * 2660.0). PE #0: 1000,00.
340,10: [Host #2] utilization is 75,19%

340,10: [Host #3] utilization is 0,00%

340,10: [Host #4] utilization is 0,00%

340,10: [Host #5] utilization is 0,00%

340,10: [Host #6] IO processing of VM #3 elapsed time is 1,61887 s
340,10: [Host #6] IO processing of VM #9 elapsed time is 0,44528 s
340,10: [Host #6] IO processing of VM #4 elapsed time is 1,61887 s
340,10: [Host #6] Total allocated MIPS for VM #3 (Host #6) is 1000,00, was requested 1000,00 out of total 1000,00 (100,00%)
340,10: [Host #6] MIPS for VM #3 by PEs (2 * 2660.0). PE #0: 1000,00.
340,10: [Host #6] Total allocated MIPS for VM #9 (Host #6) is 2500,00, was requested 2500,00 out of total 2500,00 (100,00%)
340,10: [Host #6] MIPS for VM #9 by PEs (2 * 2660.0). PE #0: 660,00. PE #1: 1840,00.
340,10: [Host #6] Total allocated MIPS for VM #4 (Host #6) is 1000,00, was requested 1000,00 out of total 1000,00 (100,00%)
340,10: [Host #6] MIPS for VM #4 by PEs (2 * 2660.0). PE #0: 1000,00.
340,10: [Host #6] utilization is 84,59%

340,10: [Host #7] utilization is 0,00%

340,10: [Host #8] utilization is 0,00%

340,10: [Host #9] utilization is 0,00%

340.1: Broker: Cloudlet 7 received


--------------------------------------------------------------


New resource usage for the time frame starting at 600,10:

600,10: [Host #0] IO processing of VM #0 elapsed time is 1,67170 s
600,10: [Host #0] IO processing of VM #6 elapsed time is 0,53396 s
600,10: [Host #0] IO processing of VM #8 elapsed time is 0,53396 s
600,10: [Host #0] Total allocated MIPS for VM #0 (Host #0) is 500,00, was requested 500,00 out of total 500,00 (100,00%)
600,10: [Host #0] MIPS for VM #0 by PEs (2 * 2660.0). PE #0: 500,00.
600,10: [Host #0] Total allocated MIPS for VM #6 (Host #0) is 2000,00, was requested 2000,00 out of total 2000,00 (100,00%)
600,10: [Host #0] MIPS for VM #6 by PEs (2 * 2660.0). PE #0: 2000,00.
600,10: [Host #0] Total allocated MIPS for VM #8 (Host #0) is 2000,00, was requested 2000,00 out of total 2000,00 (100,00%)
600,10: [Host #0] MIPS for VM #8 by PEs (2 * 2660.0). PE #0: 160,00. PE #1: 1840,00.
600,10: [Host #0] utilization is 84,59%

600,10: [Host #1] utilization is 0,00%

600,10: [Host #2] IO processing of VM #1 elapsed time is 1,67170 s
600,10: [Host #2] IO processing of VM #7 elapsed time is 0,53396 s
600,10: [Host #2] IO processing of VM #2 elapsed time is 1,67170 s
600,10: [Host #2] IO processing of VM #5 elapsed time is 0,39811 s
600,10: [Host #2] Total allocated MIPS for VM #1 (Host #2) is 500,00, was requested 500,00 out of total 500,00 (100,00%)
600,10: [Host #2] MIPS for VM #1 by PEs (2 * 2660.0). PE #0: 500,00.
600,10: [Host #2] Total allocated MIPS for VM #7 (Host #2) is 2000,00, was requested 2000,00 out of total 2000,00 (100,00%)
600,10: [Host #2] MIPS for VM #7 by PEs (2 * 2660.0). PE #0: 660,00. PE #1: 1340,00.
600,10: [Host #2] Total allocated MIPS for VM #2 (Host #2) is 500,00, was requested 500,00 out of total 500,00 (100,00%)
600,10: [Host #2] MIPS for VM #2 by PEs (2 * 2660.0). PE #0: 500,00.
600,10: [Host #2] Total allocated MIPS for VM #5 (Host #2) is 1000,00, was requested 1000,00 out of total 1000,00 (100,00%)
600,10: [Host #2] MIPS for VM #5 by PEs (2 * 2660.0). PE #0: 1000,00.
600,10: [Host #2] utilization is 75,19%

600,10: [Host #3] utilization is 0,00%

600,10: [Host #4] utilization is 0,00%

600,10: [Host #5] utilization is 0,00%

600,10: [Host #6] IO processing of VM #3 elapsed time is 0,39811 s
600,10: [Host #6] IO processing of VM #9 elapsed time is 0,20943 s
600,10: [Host #6] IO processing of VM #4 elapsed time is 0,39811 s
600,10: [Host #6] Total allocated MIPS for VM #3 (Host #6) is 1000,00, was requested 1000,00 out of total 1000,00 (100,00%)
600,10: [Host #6] MIPS for VM #3 by PEs (2 * 2660.0). PE #0: 1000,00.
600,10: [Host #6] Total allocated MIPS for VM #9 (Host #6) is 2500,00, was requested 2500,00 out of total 2500,00 (100,00%)
600,10: [Host #6] MIPS for VM #9 by PEs (2 * 2660.0). PE #0: 660,00. PE #1: 1840,00.
600,10: [Host #6] Total allocated MIPS for VM #4 (Host #6) is 1000,00, was requested 1000,00 out of total 1000,00 (100,00%)
600,10: [Host #6] MIPS for VM #4 by PEs (2 * 2660.0). PE #0: 1000,00.
600,10: [Host #6] utilization is 84,59%

600,10: [Host #7] utilization is 0,00%

600,10: [Host #8] utilization is 0,00%

600,10: [Host #9] utilization is 0,00%

Energy consumption for the last time frame from 340,10 to 600,10:

600,10: [Host #0] utilization at 340,10 was 84,59%, now is 84,59%
600,10: [Host #0] energy is 21796,99 W*sec

600,10: [Host #1] utilization at 340,10 was 0,00%, now is 0,00%
600,10: [Host #1] energy is 0,00 W*sec

600,10: [Host #2] utilization at 340,10 was 75,19%, now is 75,19%
600,10: [Host #2] energy is 20819,55 W*sec

600,10: [Host #3] utilization at 340,10 was 0,00%, now is 0,00%
600,10: [Host #3] energy is 0,00 W*sec

600,10: [Host #4] utilization at 340,10 was 0,00%, now is 0,00%
600,10: [Host #4] energy is 0,00 W*sec

600,10: [Host #5] utilization at 340,10 was 0,00%, now is 0,00%
600,10: [Host #5] energy is 0,00 W*sec

600,10: [Host #6] utilization at 340,10 was 84,59%, now is 84,59%
600,10: [Host #6] energy is 21796,99 W*sec

600,10: [Host #7] utilization at 340,10 was 0,00%, now is 0,00%
600,10: [Host #7] energy is 0,00 W*sec

600,10: [Host #8] utilization at 340,10 was 0,00%, now is 0,00%
600,10: [Host #8] energy is 0,00 W*sec

600,10: [Host #9] utilization at 340,10 was 0,00%, now is 0,00%
600,10: [Host #9] energy is 0,00 W*sec

600,10: Data center's energy is 64413,53 W*sec


Hamza: optimizeAllocation
Over-utilized hosts:
Host #0
Host #6

Reallocation of VMs from the over-utilized hosts:
VM #8 allocated to host #1
VM #4 allocated to host #1
[VmScheduler.vmCreate] Allocation of VM #8 to Host #2 failed by RAM
VM #8 allocated to host #2
VM #4 allocated to host #1
VM #8 allocated to host #3
VM #4 allocated to host #1
VM #8 allocated to host #4
VM #4 allocated to host #1
VM #8 allocated to host #5
VM #4 allocated to host #1
VM #8 allocated to host #7
VM #4 allocated to host #1
VM #8 allocated to host #8
VM #4 allocated to host #1
VM #8 allocated to host #9
VM #4 allocated to host #1
VM #8 allocated to host #1
[VmScheduler.vmCreate] Allocation of VM #4 to Host #2 failed by RAM
VM #4 allocated to host #2
[VmScheduler.vmCreate] Allocation of VM #8 to Host #2 failed by RAM
VM #8 allocated to host #2
[VmScheduler.vmCreate] Allocation of VM #4 to Host #2 failed by RAM
VM #4 allocated to host #2
VM #8 allocated to host #3
[VmScheduler.vmCreate] Allocation of VM #4 to Host #2 failed by RAM
VM #4 allocated to host #2
VM #8 allocated to host #4
[VmScheduler.vmCreate] Allocation of VM #4 to Host #2 failed by RAM
VM #4 allocated to host #2
VM #8 allocated to host #5
[VmScheduler.vmCreate] Allocation of VM #4 to Host #2 failed by RAM
VM #4 allocated to host #2
VM #8 allocated to host #7
[VmScheduler.vmCreate] Allocation of VM #4 to Host #2 failed by RAM
VM #4 allocated to host #2
VM #8 allocated to host #8
[VmScheduler.vmCreate] Allocation of VM #4 to Host #2 failed by RAM
VM #4 allocated to host #2
VM #8 allocated to host #9
[VmScheduler.vmCreate] Allocation of VM #4 to Host #2 failed by RAM
VM #4 allocated to host #2
VM #8 allocated to host #1
VM #4 allocated to host #3
[VmScheduler.vmCreate] Allocation of VM #8 to Host #2 failed by RAM
VM #8 allocated to host #2
VM #4 allocated to host #3
VM #8 allocated to host #3
VM #4 allocated to host #3
VM #8 allocated to host #4
VM #4 allocated to host #3
VM #8 allocated to host #5
VM #4 allocated to host #3
VM #8 allocated to host #7
VM #4 allocated to host #3
VM #8 allocated to host #8
VM #4 allocated to host #3
VM #8 allocated to host #9
VM #4 allocated to host #3
VM #8 allocated to host #1
VM #4 allocated to host #4
[VmScheduler.vmCreate] Allocation of VM #8 to Host #2 failed by RAM
VM #8 allocated to host #2
VM #4 allocated to host #4
VM #8 allocated to host #3
VM #4 allocated to host #4
VM #8 allocated to host #4
VM #4 allocated to host #4
VM #8 allocated to host #5
VM #4 allocated to host #4
VM #8 allocated to host #7
VM #4 allocated to host #4
VM #8 allocated to host #8
VM #4 allocated to host #4
VM #8 allocated to host #9
VM #4 allocated to host #4
VM #8 allocated to host #1
VM #4 allocated to host #5
[VmScheduler.vmCreate] Allocation of VM #8 to Host #2 failed by RAM
VM #8 allocated to host #2
VM #4 allocated to host #5
VM #8 allocated to host #3
VM #4 allocated to host #5
VM #8 allocated to host #4
VM #4 allocated to host #5
VM #8 allocated to host #5
VM #4 allocated to host #5
VM #8 allocated to host #7
VM #4 allocated to host #5
VM #8 allocated to host #8
VM #4 allocated to host #5
VM #8 allocated to host #9
VM #4 allocated to host #5
VM #8 allocated to host #1
VM #4 allocated to host #7
[VmScheduler.vmCreate] Allocation of VM #8 to Host #2 failed by RAM
VM #8 allocated to host #2
VM #4 allocated to host #7
VM #8 allocated to host #3
VM #4 allocated to host #7
VM #8 allocated to host #4
VM #4 allocated to host #7
VM #8 allocated to host #5
VM #4 allocated to host #7
VM #8 allocated to host #7
VM #4 allocated to host #7
VM #8 allocated to host #8
VM #4 allocated to host #7
VM #8 allocated to host #9
VM #4 allocated to host #7
VM #8 allocated to host #1
VM #4 allocated to host #8
[VmScheduler.vmCreate] Allocation of VM #8 to Host #2 failed by RAM
VM #8 allocated to host #2
VM #4 allocated to host #8
VM #8 allocated to host #3
VM #4 allocated to host #8
VM #8 allocated to host #4
VM #4 allocated to host #8
VM #8 allocated to host #5
VM #4 allocated to host #8
VM #8 allocated to host #7
VM #4 allocated to host #8
VM #8 allocated to host #8
VM #4 allocated to host #8
VM #8 allocated to host #9
VM #4 allocated to host #8
VM #8 allocated to host #1
VM #4 allocated to host #9
[VmScheduler.vmCreate] Allocation of VM #8 to Host #2 failed by RAM
VM #8 allocated to host #2
VM #4 allocated to host #9
VM #8 allocated to host #3
VM #4 allocated to host #9
VM #8 allocated to host #4
VM #4 allocated to host #9
VM #8 allocated to host #5
VM #4 allocated to host #9
VM #8 allocated to host #7
VM #4 allocated to host #9
VM #8 allocated to host #8
VM #4 allocated to host #9
VM #8 allocated to host #9
VM #4 allocated to host #9

Under-utilized host: host #2

Reallocation of VMs from the under-utilized host: 1 7 2 5 
Not all VMs can be reallocated from the host, reallocation cancelled

[MyStorageList.getDeviceContainsVm]: there is no device containing the vm 2-4
[MyStorageList.getDeviceContainsVm]: there is no device containing the vm 2-4
[MyStorageList.getDeviceContainsVm]: there is no device containing the vm 2-4
[MyStorageList.getDeviceContainsVm]: there is no device containing the vm 2-4
[MyStorageList.getDeviceContainsVm]: there is no device containing the vm 2-4
[MyStorageList.getDeviceContainsVm]: there is no device containing the vm 2-4
[MyStorageList.getDeviceContainsVm]: there is no device containing the vm 2-4
[MyStorageList.getDeviceContainsVm]: there is no device containing the vm 2-8
[MyStorageList.getDeviceContainsVm]: there is no device containing the vm 2-8
[MyStorageList.getDeviceContainsVm]: there is no device containing the vm 2-8
[MyStorageList.getDeviceContainsVm]: there is no device containing the vm 2-8
[MyStorageList.getDeviceContainsVm]: there is no device containing the vm 2-8
[MyStorageList.getDeviceContainsVm]: there is no device containing the vm 2-8
[MyStorageList.getDeviceContainsVm]: there is no device containing the vm 2-8
[MyStorageList.getDeviceContainsVm]: there is no device containing the vm 2-8
[MyStorageList.getDeviceContainsVm]: there is no device containing the vm 2-4
[MyStorageList.getDeviceContainsVm]: there is no device containing the vm 2-8
[MyStorageList.getDeviceContainsVm]: there is no device containing the vm 2-4
[MyStorageList.getDeviceContainsVm]: there is no device containing the vm 2-4
[MyStorageList.getDeviceContainsVm]: there is no device containing the vm 2-4
[MyStorageList.getDeviceContainsVm]: there is no device containing the vm 2-4
[MyStorageList.getDeviceContainsVm]: there is no device containing the vm 2-4
[MyStorageList.getDeviceContainsVm]: there is no device containing the vm 2-4
[MyStorageList.getDeviceContainsVm]: there is no device containing the vm 2-8
[MyStorageList.getDeviceContainsVm]: there is no device containing the vm 2-8
[MyStorageList.getDeviceContainsVm]: there is no device containing the vm 2-8
[MyStorageList.getDeviceContainsVm]: there is no device containing the vm 2-8
[MyStorageList.getDeviceContainsVm]: there is no device containing the vm 2-8
[MyStorageList.getDeviceContainsVm]: there is no device containing the vm 2-8
[MyStorageList.getDeviceContainsVm]: there is no device containing the vm 2-8
[MyStorageList.getDeviceContainsVm]: there is no device containing the vm 2-4
[MyStorageList.getDeviceContainsVm]: there is no device containing the vm 2-4
[MyStorageList.getDeviceContainsVm]: there is no device containing the vm 2-8
[MyStorageList.getDeviceContainsVm]: there is no device containing the vm 2-4
[MyStorageList.getDeviceContainsVm]: there is no device containing the vm 2-4
[MyStorageList.getDeviceContainsVm]: there is no device containing the vm 2-4
[MyStorageList.getDeviceContainsVm]: there is no device containing the vm 2-4
[MyStorageList.getDeviceContainsVm]: there is no device containing the vm 2-4
[MyStorageList.getDeviceContainsVm]: there is no device containing the vm 2-8
[MyStorageList.getDeviceContainsVm]: there is no device containing the vm 2-8
[MyStorageList.getDeviceContainsVm]: there is no device containing the vm 2-8
[MyStorageList.getDeviceContainsVm]: there is no device containing the vm 2-8
[MyStorageList.getDeviceContainsVm]: there is no device containing the vm 2-8
[MyStorageList.getDeviceContainsVm]: there is no device containing the vm 2-8
[MyStorageList.getDeviceContainsVm]: there is no device containing the vm 2-8
[MyStorageList.getDeviceContainsVm]: there is no device containing the vm 2-4
[MyStorageList.getDeviceContainsVm]: there is no device containing the vm 2-4
[MyStorageList.getDeviceContainsVm]: there is no device containing the vm 2-4
[MyStorageList.getDeviceContainsVm]: there is no device containing the vm 2-8
[MyStorageList.getDeviceContainsVm]: there is no device containing the vm 2-4
[MyStorageList.getDeviceContainsVm]: there is no device containing the vm 2-4
[MyStorageList.getDeviceContainsVm]: there is no device containing the vm 2-4
[MyStorageList.getDeviceContainsVm]: there is no device containing the vm 2-4
[MyStorageList.getDeviceContainsVm]: there is no device containing the vm 2-8
[MyStorageList.getDeviceContainsVm]: there is no device containing the vm 2-8
[MyStorageList.getDeviceContainsVm]: there is no device containing the vm 2-8
[MyStorageList.getDeviceContainsVm]: there is no device containing the vm 2-8
[MyStorageList.getDeviceContainsVm]: there is no device containing the vm 2-8
[MyStorageList.getDeviceContainsVm]: there is no device containing the vm 2-8
[MyStorageList.getDeviceContainsVm]: there is no device containing the vm 2-8
[MyStorageList.getDeviceContainsVm]: there is no device containing the vm 2-4
[MyStorageList.getDeviceContainsVm]: there is no device containing the vm 2-4
[MyStorageList.getDeviceContainsVm]: there is no device containing the vm 2-4
[MyStorageList.getDeviceContainsVm]: there is no device containing the vm 2-4
[MyStorageList.getDeviceContainsVm]: there is no device containing the vm 2-8
[MyStorageList.getDeviceContainsVm]: there is no device containing the vm 2-4
[MyStorageList.getDeviceContainsVm]: there is no device containing the vm 2-4
[MyStorageList.getDeviceContainsVm]: there is no device containing the vm 2-4
[MyStorageList.getDeviceContainsVm]: there is no device containing the vm 2-8
[MyStorageList.getDeviceContainsVm]: there is no device containing the vm 2-8
[MyStorageList.getDeviceContainsVm]: there is no device containing the vm 2-8
[MyStorageList.getDeviceContainsVm]: there is no device containing the vm 2-8
[MyStorageList.getDeviceContainsVm]: there is no device containing the vm 2-8
[MyStorageList.getDeviceContainsVm]: there is no device containing the vm 2-8
[MyStorageList.getDeviceContainsVm]: there is no device containing the vm 2-8
[MyStorageList.getDeviceContainsVm]: there is no device containing the vm 2-4
[MyStorageList.getDeviceContainsVm]: there is no device containing the vm 2-4
[MyStorageList.getDeviceContainsVm]: there is no device containing the vm 2-4
[MyStorageList.getDeviceContainsVm]: there is no device containing the vm 2-4
[MyStorageList.getDeviceContainsVm]: there is no device containing the vm 2-4
[MyStorageList.getDeviceContainsVm]: there is no device containing the vm 2-8
[MyStorageList.getDeviceContainsVm]: there is no device containing the vm 2-4
[MyStorageList.getDeviceContainsVm]: there is no device containing the vm 2-4
[MyStorageList.getDeviceContainsVm]: there is no device containing the vm 2-8
[MyStorageList.getDeviceContainsVm]: there is no device containing the vm 2-8
[MyStorageList.getDeviceContainsVm]: there is no device containing the vm 2-8
[MyStorageList.getDeviceContainsVm]: there is no device containing the vm 2-8
[MyStorageList.getDeviceContainsVm]: there is no device containing the vm 2-8
[MyStorageList.getDeviceContainsVm]: there is no device containing the vm 2-8
[MyStorageList.getDeviceContainsVm]: there is no device containing the vm 2-8
[MyStorageList.getDeviceContainsVm]: there is no device containing the vm 2-4
[MyStorageList.getDeviceContainsVm]: there is no device containing the vm 2-4
[MyStorageList.getDeviceContainsVm]: there is no device containing the vm 2-4
[MyStorageList.getDeviceContainsVm]: there is no device containing the vm 2-4
[MyStorageList.getDeviceContainsVm]: there is no device containing the vm 2-4
[MyStorageList.getDeviceContainsVm]: there is no device containing the vm 2-4
[MyStorageList.getDeviceContainsVm]: there is no device containing the vm 2-8
[MyStorageList.getDeviceContainsVm]: there is no device containing the vm 2-4
600.1: Broker: Cloudlet 6 received


--------------------------------------------------------------


New resource usage for the time frame starting at 900,10:

900,10: [Host #0] IO processing of VM #0 elapsed time is 2,86415 s
900,10: [Host #0] IO processing of VM #6 elapsed time is 0,37547 s
900,10: [Host #0] IO processing of VM #8 elapsed time is 0,37547 s
900,10: [Host #0] Total allocated MIPS for VM #0 (Host #0) is 500,00, was requested 500,00 out of total 500,00 (100,00%)
900,10: [Host #0] MIPS for VM #0 by PEs (2 * 2660.0). PE #0: 500,00.
900,10: [Host #0] Total allocated MIPS for VM #6 (Host #0) is 2000,00, was requested 2000,00 out of total 2000,00 (100,00%)
900,10: [Host #0] MIPS for VM #6 by PEs (2 * 2660.0). PE #0: 2000,00.
900,10: [Host #0] Total allocated MIPS for VM #8 (Host #0) is 2000,00, was requested 2000,00 out of total 2000,00 (100,00%)
900,10: [Host #0] MIPS for VM #8 by PEs (2 * 2660.0). PE #0: 160,00. PE #1: 1840,00.
900,10: [Host #0] utilization is 84,59%

900,10: [Host #1] utilization is 0,00%

900,10: [Host #2] IO processing of VM #1 elapsed time is 2,86415 s
900,10: [Host #2] IO processing of VM #7 elapsed time is 0,37547 s
900,10: [Host #2] IO processing of VM #2 elapsed time is 2,86415 s
900,10: [Host #2] IO processing of VM #5 elapsed time is 1,74717 s
900,10: [Host #2] Total allocated MIPS for VM #1 (Host #2) is 500,00, was requested 500,00 out of total 500,00 (100,00%)
900,10: [Host #2] MIPS for VM #1 by PEs (2 * 2660.0). PE #0: 500,00.
900,10: [Host #2] Total allocated MIPS for VM #7 (Host #2) is 2000,00, was requested 2000,00 out of total 2000,00 (100,00%)
900,10: [Host #2] MIPS for VM #7 by PEs (2 * 2660.0). PE #0: 660,00. PE #1: 1340,00.
900,10: [Host #2] Total allocated MIPS for VM #2 (Host #2) is 500,00, was requested 500,00 out of total 500,00 (100,00%)
900,10: [Host #2] MIPS for VM #2 by PEs (2 * 2660.0). PE #0: 500,00.
900,10: [Host #2] Total allocated MIPS for VM #5 (Host #2) is 1000,00, was requested 1000,00 out of total 1000,00 (100,00%)
900,10: [Host #2] MIPS for VM #5 by PEs (2 * 2660.0). PE #0: 1000,00.
900,10: [Host #2] utilization is 75,19%

900,10: [Host #3] utilization is 0,00%

900,10: [Host #4] utilization is 0,00%

900,10: [Host #5] utilization is 0,00%

900,10: [Host #6] IO processing of VM #3 elapsed time is 1,74717 s
900,10: [Host #6] IO processing of VM #9 elapsed time is 1,75472 s
900,10: [Host #6] IO processing of VM #4 elapsed time is 1,74717 s
900,10: [Host #6] Total allocated MIPS for VM #3 (Host #6) is 1000,00, was requested 1000,00 out of total 1000,00 (100,00%)
900,10: [Host #6] MIPS for VM #3 by PEs (2 * 2660.0). PE #0: 1000,00.
900,10: [Host #6] Total allocated MIPS for VM #9 (Host #6) is 2500,00, was requested 2500,00 out of total 2500,00 (100,00%)
900,10: [Host #6] MIPS for VM #9 by PEs (2 * 2660.0). PE #0: 660,00. PE #1: 1840,00.
900,10: [Host #6] Total allocated MIPS for VM #4 (Host #6) is 1000,00, was requested 1000,00 out of total 1000,00 (100,00%)
900,10: [Host #6] MIPS for VM #4 by PEs (2 * 2660.0). PE #0: 1000,00.
900,10: [Host #6] utilization is 84,59%

900,10: [Host #7] utilization is 0,00%

900,10: [Host #8] utilization is 0,00%

900,10: [Host #9] utilization is 0,00%

Energy consumption for the last time frame from 600,10 to 900,10:

900,10: [Host #0] utilization at 600,10 was 84,59%, now is 84,59%
900,10: [Host #0] energy is 25150,38 W*sec

900,10: [Host #1] utilization at 600,10 was 0,00%, now is 0,00%
900,10: [Host #1] energy is 0,00 W*sec

900,10: [Host #2] utilization at 600,10 was 75,19%, now is 75,19%
900,10: [Host #2] energy is 24022,56 W*sec

900,10: [Host #3] utilization at 600,10 was 0,00%, now is 0,00%
900,10: [Host #3] energy is 0,00 W*sec

900,10: [Host #4] utilization at 600,10 was 0,00%, now is 0,00%
900,10: [Host #4] energy is 0,00 W*sec

900,10: [Host #5] utilization at 600,10 was 0,00%, now is 0,00%
900,10: [Host #5] energy is 0,00 W*sec

900,10: [Host #6] utilization at 600,10 was 84,59%, now is 84,59%
900,10: [Host #6] energy is 25150,38 W*sec

900,10: [Host #7] utilization at 600,10 was 0,00%, now is 0,00%
900,10: [Host #7] energy is 0,00 W*sec

900,10: [Host #8] utilization at 600,10 was 0,00%, now is 0,00%
900,10: [Host #8] energy is 0,00 W*sec

900,10: [Host #9] utilization at 600,10 was 0,00%, now is 0,00%
900,10: [Host #9] energy is 0,00 W*sec

900,10: Data center's energy is 74323,31 W*sec


Hamza: optimizeAllocation
Over-utilized hosts:
Host #0
Host #6

Reallocation of VMs from the over-utilized hosts:
VM #0 allocated to host #1
VM #9 allocated to host #1
[VmScheduler.vmCreate] Allocation of VM #0 to Host #2 failed by RAM
VM #0 allocated to host #2
VM #9 allocated to host #1
VM #0 allocated to host #3
VM #9 allocated to host #1
VM #0 allocated to host #4
VM #9 allocated to host #1
VM #0 allocated to host #5
VM #9 allocated to host #1
VM #0 allocated to host #7
VM #9 allocated to host #1
VM #0 allocated to host #8
VM #9 allocated to host #1
VM #0 allocated to host #9
VM #9 allocated to host #1
VM #0 allocated to host #1
[VmScheduler.vmCreate] Allocation of VM #9 to Host #2 failed by RAM
VM #9 allocated to host #2
[VmScheduler.vmCreate] Allocation of VM #0 to Host #2 failed by RAM
VM #0 allocated to host #2
[VmScheduler.vmCreate] Allocation of VM #9 to Host #2 failed by RAM
VM #9 allocated to host #2
VM #0 allocated to host #3
[VmScheduler.vmCreate] Allocation of VM #9 to Host #2 failed by RAM
VM #9 allocated to host #2
VM #0 allocated to host #4
[VmScheduler.vmCreate] Allocation of VM #9 to Host #2 failed by RAM
VM #9 allocated to host #2
VM #0 allocated to host #5
[VmScheduler.vmCreate] Allocation of VM #9 to Host #2 failed by RAM
VM #9 allocated to host #2
VM #0 allocated to host #7
[VmScheduler.vmCreate] Allocation of VM #9 to Host #2 failed by RAM
VM #9 allocated to host #2
VM #0 allocated to host #8
[VmScheduler.vmCreate] Allocation of VM #9 to Host #2 failed by RAM
VM #9 allocated to host #2
VM #0 allocated to host #9
[VmScheduler.vmCreate] Allocation of VM #9 to Host #2 failed by RAM
VM #9 allocated to host #2
VM #0 allocated to host #1
VM #9 allocated to host #3
[VmScheduler.vmCreate] Allocation of VM #0 to Host #2 failed by RAM
VM #0 allocated to host #2
VM #9 allocated to host #3
VM #0 allocated to host #3
VM #9 allocated to host #3
VM #0 allocated to host #4
VM #9 allocated to host #3
VM #0 allocated to host #5
VM #9 allocated to host #3
VM #0 allocated to host #7
VM #9 allocated to host #3
VM #0 allocated to host #8
VM #9 allocated to host #3
VM #0 allocated to host #9
VM #9 allocated to host #3
VM #0 allocated to host #1
VM #9 allocated to host #4
[VmScheduler.vmCreate] Allocation of VM #0 to Host #2 failed by RAM
VM #0 allocated to host #2
VM #9 allocated to host #4
VM #0 allocated to host #3
VM #9 allocated to host #4
VM #0 allocated to host #4
VM #9 allocated to host #4
VM #0 allocated to host #5
VM #9 allocated to host #4
VM #0 allocated to host #7
VM #9 allocated to host #4
VM #0 allocated to host #8
VM #9 allocated to host #4
VM #0 allocated to host #9
VM #9 allocated to host #4
VM #0 allocated to host #1
VM #9 allocated to host #5
[VmScheduler.vmCreate] Allocation of VM #0 to Host #2 failed by RAM
VM #0 allocated to host #2
VM #9 allocated to host #5
VM #0 allocated to host #3
VM #9 allocated to host #5
VM #0 allocated to host #4
VM #9 allocated to host #5
VM #0 allocated to host #5
VM #9 allocated to host #5
VM #0 allocated to host #7
VM #9 allocated to host #5
VM #0 allocated to host #8
VM #9 allocated to host #5
VM #0 allocated to host #9
VM #9 allocated to host #5
VM #0 allocated to host #1
VM #9 allocated to host #7
[VmScheduler.vmCreate] Allocation of VM #0 to Host #2 failed by RAM
VM #0 allocated to host #2
VM #9 allocated to host #7
VM #0 allocated to host #3
VM #9 allocated to host #7
VM #0 allocated to host #4
VM #9 allocated to host #7
VM #0 allocated to host #5
VM #9 allocated to host #7
VM #0 allocated to host #7
VM #9 allocated to host #7
VM #0 allocated to host #8
VM #9 allocated to host #7
VM #0 allocated to host #9
VM #9 allocated to host #7
VM #0 allocated to host #1
VM #9 allocated to host #8
[VmScheduler.vmCreate] Allocation of VM #0 to Host #2 failed by RAM
VM #0 allocated to host #2
VM #9 allocated to host #8
VM #0 allocated to host #3
VM #9 allocated to host #8
VM #0 allocated to host #4
VM #9 allocated to host #8
VM #0 allocated to host #5
VM #9 allocated to host #8
VM #0 allocated to host #7
VM #9 allocated to host #8
VM #0 allocated to host #8
VM #9 allocated to host #8
VM #0 allocated to host #9
VM #9 allocated to host #8
VM #0 allocated to host #1
VM #9 allocated to host #9
[VmScheduler.vmCreate] Allocation of VM #0 to Host #2 failed by RAM
VM #0 allocated to host #2
VM #9 allocated to host #9
VM #0 allocated to host #3
VM #9 allocated to host #9
VM #0 allocated to host #4
VM #9 allocated to host #9
VM #0 allocated to host #5
VM #9 allocated to host #9
VM #0 allocated to host #7
VM #9 allocated to host #9
VM #0 allocated to host #8
VM #9 allocated to host #9
VM #0 allocated to host #9
VM #9 allocated to host #9

Under-utilized host: host #2

Reallocation of VMs from the under-utilized host: 1 7 2 5 
Not all VMs can be reallocated from the host, reallocation cancelled

[MyStorageList.getDeviceContainsVm]: there is no device containing the vm 2-9
[MyStorageList.getDeviceContainsVm]: there is no device containing the vm 2-9
[MyStorageList.getDeviceContainsVm]: there is no device containing the vm 2-9
[MyStorageList.getDeviceContainsVm]: there is no device containing the vm 2-9
[MyStorageList.getDeviceContainsVm]: there is no device containing the vm 2-9
[MyStorageList.getDeviceContainsVm]: there is no device containing the vm 2-9
[MyStorageList.getDeviceContainsVm]: there is no device containing the vm 2-9
[MyStorageList.getDeviceContainsVm]: there is no device containing the vm 2-0
[MyStorageList.getDeviceContainsVm]: there is no device containing the vm 2-0
[MyStorageList.getDeviceContainsVm]: there is no device containing the vm 2-0
[MyStorageList.getDeviceContainsVm]: there is no device containing the vm 2-0
[MyStorageList.getDeviceContainsVm]: there is no device containing the vm 2-0
[MyStorageList.getDeviceContainsVm]: there is no device containing the vm 2-0
[MyStorageList.getDeviceContainsVm]: there is no device containing the vm 2-0
[MyStorageList.getDeviceContainsVm]: there is no device containing the vm 2-0
[MyStorageList.getDeviceContainsVm]: there is no device containing the vm 2-9
[MyStorageList.getDeviceContainsVm]: there is no device containing the vm 2-0
[MyStorageList.getDeviceContainsVm]: there is no device containing the vm 2-9
[MyStorageList.getDeviceContainsVm]: there is no device containing the vm 2-9
[MyStorageList.getDeviceContainsVm]: there is no device containing the vm 2-9
[MyStorageList.getDeviceContainsVm]: there is no device containing the vm 2-9
[MyStorageList.getDeviceContainsVm]: there is no device containing the vm 2-9
[MyStorageList.getDeviceContainsVm]: there is no device containing the vm 2-9
[MyStorageList.getDeviceContainsVm]: there is no device containing the vm 2-0
[MyStorageList.getDeviceContainsVm]: there is no device containing the vm 2-0
[MyStorageList.getDeviceContainsVm]: there is no device containing the vm 2-0
[MyStorageList.getDeviceContainsVm]: there is no device containing the vm 2-0
[MyStorageList.getDeviceContainsVm]: there is no device containing the vm 2-0
[MyStorageList.getDeviceContainsVm]: there is no device containing the vm 2-0
[MyStorageList.getDeviceContainsVm]: there is no device containing the vm 2-0
[MyStorageList.getDeviceContainsVm]: there is no device containing the vm 2-9
[MyStorageList.getDeviceContainsVm]: there is no device containing the vm 2-9
[MyStorageList.getDeviceContainsVm]: there is no device containing the vm 2-0
[MyStorageList.getDeviceContainsVm]: there is no device containing the vm 2-9
[MyStorageList.getDeviceContainsVm]: there is no device containing the vm 2-9
[MyStorageList.getDeviceContainsVm]: there is no device containing the vm 2-9
[MyStorageList.getDeviceContainsVm]: there is no device containing the vm 2-9
[MyStorageList.getDeviceContainsVm]: there is no device containing the vm 2-9
[MyStorageList.getDeviceContainsVm]: there is no device containing the vm 2-0
[MyStorageList.getDeviceContainsVm]: there is no device containing the vm 2-0
[MyStorageList.getDeviceContainsVm]: there is no device containing the vm 2-0
[MyStorageList.getDeviceContainsVm]: there is no device containing the vm 2-0
[MyStorageList.getDeviceContainsVm]: there is no device containing the vm 2-0
[MyStorageList.getDeviceContainsVm]: there is no device containing the vm 2-0
[MyStorageList.getDeviceContainsVm]: there is no device containing the vm 2-0
[MyStorageList.getDeviceContainsVm]: there is no device containing the vm 2-9
[MyStorageList.getDeviceContainsVm]: there is no device containing the vm 2-9
[MyStorageList.getDeviceContainsVm]: there is no device containing the vm 2-9
[MyStorageList.getDeviceContainsVm]: there is no device containing the vm 2-0
[MyStorageList.getDeviceContainsVm]: there is no device containing the vm 2-9
[MyStorageList.getDeviceContainsVm]: there is no device containing the vm 2-9
[MyStorageList.getDeviceContainsVm]: there is no device containing the vm 2-9
[MyStorageList.getDeviceContainsVm]: there is no device containing the vm 2-9
[MyStorageList.getDeviceContainsVm]: there is no device containing the vm 2-0
[MyStorageList.getDeviceContainsVm]: there is no device containing the vm 2-0
[MyStorageList.getDeviceContainsVm]: there is no device containing the vm 2-0
[MyStorageList.getDeviceContainsVm]: there is no device containing the vm 2-0
[MyStorageList.getDeviceContainsVm]: there is no device containing the vm 2-0
[MyStorageList.getDeviceContainsVm]: there is no device containing the vm 2-0
[MyStorageList.getDeviceContainsVm]: there is no device containing the vm 2-0
[MyStorageList.getDeviceContainsVm]: there is no device containing the vm 2-9
[MyStorageList.getDeviceContainsVm]: there is no device containing the vm 2-9
[MyStorageList.getDeviceContainsVm]: there is no device containing the vm 2-9
[MyStorageList.getDeviceContainsVm]: there is no device containing the vm 2-9
[MyStorageList.getDeviceContainsVm]: there is no device containing the vm 2-0
[MyStorageList.getDeviceContainsVm]: there is no device containing the vm 2-9
[MyStorageList.getDeviceContainsVm]: there is no device containing the vm 2-9
[MyStorageList.getDeviceContainsVm]: there is no device containing the vm 2-9
[MyStorageList.getDeviceContainsVm]: there is no device containing the vm 2-0
[MyStorageList.getDeviceContainsVm]: there is no device containing the vm 2-0
[MyStorageList.getDeviceContainsVm]: there is no device containing the vm 2-0
[MyStorageList.getDeviceContainsVm]: there is no device containing the vm 2-0
[MyStorageList.getDeviceContainsVm]: there is no device containing the vm 2-0
[MyStorageList.getDeviceContainsVm]: there is no device containing the vm 2-0
[MyStorageList.getDeviceContainsVm]: there is no device containing the vm 2-0
[MyStorageList.getDeviceContainsVm]: there is no device containing the vm 2-9
[MyStorageList.getDeviceContainsVm]: there is no device containing the vm 2-9
[MyStorageList.getDeviceContainsVm]: there is no device containing the vm 2-9
[MyStorageList.getDeviceContainsVm]: there is no device containing the vm 2-9
[MyStorageList.getDeviceContainsVm]: there is no device containing the vm 2-9
[MyStorageList.getDeviceContainsVm]: there is no device containing the vm 2-0
[MyStorageList.getDeviceContainsVm]: there is no device containing the vm 2-9
[MyStorageList.getDeviceContainsVm]: there is no device containing the vm 2-9
[MyStorageList.getDeviceContainsVm]: there is no device containing the vm 2-0
[MyStorageList.getDeviceContainsVm]: there is no device containing the vm 2-0
[MyStorageList.getDeviceContainsVm]: there is no device containing the vm 2-0
[MyStorageList.getDeviceContainsVm]: there is no device containing the vm 2-0
[MyStorageList.getDeviceContainsVm]: there is no device containing the vm 2-0
[MyStorageList.getDeviceContainsVm]: there is no device containing the vm 2-0
[MyStorageList.getDeviceContainsVm]: there is no device containing the vm 2-0
[MyStorageList.getDeviceContainsVm]: there is no device containing the vm 2-9
[MyStorageList.getDeviceContainsVm]: there is no device containing the vm 2-9
[MyStorageList.getDeviceContainsVm]: there is no device containing the vm 2-9
[MyStorageList.getDeviceContainsVm]: there is no device containing the vm 2-9
[MyStorageList.getDeviceContainsVm]: there is no device containing the vm 2-9
[MyStorageList.getDeviceContainsVm]: there is no device containing the vm 2-9
[MyStorageList.getDeviceContainsVm]: there is no device containing the vm 2-0
[MyStorageList.getDeviceContainsVm]: there is no device containing the vm 2-9
900.1: Broker: Cloudlet 5 received
900.1: Broker: Cloudlet 3 received


--------------------------------------------------------------


New resource usage for the time frame starting at 1200,10:

1200,10: [Host #0] IO processing of VM #0 elapsed time is 1,60189 s
1200,10: [Host #0] IO processing of VM #6 elapsed time is 2,98868 s
1200,10: [Host #0] IO processing of VM #8 elapsed time is 2,98868 s
1200,10: [Host #0] Total allocated MIPS for VM #0 (Host #0) is 500,00, was requested 500,00 out of total 500,00 (100,00%)
1200,10: [Host #0] MIPS for VM #0 by PEs (2 * 2660.0). PE #0: 500,00.
1200,10: [Host #0] Total allocated MIPS for VM #6 (Host #0) is 2000,00, was requested 2000,00 out of total 2000,00 (100,00%)
1200,10: [Host #0] MIPS for VM #6 by PEs (2 * 2660.0). PE #0: 2000,00.
1200,10: [Host #0] Total allocated MIPS for VM #8 (Host #0) is 2000,00, was requested 2000,00 out of total 2000,00 (100,00%)
1200,10: [Host #0] MIPS for VM #8 by PEs (2 * 2660.0). PE #0: 160,00. PE #1: 1840,00.
1200,10: [Host #0] utilization is 84,59%

1200,10: [Host #1] utilization is 0,00%

1200,10: [Host #2] IO processing of VM #1 elapsed time is 1,60189 s
1200,10: [Host #2] IO processing of VM #7 elapsed time is 2,98868 s
1200,10: [Host #2] IO processing of VM #2 elapsed time is 1,60189 s
1200,10: [Host #2] IO processing of VM #5 elapsed time is 0,25849 s
1200,10: [Host #2] Total allocated MIPS for VM #1 (Host #2) is 500,00, was requested 500,00 out of total 500,00 (100,00%)
1200,10: [Host #2] MIPS for VM #1 by PEs (2 * 2660.0). PE #0: 500,00.
1200,10: [Host #2] Total allocated MIPS for VM #7 (Host #2) is 2000,00, was requested 2000,00 out of total 2000,00 (100,00%)
1200,10: [Host #2] MIPS for VM #7 by PEs (2 * 2660.0). PE #0: 660,00. PE #1: 1340,00.
1200,10: [Host #2] Total allocated MIPS for VM #2 (Host #2) is 500,00, was requested 500,00 out of total 500,00 (100,00%)
1200,10: [Host #2] MIPS for VM #2 by PEs (2 * 2660.0). PE #0: 500,00.
1200,10: [Host #2] Total allocated MIPS for VM #5 (Host #2) is 1000,00, was requested 1000,00 out of total 1000,00 (100,00%)
1200,10: [Host #2] MIPS for VM #5 by PEs (2 * 2660.0). PE #0: 1000,00.
1200,10: [Host #2] utilization is 75,19%

1200,10: [Host #3] utilization is 0,00%

1200,10: [Host #4] utilization is 0,00%

1200,10: [Host #5] utilization is 0,00%

1200,10: [Host #6] IO processing of VM #3 elapsed time is 0,25849 s
1200,10: [Host #6] IO processing of VM #9 elapsed time is 0,52453 s
1200,10: [Host #6] IO processing of VM #4 elapsed time is 0,25849 s
1200,10: [Host #6] Total allocated MIPS for VM #3 (Host #6) is 1000,00, was requested 1000,00 out of total 1000,00 (100,00%)
1200,10: [Host #6] MIPS for VM #3 by PEs (2 * 2660.0). PE #0: 1000,00.
1200,10: [Host #6] Total allocated MIPS for VM #9 (Host #6) is 2500,00, was requested 2500,00 out of total 2500,00 (100,00%)
1200,10: [Host #6] MIPS for VM #9 by PEs (2 * 2660.0). PE #0: 660,00. PE #1: 1840,00.
1200,10: [Host #6] Total allocated MIPS for VM #4 (Host #6) is 1000,00, was requested 1000,00 out of total 1000,00 (100,00%)
1200,10: [Host #6] MIPS for VM #4 by PEs (2 * 2660.0). PE #0: 1000,00.
1200,10: [Host #6] utilization is 84,59%

1200,10: [Host #7] utilization is 0,00%

1200,10: [Host #8] utilization is 0,00%

1200,10: [Host #9] utilization is 0,00%

Energy consumption for the last time frame from 900,10 to 1200,10:

1200,10: [Host #0] utilization at 900,10 was 84,59%, now is 84,59%
1200,10: [Host #0] energy is 25150,38 W*sec

1200,10: [Host #1] utilization at 900,10 was 0,00%, now is 0,00%
1200,10: [Host #1] energy is 0,00 W*sec

1200,10: [Host #2] utilization at 900,10 was 75,19%, now is 75,19%
1200,10: [Host #2] energy is 24022,56 W*sec

1200,10: [Host #3] utilization at 900,10 was 0,00%, now is 0,00%
1200,10: [Host #3] energy is 0,00 W*sec

1200,10: [Host #4] utilization at 900,10 was 0,00%, now is 0,00%
1200,10: [Host #4] energy is 0,00 W*sec

1200,10: [Host #5] utilization at 900,10 was 0,00%, now is 0,00%
1200,10: [Host #5] energy is 0,00 W*sec

1200,10: [Host #6] utilization at 900,10 was 84,59%, now is 84,59%
1200,10: [Host #6] energy is 25150,38 W*sec

1200,10: [Host #7] utilization at 900,10 was 0,00%, now is 0,00%
1200,10: [Host #7] energy is 0,00 W*sec

1200,10: [Host #8] utilization at 900,10 was 0,00%, now is 0,00%
1200,10: [Host #8] energy is 0,00 W*sec

1200,10: [Host #9] utilization at 900,10 was 0,00%, now is 0,00%
1200,10: [Host #9] energy is 0,00 W*sec

1200,10: Data center's energy is 74323,31 W*sec


Hamza: optimizeAllocation
Over-utilized hosts:
Host #0
Host #6

Reallocation of VMs from the over-utilized hosts:
VM #6 allocated to host #1
VM #3 allocated to host #1
[VmScheduler.vmCreate] Allocation of VM #6 to Host #2 failed by RAM
VM #6 allocated to host #2
VM #3 allocated to host #1
VM #6 allocated to host #3
VM #3 allocated to host #1
VM #6 allocated to host #4
VM #3 allocated to host #1
VM #6 allocated to host #5
VM #3 allocated to host #1
VM #6 allocated to host #7
VM #3 allocated to host #1
VM #6 allocated to host #8
VM #3 allocated to host #1
VM #6 allocated to host #9
VM #3 allocated to host #1
VM #6 allocated to host #1
[VmScheduler.vmCreate] Allocation of VM #3 to Host #2 failed by RAM
VM #3 allocated to host #2
[VmScheduler.vmCreate] Allocation of VM #6 to Host #2 failed by RAM
VM #6 allocated to host #2
[VmScheduler.vmCreate] Allocation of VM #3 to Host #2 failed by RAM
VM #3 allocated to host #2
VM #6 allocated to host #3
[VmScheduler.vmCreate] Allocation of VM #3 to Host #2 failed by RAM
VM #3 allocated to host #2
VM #6 allocated to host #4
[VmScheduler.vmCreate] Allocation of VM #3 to Host #2 failed by RAM
VM #3 allocated to host #2
VM #6 allocated to host #5
[VmScheduler.vmCreate] Allocation of VM #3 to Host #2 failed by RAM
VM #3 allocated to host #2
VM #6 allocated to host #7
[VmScheduler.vmCreate] Allocation of VM #3 to Host #2 failed by RAM
VM #3 allocated to host #2
VM #6 allocated to host #8
[VmScheduler.vmCreate] Allocation of VM #3 to Host #2 failed by RAM
VM #3 allocated to host #2
VM #6 allocated to host #9
[VmScheduler.vmCreate] Allocation of VM #3 to Host #2 failed by RAM
VM #3 allocated to host #2
VM #6 allocated to host #1
VM #3 allocated to host #3
[VmScheduler.vmCreate] Allocation of VM #6 to Host #2 failed by RAM
VM #6 allocated to host #2
VM #3 allocated to host #3
VM #6 allocated to host #3
VM #3 allocated to host #3
VM #6 allocated to host #4
VM #3 allocated to host #3
VM #6 allocated to host #5
VM #3 allocated to host #3
VM #6 allocated to host #7
VM #3 allocated to host #3
VM #6 allocated to host #8
VM #3 allocated to host #3
VM #6 allocated to host #9
VM #3 allocated to host #3
VM #6 allocated to host #1
VM #3 allocated to host #4
[VmScheduler.vmCreate] Allocation of VM #6 to Host #2 failed by RAM
VM #6 allocated to host #2
VM #3 allocated to host #4
VM #6 allocated to host #3
VM #3 allocated to host #4
VM #6 allocated to host #4
VM #3 allocated to host #4
VM #6 allocated to host #5
VM #3 allocated to host #4
VM #6 allocated to host #7
VM #3 allocated to host #4
VM #6 allocated to host #8
VM #3 allocated to host #4
VM #6 allocated to host #9
VM #3 allocated to host #4
VM #6 allocated to host #1
VM #3 allocated to host #5
[VmScheduler.vmCreate] Allocation of VM #6 to Host #2 failed by RAM
VM #6 allocated to host #2
VM #3 allocated to host #5
VM #6 allocated to host #3
VM #3 allocated to host #5
VM #6 allocated to host #4
VM #3 allocated to host #5
VM #6 allocated to host #5
VM #3 allocated to host #5
VM #6 allocated to host #7
VM #3 allocated to host #5
VM #6 allocated to host #8
VM #3 allocated to host #5
VM #6 allocated to host #9
VM #3 allocated to host #5
VM #6 allocated to host #1
VM #3 allocated to host #7
[VmScheduler.vmCreate] Allocation of VM #6 to Host #2 failed by RAM
VM #6 allocated to host #2
VM #3 allocated to host #7
VM #6 allocated to host #3
VM #3 allocated to host #7
VM #6 allocated to host #4
VM #3 allocated to host #7
VM #6 allocated to host #5
VM #3 allocated to host #7
VM #6 allocated to host #7
VM #3 allocated to host #7
VM #6 allocated to host #8
VM #3 allocated to host #7
VM #6 allocated to host #9
VM #3 allocated to host #7
VM #6 allocated to host #1
VM #3 allocated to host #8
[VmScheduler.vmCreate] Allocation of VM #6 to Host #2 failed by RAM
VM #6 allocated to host #2
VM #3 allocated to host #8
VM #6 allocated to host #3
VM #3 allocated to host #8
VM #6 allocated to host #4
VM #3 allocated to host #8
VM #6 allocated to host #5
VM #3 allocated to host #8
VM #6 allocated to host #7
VM #3 allocated to host #8
VM #6 allocated to host #8
VM #3 allocated to host #8
VM #6 allocated to host #9
VM #3 allocated to host #8
VM #6 allocated to host #1
VM #3 allocated to host #9
[VmScheduler.vmCreate] Allocation of VM #6 to Host #2 failed by RAM
VM #6 allocated to host #2
VM #3 allocated to host #9
VM #6 allocated to host #3
VM #3 allocated to host #9
VM #6 allocated to host #4
VM #3 allocated to host #9
VM #6 allocated to host #5
VM #3 allocated to host #9
VM #6 allocated to host #7
VM #3 allocated to host #9
VM #6 allocated to host #8
VM #3 allocated to host #9
VM #6 allocated to host #9
VM #3 allocated to host #9

Under-utilized host: host #2

Reallocation of VMs from the under-utilized host: 1 7 2 5 
Not all VMs can be reallocated from the host, reallocation cancelled

[MyStorageList.getDeviceContainsVm]: there is no device containing the vm 2-3
[MyStorageList.getDeviceContainsVm]: there is no device containing the vm 2-3
[MyStorageList.getDeviceContainsVm]: there is no device containing the vm 2-3
[MyStorageList.getDeviceContainsVm]: there is no device containing the vm 2-3
[MyStorageList.getDeviceContainsVm]: there is no device containing the vm 2-3
[MyStorageList.getDeviceContainsVm]: there is no device containing the vm 2-3
[MyStorageList.getDeviceContainsVm]: there is no device containing the vm 2-3
[MyStorageList.getDeviceContainsVm]: there is no device containing the vm 2-6
[MyStorageList.getDeviceContainsVm]: there is no device containing the vm 2-6
[MyStorageList.getDeviceContainsVm]: there is no device containing the vm 2-6
[MyStorageList.getDeviceContainsVm]: there is no device containing the vm 2-6
[MyStorageList.getDeviceContainsVm]: there is no device containing the vm 2-6
[MyStorageList.getDeviceContainsVm]: there is no device containing the vm 2-6
[MyStorageList.getDeviceContainsVm]: there is no device containing the vm 2-6
[MyStorageList.getDeviceContainsVm]: there is no device containing the vm 2-6
[MyStorageList.getDeviceContainsVm]: there is no device containing the vm 2-3
[MyStorageList.getDeviceContainsVm]: there is no device containing the vm 2-6
[MyStorageList.getDeviceContainsVm]: there is no device containing the vm 2-3
[MyStorageList.getDeviceContainsVm]: there is no device containing the vm 2-3
[MyStorageList.getDeviceContainsVm]: there is no device containing the vm 2-3
[MyStorageList.getDeviceContainsVm]: there is no device containing the vm 2-3
[MyStorageList.getDeviceContainsVm]: there is no device containing the vm 2-3
[MyStorageList.getDeviceContainsVm]: there is no device containing the vm 2-3
[MyStorageList.getDeviceContainsVm]: there is no device containing the vm 2-6
[MyStorageList.getDeviceContainsVm]: there is no device containing the vm 2-6
[MyStorageList.getDeviceContainsVm]: there is no device containing the vm 2-6
[MyStorageList.getDeviceContainsVm]: there is no device containing the vm 2-6
[MyStorageList.getDeviceContainsVm]: there is no device containing the vm 2-6
[MyStorageList.getDeviceContainsVm]: there is no device containing the vm 2-6
[MyStorageList.getDeviceContainsVm]: there is no device containing the vm 2-6
[MyStorageList.getDeviceContainsVm]: there is no device containing the vm 2-3
[MyStorageList.getDeviceContainsVm]: there is no device containing the vm 2-3
[MyStorageList.getDeviceContainsVm]: there is no device containing the vm 2-6
[MyStorageList.getDeviceContainsVm]: there is no device containing the vm 2-3
[MyStorageList.getDeviceContainsVm]: there is no device containing the vm 2-3
[MyStorageList.getDeviceContainsVm]: there is no device containing the vm 2-3
[MyStorageList.getDeviceContainsVm]: there is no device containing the vm 2-3
[MyStorageList.getDeviceContainsVm]: there is no device containing the vm 2-3
[MyStorageList.getDeviceContainsVm]: there is no device containing the vm 2-6
[MyStorageList.getDeviceContainsVm]: there is no device containing the vm 2-6
[MyStorageList.getDeviceContainsVm]: there is no device containing the vm 2-6
[MyStorageList.getDeviceContainsVm]: there is no device containing the vm 2-6
[MyStorageList.getDeviceContainsVm]: there is no device containing the vm 2-6
[MyStorageList.getDeviceContainsVm]: there is no device containing the vm 2-6
[MyStorageList.getDeviceContainsVm]: there is no device containing the vm 2-6
[MyStorageList.getDeviceContainsVm]: there is no device containing the vm 2-3
[MyStorageList.getDeviceContainsVm]: there is no device containing the vm 2-3
[MyStorageList.getDeviceContainsVm]: there is no device containing the vm 2-3
[MyStorageList.getDeviceContainsVm]: there is no device containing the vm 2-6
[MyStorageList.getDeviceContainsVm]: there is no device containing the vm 2-3
[MyStorageList.getDeviceContainsVm]: there is no device containing the vm 2-3
[MyStorageList.getDeviceContainsVm]: there is no device containing the vm 2-3
[MyStorageList.getDeviceContainsVm]: there is no device containing the vm 2-3
[MyStorageList.getDeviceContainsVm]: there is no device containing the vm 2-6
[MyStorageList.getDeviceContainsVm]: there is no device containing the vm 2-6
[MyStorageList.getDeviceContainsVm]: there is no device containing the vm 2-6
[MyStorageList.getDeviceContainsVm]: there is no device containing the vm 2-6
[MyStorageList.getDeviceContainsVm]: there is no device containing the vm 2-6
[MyStorageList.getDeviceContainsVm]: there is no device containing the vm 2-6
[MyStorageList.getDeviceContainsVm]: there is no device containing the vm 2-6
[MyStorageList.getDeviceContainsVm]: there is no device containing the vm 2-3
[MyStorageList.getDeviceContainsVm]: there is no device containing the vm 2-3
[MyStorageList.getDeviceContainsVm]: there is no device containing the vm 2-3
[MyStorageList.getDeviceContainsVm]: there is no device containing the vm 2-3
[MyStorageList.getDeviceContainsVm]: there is no device containing the vm 2-6
[MyStorageList.getDeviceContainsVm]: there is no device containing the vm 2-3
[MyStorageList.getDeviceContainsVm]: there is no device containing the vm 2-3
[MyStorageList.getDeviceContainsVm]: there is no device containing the vm 2-3
[MyStorageList.getDeviceContainsVm]: there is no device containing the vm 2-6
[MyStorageList.getDeviceContainsVm]: there is no device containing the vm 2-6
[MyStorageList.getDeviceContainsVm]: there is no device containing the vm 2-6
[MyStorageList.getDeviceContainsVm]: there is no device containing the vm 2-6
[MyStorageList.getDeviceContainsVm]: there is no device containing the vm 2-6
[MyStorageList.getDeviceContainsVm]: there is no device containing the vm 2-6
[MyStorageList.getDeviceContainsVm]: there is no device containing the vm 2-6
[MyStorageList.getDeviceContainsVm]: there is no device containing the vm 2-3
[MyStorageList.getDeviceContainsVm]: there is no device containing the vm 2-3
[MyStorageList.getDeviceContainsVm]: there is no device containing the vm 2-3
[MyStorageList.getDeviceContainsVm]: there is no device containing the vm 2-3
[MyStorageList.getDeviceContainsVm]: there is no device containing the vm 2-3
[MyStorageList.getDeviceContainsVm]: there is no device containing the vm 2-6
[MyStorageList.getDeviceContainsVm]: there is no device containing the vm 2-3
[MyStorageList.getDeviceContainsVm]: there is no device containing the vm 2-3
[MyStorageList.getDeviceContainsVm]: there is no device containing the vm 2-6
[MyStorageList.getDeviceContainsVm]: there is no device containing the vm 2-6
[MyStorageList.getDeviceContainsVm]: there is no device containing the vm 2-6
[MyStorageList.getDeviceContainsVm]: there is no device containing the vm 2-6
[MyStorageList.getDeviceContainsVm]: there is no device containing the vm 2-6
[MyStorageList.getDeviceContainsVm]: there is no device containing the vm 2-6
[MyStorageList.getDeviceContainsVm]: there is no device containing the vm 2-6
[MyStorageList.getDeviceContainsVm]: there is no device containing the vm 2-3
[MyStorageList.getDeviceContainsVm]: there is no device containing the vm 2-3
[MyStorageList.getDeviceContainsVm]: there is no device containing the vm 2-3
[MyStorageList.getDeviceContainsVm]: there is no device containing the vm 2-3
[MyStorageList.getDeviceContainsVm]: there is no device containing the vm 2-3
[MyStorageList.getDeviceContainsVm]: there is no device containing the vm 2-3
[MyStorageList.getDeviceContainsVm]: there is no device containing the vm 2-6
[MyStorageList.getDeviceContainsVm]: there is no device containing the vm 2-3
1200.1: Broker: Cloudlet 9 received


--------------------------------------------------------------


New resource usage for the time frame starting at 1500,10:

1500,10: [Host #0] IO processing of VM #0 elapsed time is 2,93396 s
1500,10: [Host #0] IO processing of VM #6 elapsed time is 0,25283 s
1500,10: [Host #0] IO processing of VM #8 elapsed time is 0,25283 s
1500,10: [Host #0] Total allocated MIPS for VM #0 (Host #0) is 500,00, was requested 500,00 out of total 500,00 (100,00%)
1500,10: [Host #0] MIPS for VM #0 by PEs (2 * 2660.0). PE #0: 500,00.
1500,10: [Host #0] Total allocated MIPS for VM #6 (Host #0) is 2000,00, was requested 2000,00 out of total 2000,00 (100,00%)
1500,10: [Host #0] MIPS for VM #6 by PEs (2 * 2660.0). PE #0: 2000,00.
1500,10: [Host #0] Total allocated MIPS for VM #8 (Host #0) is 2000,00, was requested 2000,00 out of total 2000,00 (100,00%)
1500,10: [Host #0] MIPS for VM #8 by PEs (2 * 2660.0). PE #0: 160,00. PE #1: 1840,00.
1500,10: [Host #0] utilization is 84,59%

1500,10: [Host #1] utilization is 0,00%

1500,10: [Host #2] IO processing of VM #1 elapsed time is 2,93396 s
1500,10: [Host #2] IO processing of VM #7 elapsed time is 0,25283 s
1500,10: [Host #2] IO processing of VM #2 elapsed time is 2,93396 s
1500,10: [Host #2] IO processing of VM #5 elapsed time is 2,87358 s
1500,10: [Host #2] Total allocated MIPS for VM #1 (Host #2) is 500,00, was requested 500,00 out of total 500,00 (100,00%)
1500,10: [Host #2] MIPS for VM #1 by PEs (2 * 2660.0). PE #0: 500,00.
1500,10: [Host #2] Total allocated MIPS for VM #7 (Host #2) is 2000,00, was requested 2000,00 out of total 2000,00 (100,00%)
1500,10: [Host #2] MIPS for VM #7 by PEs (2 * 2660.0). PE #0: 660,00. PE #1: 1340,00.
1500,10: [Host #2] Total allocated MIPS for VM #2 (Host #2) is 500,00, was requested 500,00 out of total 500,00 (100,00%)
1500,10: [Host #2] MIPS for VM #2 by PEs (2 * 2660.0). PE #0: 500,00.
1500,10: [Host #2] Total allocated MIPS for VM #5 (Host #2) is 1000,00, was requested 1000,00 out of total 1000,00 (100,00%)
1500,10: [Host #2] MIPS for VM #5 by PEs (2 * 2660.0). PE #0: 1000,00.
1500,10: [Host #2] utilization is 75,19%

1500,10: [Host #3] utilization is 0,00%

1500,10: [Host #4] utilization is 0,00%

1500,10: [Host #5] utilization is 0,00%

1500,10: [Host #6] IO processing of VM #3 elapsed time is 2,87358 s
1500,10: [Host #6] IO processing of VM #9 elapsed time is 0,47170 s
1500,10: [Host #6] IO processing of VM #4 elapsed time is 2,87358 s
1500,10: [Host #6] Total allocated MIPS for VM #3 (Host #6) is 1000,00, was requested 1000,00 out of total 1000,00 (100,00%)
1500,10: [Host #6] MIPS for VM #3 by PEs (2 * 2660.0). PE #0: 1000,00.
1500,10: [Host #6] Total allocated MIPS for VM #9 (Host #6) is 2500,00, was requested 2500,00 out of total 2500,00 (100,00%)
1500,10: [Host #6] MIPS for VM #9 by PEs (2 * 2660.0). PE #0: 660,00. PE #1: 1840,00.
1500,10: [Host #6] Total allocated MIPS for VM #4 (Host #6) is 1000,00, was requested 1000,00 out of total 1000,00 (100,00%)
1500,10: [Host #6] MIPS for VM #4 by PEs (2 * 2660.0). PE #0: 1000,00.
1500,10: [Host #6] utilization is 84,59%

1500,10: [Host #7] utilization is 0,00%

1500,10: [Host #8] utilization is 0,00%

1500,10: [Host #9] utilization is 0,00%

Energy consumption for the last time frame from 1200,10 to 1500,10:

1500,10: [Host #0] utilization at 1200,10 was 84,59%, now is 84,59%
1500,10: [Host #0] energy is 25150,38 W*sec

1500,10: [Host #1] utilization at 1200,10 was 0,00%, now is 0,00%
1500,10: [Host #1] energy is 0,00 W*sec

1500,10: [Host #2] utilization at 1200,10 was 75,19%, now is 75,19%
1500,10: [Host #2] energy is 24022,56 W*sec

1500,10: [Host #3] utilization at 1200,10 was 0,00%, now is 0,00%
1500,10: [Host #3] energy is 0,00 W*sec

1500,10: [Host #4] utilization at 1200,10 was 0,00%, now is 0,00%
1500,10: [Host #4] energy is 0,00 W*sec

1500,10: [Host #5] utilization at 1200,10 was 0,00%, now is 0,00%
1500,10: [Host #5] energy is 0,00 W*sec

1500,10: [Host #6] utilization at 1200,10 was 84,59%, now is 84,59%
1500,10: [Host #6] energy is 25150,38 W*sec

1500,10: [Host #7] utilization at 1200,10 was 0,00%, now is 0,00%
1500,10: [Host #7] energy is 0,00 W*sec

1500,10: [Host #8] utilization at 1200,10 was 0,00%, now is 0,00%
1500,10: [Host #8] energy is 0,00 W*sec

1500,10: [Host #9] utilization at 1200,10 was 0,00%, now is 0,00%
1500,10: [Host #9] energy is 0,00 W*sec

1500,10: Data center's energy is 74323,31 W*sec


Hamza: optimizeAllocation
Over-utilized hosts:
Host #0
Host #6

Reallocation of VMs from the over-utilized hosts:
VM #0 allocated to host #1
VM #4 allocated to host #1
[VmScheduler.vmCreate] Allocation of VM #0 to Host #2 failed by RAM
VM #0 allocated to host #2
VM #4 allocated to host #1
VM #0 allocated to host #3
VM #4 allocated to host #1
VM #0 allocated to host #4
VM #4 allocated to host #1
VM #0 allocated to host #5
VM #4 allocated to host #1
VM #0 allocated to host #7
VM #4 allocated to host #1
VM #0 allocated to host #8
VM #4 allocated to host #1
VM #0 allocated to host #9
VM #4 allocated to host #1
VM #0 allocated to host #1
[VmScheduler.vmCreate] Allocation of VM #4 to Host #2 failed by RAM
VM #4 allocated to host #2
[VmScheduler.vmCreate] Allocation of VM #0 to Host #2 failed by RAM
VM #0 allocated to host #2
[VmScheduler.vmCreate] Allocation of VM #4 to Host #2 failed by RAM
VM #4 allocated to host #2
VM #0 allocated to host #3
[VmScheduler.vmCreate] Allocation of VM #4 to Host #2 failed by RAM
VM #4 allocated to host #2
VM #0 allocated to host #4
[VmScheduler.vmCreate] Allocation of VM #4 to Host #2 failed by RAM
VM #4 allocated to host #2
VM #0 allocated to host #5
[VmScheduler.vmCreate] Allocation of VM #4 to Host #2 failed by RAM
VM #4 allocated to host #2
VM #0 allocated to host #7
[VmScheduler.vmCreate] Allocation of VM #4 to Host #2 failed by RAM
VM #4 allocated to host #2
VM #0 allocated to host #8
[VmScheduler.vmCreate] Allocation of VM #4 to Host #2 failed by RAM
VM #4 allocated to host #2
VM #0 allocated to host #9
[VmScheduler.vmCreate] Allocation of VM #4 to Host #2 failed by RAM
VM #4 allocated to host #2
VM #0 allocated to host #1
VM #4 allocated to host #3
[VmScheduler.vmCreate] Allocation of VM #0 to Host #2 failed by RAM
VM #0 allocated to host #2
VM #4 allocated to host #3
VM #0 allocated to host #3
VM #4 allocated to host #3
VM #0 allocated to host #4
VM #4 allocated to host #3
VM #0 allocated to host #5
VM #4 allocated to host #3
VM #0 allocated to host #7
VM #4 allocated to host #3
VM #0 allocated to host #8
VM #4 allocated to host #3
VM #0 allocated to host #9
VM #4 allocated to host #3
VM #0 allocated to host #1
VM #4 allocated to host #4
[VmScheduler.vmCreate] Allocation of VM #0 to Host #2 failed by RAM
VM #0 allocated to host #2
VM #4 allocated to host #4
VM #0 allocated to host #3
VM #4 allocated to host #4
VM #0 allocated to host #4
VM #4 allocated to host #4
VM #0 allocated to host #5
VM #4 allocated to host #4
VM #0 allocated to host #7
VM #4 allocated to host #4
VM #0 allocated to host #8
VM #4 allocated to host #4
VM #0 allocated to host #9
VM #4 allocated to host #4
VM #0 allocated to host #1
VM #4 allocated to host #5
[VmScheduler.vmCreate] Allocation of VM #0 to Host #2 failed by RAM
VM #0 allocated to host #2
VM #4 allocated to host #5
VM #0 allocated to host #3
VM #4 allocated to host #5
VM #0 allocated to host #4
VM #4 allocated to host #5
VM #0 allocated to host #5
VM #4 allocated to host #5
VM #0 allocated to host #7
VM #4 allocated to host #5
VM #0 allocated to host #8
VM #4 allocated to host #5
VM #0 allocated to host #9
VM #4 allocated to host #5
VM #0 allocated to host #1
VM #4 allocated to host #7
[VmScheduler.vmCreate] Allocation of VM #0 to Host #2 failed by RAM
VM #0 allocated to host #2
VM #4 allocated to host #7
VM #0 allocated to host #3
VM #4 allocated to host #7
VM #0 allocated to host #4
VM #4 allocated to host #7
VM #0 allocated to host #5
VM #4 allocated to host #7
VM #0 allocated to host #7
VM #4 allocated to host #7
VM #0 allocated to host #8
VM #4 allocated to host #7
VM #0 allocated to host #9
VM #4 allocated to host #7
VM #0 allocated to host #1
VM #4 allocated to host #8
[VmScheduler.vmCreate] Allocation of VM #0 to Host #2 failed by RAM
VM #0 allocated to host #2
VM #4 allocated to host #8
VM #0 allocated to host #3
VM #4 allocated to host #8
VM #0 allocated to host #4
VM #4 allocated to host #8
VM #0 allocated to host #5
VM #4 allocated to host #8
VM #0 allocated to host #7
VM #4 allocated to host #8
VM #0 allocated to host #8
VM #4 allocated to host #8
VM #0 allocated to host #9
VM #4 allocated to host #8
VM #0 allocated to host #1
VM #4 allocated to host #9
[VmScheduler.vmCreate] Allocation of VM #0 to Host #2 failed by RAM
VM #0 allocated to host #2
VM #4 allocated to host #9
VM #0 allocated to host #3
VM #4 allocated to host #9
VM #0 allocated to host #4
VM #4 allocated to host #9
VM #0 allocated to host #5
VM #4 allocated to host #9
VM #0 allocated to host #7
VM #4 allocated to host #9
VM #0 allocated to host #8
VM #4 allocated to host #9
VM #0 allocated to host #9
VM #4 allocated to host #9

Under-utilized host: host #2

Reallocation of VMs from the under-utilized host: 1 7 2 5 
Not all VMs can be reallocated from the host, reallocation cancelled

[MyStorageList.getDeviceContainsVm]: there is no device containing the vm 2-4
[MyStorageList.getDeviceContainsVm]: there is no device containing the vm 2-4
[MyStorageList.getDeviceContainsVm]: there is no device containing the vm 2-4
[MyStorageList.getDeviceContainsVm]: there is no device containing the vm 2-4
[MyStorageList.getDeviceContainsVm]: there is no device containing the vm 2-4
[MyStorageList.getDeviceContainsVm]: there is no device containing the vm 2-4
[MyStorageList.getDeviceContainsVm]: there is no device containing the vm 2-4
[MyStorageList.getDeviceContainsVm]: there is no device containing the vm 2-0
[MyStorageList.getDeviceContainsVm]: there is no device containing the vm 2-0
[MyStorageList.getDeviceContainsVm]: there is no device containing the vm 2-0
[MyStorageList.getDeviceContainsVm]: there is no device containing the vm 2-0
[MyStorageList.getDeviceContainsVm]: there is no device containing the vm 2-0
[MyStorageList.getDeviceContainsVm]: there is no device containing the vm 2-0
[MyStorageList.getDeviceContainsVm]: there is no device containing the vm 2-0
[MyStorageList.getDeviceContainsVm]: there is no device containing the vm 2-0
[MyStorageList.getDeviceContainsVm]: there is no device containing the vm 2-4
[MyStorageList.getDeviceContainsVm]: there is no device containing the vm 2-0
[MyStorageList.getDeviceContainsVm]: there is no device containing the vm 2-4
[MyStorageList.getDeviceContainsVm]: there is no device containing the vm 2-4
[MyStorageList.getDeviceContainsVm]: there is no device containing the vm 2-4
[MyStorageList.getDeviceContainsVm]: there is no device containing the vm 2-4
[MyStorageList.getDeviceContainsVm]: there is no device containing the vm 2-4
[MyStorageList.getDeviceContainsVm]: there is no device containing the vm 2-4
[MyStorageList.getDeviceContainsVm]: there is no device containing the vm 2-0
[MyStorageList.getDeviceContainsVm]: there is no device containing the vm 2-0
[MyStorageList.getDeviceContainsVm]: there is no device containing the vm 2-0
[MyStorageList.getDeviceContainsVm]: there is no device containing the vm 2-0
[MyStorageList.getDeviceContainsVm]: there is no device containing the vm 2-0
[MyStorageList.getDeviceContainsVm]: there is no device containing the vm 2-0
[MyStorageList.getDeviceContainsVm]: there is no device containing the vm 2-0
[MyStorageList.getDeviceContainsVm]: there is no device containing the vm 2-4
[MyStorageList.getDeviceContainsVm]: there is no device containing the vm 2-4
[MyStorageList.getDeviceContainsVm]: there is no device containing the vm 2-0
[MyStorageList.getDeviceContainsVm]: there is no device containing the vm 2-4
[MyStorageList.getDeviceContainsVm]: there is no device containing the vm 2-4
[MyStorageList.getDeviceContainsVm]: there is no device containing the vm 2-4
[MyStorageList.getDeviceContainsVm]: there is no device containing the vm 2-4
[MyStorageList.getDeviceContainsVm]: there is no device containing the vm 2-4
[MyStorageList.getDeviceContainsVm]: there is no device containing the vm 2-0
[MyStorageList.getDeviceContainsVm]: there is no device containing the vm 2-0
[MyStorageList.getDeviceContainsVm]: there is no device containing the vm 2-0
[MyStorageList.getDeviceContainsVm]: there is no device containing the vm 2-0
[MyStorageList.getDeviceContainsVm]: there is no device containing the vm 2-0
[MyStorageList.getDeviceContainsVm]: there is no device containing the vm 2-0
[MyStorageList.getDeviceContainsVm]: there is no device containing the vm 2-0
[MyStorageList.getDeviceContainsVm]: there is no device containing the vm 2-4
[MyStorageList.getDeviceContainsVm]: there is no device containing the vm 2-4
[MyStorageList.getDeviceContainsVm]: there is no device containing the vm 2-4
[MyStorageList.getDeviceContainsVm]: there is no device containing the vm 2-0
[MyStorageList.getDeviceContainsVm]: there is no device containing the vm 2-4
[MyStorageList.getDeviceContainsVm]: there is no device containing the vm 2-4
[MyStorageList.getDeviceContainsVm]: there is no device containing the vm 2-4
[MyStorageList.getDeviceContainsVm]: there is no device containing the vm 2-4
[MyStorageList.getDeviceContainsVm]: there is no device containing the vm 2-0
[MyStorageList.getDeviceContainsVm]: there is no device containing the vm 2-0
[MyStorageList.getDeviceContainsVm]: there is no device containing the vm 2-0
[MyStorageList.getDeviceContainsVm]: there is no device containing the vm 2-0
[MyStorageList.getDeviceContainsVm]: there is no device containing the vm 2-0
[MyStorageList.getDeviceContainsVm]: there is no device containing the vm 2-0
[MyStorageList.getDeviceContainsVm]: there is no device containing the vm 2-0
[MyStorageList.getDeviceContainsVm]: there is no device containing the vm 2-4
[MyStorageList.getDeviceContainsVm]: there is no device containing the vm 2-4
[MyStorageList.getDeviceContainsVm]: there is no device containing the vm 2-4
[MyStorageList.getDeviceContainsVm]: there is no device containing the vm 2-4
[MyStorageList.getDeviceContainsVm]: there is no device containing the vm 2-0
[MyStorageList.getDeviceContainsVm]: there is no device containing the vm 2-4
[MyStorageList.getDeviceContainsVm]: there is no device containing the vm 2-4
[MyStorageList.getDeviceContainsVm]: there is no device containing the vm 2-4
[MyStorageList.getDeviceContainsVm]: there is no device containing the vm 2-0
[MyStorageList.getDeviceContainsVm]: there is no device containing the vm 2-0
[MyStorageList.getDeviceContainsVm]: there is no device containing the vm 2-0
[MyStorageList.getDeviceContainsVm]: there is no device containing the vm 2-0
[MyStorageList.getDeviceContainsVm]: there is no device containing the vm 2-0
[MyStorageList.getDeviceContainsVm]: there is no device containing the vm 2-0
[MyStorageList.getDeviceContainsVm]: there is no device containing the vm 2-0
[MyStorageList.getDeviceContainsVm]: there is no device containing the vm 2-4
[MyStorageList.getDeviceContainsVm]: there is no device containing the vm 2-4
[MyStorageList.getDeviceContainsVm]: there is no device containing the vm 2-4
[MyStorageList.getDeviceContainsVm]: there is no device containing the vm 2-4
[MyStorageList.getDeviceContainsVm]: there is no device containing the vm 2-4
[MyStorageList.getDeviceContainsVm]: there is no device containing the vm 2-0
[MyStorageList.getDeviceContainsVm]: there is no device containing the vm 2-4
[MyStorageList.getDeviceContainsVm]: there is no device containing the vm 2-4
[MyStorageList.getDeviceContainsVm]: there is no device containing the vm 2-0
[MyStorageList.getDeviceContainsVm]: there is no device containing the vm 2-0
[MyStorageList.getDeviceContainsVm]: there is no device containing the vm 2-0
[MyStorageList.getDeviceContainsVm]: there is no device containing the vm 2-0
[MyStorageList.getDeviceContainsVm]: there is no device containing the vm 2-0
[MyStorageList.getDeviceContainsVm]: there is no device containing the vm 2-0
[MyStorageList.getDeviceContainsVm]: there is no device containing the vm 2-0
[MyStorageList.getDeviceContainsVm]: there is no device containing the vm 2-4
[MyStorageList.getDeviceContainsVm]: there is no device containing the vm 2-4
[MyStorageList.getDeviceContainsVm]: there is no device containing the vm 2-4
[MyStorageList.getDeviceContainsVm]: there is no device containing the vm 2-4
[MyStorageList.getDeviceContainsVm]: there is no device containing the vm 2-4
[MyStorageList.getDeviceContainsVm]: there is no device containing the vm 2-4
[MyStorageList.getDeviceContainsVm]: there is no device containing the vm 2-0
[MyStorageList.getDeviceContainsVm]: there is no device containing the vm 2-4
1500.1: Broker: Cloudlet 8 received
1500.1: Broker: Cloudlet 1 received
1500.1: Broker: Cloudlet 4 received


--------------------------------------------------------------


New resource usage for the time frame starting at 1800,10:

1800,10: [Host #0] IO processing of VM #0 elapsed time is 1,53208 s
1800,10: [Host #0] IO processing of VM #6 elapsed time is 1,55094 s
1800,10: [Host #0] IO processing of VM #8 elapsed time is 1,55094 s
1800,10: [Host #0] Total allocated MIPS for VM #0 (Host #0) is 500,00, was requested 500,00 out of total 500,00 (100,00%)
1800,10: [Host #0] MIPS for VM #0 by PEs (2 * 2660.0). PE #0: 500,00.
1800,10: [Host #0] Total allocated MIPS for VM #6 (Host #0) is 2000,00, was requested 2000,00 out of total 2000,00 (100,00%)
1800,10: [Host #0] MIPS for VM #6 by PEs (2 * 2660.0). PE #0: 2000,00.
1800,10: [Host #0] Total allocated MIPS for VM #8 (Host #0) is 2000,00, was requested 2000,00 out of total 2000,00 (100,00%)
1800,10: [Host #0] MIPS for VM #8 by PEs (2 * 2660.0). PE #0: 160,00. PE #1: 1840,00.
1800,10: [Host #0] utilization is 84,59%

1800,10: [Host #1] utilization is 0,00%

1800,10: [Host #2] IO processing of VM #1 elapsed time is 1,53208 s
1800,10: [Host #2] IO processing of VM #7 elapsed time is 1,55094 s
1800,10: [Host #2] IO processing of VM #2 elapsed time is 1,53208 s
1800,10: [Host #2] IO processing of VM #5 elapsed time is 0,11887 s
1800,10: [Host #2] Total allocated MIPS for VM #1 (Host #2) is 500,00, was requested 500,00 out of total 500,00 (100,00%)
1800,10: [Host #2] MIPS for VM #1 by PEs (2 * 2660.0). PE #0: 500,00.
1800,10: [Host #2] Total allocated MIPS for VM #7 (Host #2) is 2000,00, was requested 2000,00 out of total 2000,00 (100,00%)
1800,10: [Host #2] MIPS for VM #7 by PEs (2 * 2660.0). PE #0: 660,00. PE #1: 1340,00.
1800,10: [Host #2] Total allocated MIPS for VM #2 (Host #2) is 500,00, was requested 500,00 out of total 500,00 (100,00%)
1800,10: [Host #2] MIPS for VM #2 by PEs (2 * 2660.0). PE #0: 500,00.
1800,10: [Host #2] Total allocated MIPS for VM #5 (Host #2) is 1000,00, was requested 1000,00 out of total 1000,00 (100,00%)
1800,10: [Host #2] MIPS for VM #5 by PEs (2 * 2660.0). PE #0: 1000,00.
1800,10: [Host #2] utilization is 75,19%

1800,10: [Host #3] utilization is 0,00%

1800,10: [Host #4] utilization is 0,00%

1800,10: [Host #5] utilization is 0,00%

1800,10: [Host #6] IO processing of VM #3 elapsed time is 0,11887 s
1800,10: [Host #6] IO processing of VM #9 elapsed time is 0,23208 s
1800,10: [Host #6] IO processing of VM #4 elapsed time is 0,11887 s
1800,10: [Host #6] Total allocated MIPS for VM #3 (Host #6) is 1000,00, was requested 1000,00 out of total 1000,00 (100,00%)
1800,10: [Host #6] MIPS for VM #3 by PEs (2 * 2660.0). PE #0: 1000,00.
1800,10: [Host #6] Total allocated MIPS for VM #9 (Host #6) is 2500,00, was requested 2500,00 out of total 2500,00 (100,00%)
1800,10: [Host #6] MIPS for VM #9 by PEs (2 * 2660.0). PE #0: 660,00. PE #1: 1840,00.
1800,10: [Host #6] Total allocated MIPS for VM #4 (Host #6) is 1000,00, was requested 1000,00 out of total 1000,00 (100,00%)
1800,10: [Host #6] MIPS for VM #4 by PEs (2 * 2660.0). PE #0: 1000,00.
1800,10: [Host #6] utilization is 84,59%

1800,10: [Host #7] utilization is 0,00%

1800,10: [Host #8] utilization is 0,00%

1800,10: [Host #9] utilization is 0,00%

Energy consumption for the last time frame from 1500,10 to 1800,10:

1800,10: [Host #0] utilization at 1500,10 was 84,59%, now is 84,59%
1800,10: [Host #0] energy is 25150,38 W*sec

1800,10: [Host #1] utilization at 1500,10 was 0,00%, now is 0,00%
1800,10: [Host #1] energy is 0,00 W*sec

1800,10: [Host #2] utilization at 1500,10 was 75,19%, now is 75,19%
1800,10: [Host #2] energy is 24022,56 W*sec

1800,10: [Host #3] utilization at 1500,10 was 0,00%, now is 0,00%
1800,10: [Host #3] energy is 0,00 W*sec

1800,10: [Host #4] utilization at 1500,10 was 0,00%, now is 0,00%
1800,10: [Host #4] energy is 0,00 W*sec

1800,10: [Host #5] utilization at 1500,10 was 0,00%, now is 0,00%
1800,10: [Host #5] energy is 0,00 W*sec

1800,10: [Host #6] utilization at 1500,10 was 84,59%, now is 84,59%
1800,10: [Host #6] energy is 25150,38 W*sec

1800,10: [Host #7] utilization at 1500,10 was 0,00%, now is 0,00%
1800,10: [Host #7] energy is 0,00 W*sec

1800,10: [Host #8] utilization at 1500,10 was 0,00%, now is 0,00%
1800,10: [Host #8] energy is 0,00 W*sec

1800,10: [Host #9] utilization at 1500,10 was 0,00%, now is 0,00%
1800,10: [Host #9] energy is 0,00 W*sec

1800,10: Data center's energy is 74323,31 W*sec


Hamza: optimizeAllocation
Over-utilized hosts:
Host #0
Host #6

Reallocation of VMs from the over-utilized hosts:
VM #0 allocated to host #1
VM #9 allocated to host #1
[VmScheduler.vmCreate] Allocation of VM #0 to Host #2 failed by RAM
VM #0 allocated to host #2
VM #9 allocated to host #1
VM #0 allocated to host #3
VM #9 allocated to host #1
VM #0 allocated to host #4
VM #9 allocated to host #1
VM #0 allocated to host #5
VM #9 allocated to host #1
VM #0 allocated to host #7
VM #9 allocated to host #1
VM #0 allocated to host #8
VM #9 allocated to host #1
VM #0 allocated to host #9
VM #9 allocated to host #1
VM #0 allocated to host #1
[VmScheduler.vmCreate] Allocation of VM #9 to Host #2 failed by RAM
VM #9 allocated to host #2
[VmScheduler.vmCreate] Allocation of VM #0 to Host #2 failed by RAM
VM #0 allocated to host #2
[VmScheduler.vmCreate] Allocation of VM #9 to Host #2 failed by RAM
VM #9 allocated to host #2
VM #0 allocated to host #3
[VmScheduler.vmCreate] Allocation of VM #9 to Host #2 failed by RAM
VM #9 allocated to host #2
VM #0 allocated to host #4
[VmScheduler.vmCreate] Allocation of VM #9 to Host #2 failed by RAM
VM #9 allocated to host #2
VM #0 allocated to host #5
[VmScheduler.vmCreate] Allocation of VM #9 to Host #2 failed by RAM
VM #9 allocated to host #2
VM #0 allocated to host #7
[VmScheduler.vmCreate] Allocation of VM #9 to Host #2 failed by RAM
VM #9 allocated to host #2
VM #0 allocated to host #8
[VmScheduler.vmCreate] Allocation of VM #9 to Host #2 failed by RAM
VM #9 allocated to host #2
VM #0 allocated to host #9
[VmScheduler.vmCreate] Allocation of VM #9 to Host #2 failed by RAM
VM #9 allocated to host #2
VM #0 allocated to host #1
VM #9 allocated to host #3
[VmScheduler.vmCreate] Allocation of VM #0 to Host #2 failed by RAM
VM #0 allocated to host #2
VM #9 allocated to host #3
VM #0 allocated to host #3
VM #9 allocated to host #3
VM #0 allocated to host #4
VM #9 allocated to host #3
VM #0 allocated to host #5
VM #9 allocated to host #3
VM #0 allocated to host #7
VM #9 allocated to host #3
VM #0 allocated to host #8
VM #9 allocated to host #3
VM #0 allocated to host #9
VM #9 allocated to host #3
VM #0 allocated to host #1
VM #9 allocated to host #4
[VmScheduler.vmCreate] Allocation of VM #0 to Host #2 failed by RAM
VM #0 allocated to host #2
VM #9 allocated to host #4
VM #0 allocated to host #3
VM #9 allocated to host #4
VM #0 allocated to host #4
VM #9 allocated to host #4
VM #0 allocated to host #5
VM #9 allocated to host #4
VM #0 allocated to host #7
VM #9 allocated to host #4
VM #0 allocated to host #8
VM #9 allocated to host #4
VM #0 allocated to host #9
VM #9 allocated to host #4
VM #0 allocated to host #1
VM #9 allocated to host #5
[VmScheduler.vmCreate] Allocation of VM #0 to Host #2 failed by RAM
VM #0 allocated to host #2
VM #9 allocated to host #5
VM #0 allocated to host #3
VM #9 allocated to host #5
VM #0 allocated to host #4
VM #9 allocated to host #5
VM #0 allocated to host #5
VM #9 allocated to host #5
VM #0 allocated to host #7
VM #9 allocated to host #5
VM #0 allocated to host #8
VM #9 allocated to host #5
VM #0 allocated to host #9
VM #9 allocated to host #5
VM #0 allocated to host #1
VM #9 allocated to host #7
[VmScheduler.vmCreate] Allocation of VM #0 to Host #2 failed by RAM
VM #0 allocated to host #2
VM #9 allocated to host #7
VM #0 allocated to host #3
VM #9 allocated to host #7
VM #0 allocated to host #4
VM #9 allocated to host #7
VM #0 allocated to host #5
VM #9 allocated to host #7
VM #0 allocated to host #7
VM #9 allocated to host #7
VM #0 allocated to host #8
VM #9 allocated to host #7
VM #0 allocated to host #9
VM #9 allocated to host #7
VM #0 allocated to host #1
VM #9 allocated to host #8
[VmScheduler.vmCreate] Allocation of VM #0 to Host #2 failed by RAM
VM #0 allocated to host #2
VM #9 allocated to host #8
VM #0 allocated to host #3
VM #9 allocated to host #8
VM #0 allocated to host #4
VM #9 allocated to host #8
VM #0 allocated to host #5
VM #9 allocated to host #8
VM #0 allocated to host #7
VM #9 allocated to host #8
VM #0 allocated to host #8
VM #9 allocated to host #8
VM #0 allocated to host #9
VM #9 allocated to host #8
VM #0 allocated to host #1
VM #9 allocated to host #9
[VmScheduler.vmCreate] Allocation of VM #0 to Host #2 failed by RAM
VM #0 allocated to host #2
VM #9 allocated to host #9
VM #0 allocated to host #3
VM #9 allocated to host #9
VM #0 allocated to host #4
VM #9 allocated to host #9
VM #0 allocated to host #5
VM #9 allocated to host #9
VM #0 allocated to host #7
VM #9 allocated to host #9
VM #0 allocated to host #8
VM #9 allocated to host #9
VM #0 allocated to host #9
VM #9 allocated to host #9

Under-utilized host: host #2

Reallocation of VMs from the under-utilized host: 1 7 2 5 
Not all VMs can be reallocated from the host, reallocation cancelled

[MyStorageList.getDeviceContainsVm]: there is no device containing the vm 2-9
[MyStorageList.getDeviceContainsVm]: there is no device containing the vm 2-9
[MyStorageList.getDeviceContainsVm]: there is no device containing the vm 2-9
[MyStorageList.getDeviceContainsVm]: there is no device containing the vm 2-9
[MyStorageList.getDeviceContainsVm]: there is no device containing the vm 2-9
[MyStorageList.getDeviceContainsVm]: there is no device containing the vm 2-9
[MyStorageList.getDeviceContainsVm]: there is no device containing the vm 2-9
[MyStorageList.getDeviceContainsVm]: there is no device containing the vm 2-0
[MyStorageList.getDeviceContainsVm]: there is no device containing the vm 2-0
[MyStorageList.getDeviceContainsVm]: there is no device containing the vm 2-0
[MyStorageList.getDeviceContainsVm]: there is no device containing the vm 2-0
[MyStorageList.getDeviceContainsVm]: there is no device containing the vm 2-0
[MyStorageList.getDeviceContainsVm]: there is no device containing the vm 2-0
[MyStorageList.getDeviceContainsVm]: there is no device containing the vm 2-0
[MyStorageList.getDeviceContainsVm]: there is no device containing the vm 2-0
[MyStorageList.getDeviceContainsVm]: there is no device containing the vm 2-9
[MyStorageList.getDeviceContainsVm]: there is no device containing the vm 2-0
[MyStorageList.getDeviceContainsVm]: there is no device containing the vm 2-9
[MyStorageList.getDeviceContainsVm]: there is no device containing the vm 2-9
[MyStorageList.getDeviceContainsVm]: there is no device containing the vm 2-9
